Workbook
Name L_tot: #REF!
Name L_tot: #REF!
Name L_tot: #REF!
Name L_tot: #REF!
Name L_tot: #REF!
Name L_tot: #REF!
Name L_tot: #REF!
Name L_tot: #REF!
Name 半径方向の出力: #REF!
Name 半径方向の出力: #REF!
Name 半径方向の出力: #REF!
Name 半径方向の出力: #REF!
Name 半径方向の出力: #REF!
Name 半径方向の出力: #REF!
Name 半径方向の出力: #REF!
Name 半径方向の出力: #REF!

Sheet 00_RESULT_README
A1: 【H-50H1 result移送用。resultブックへコピー後、internal側では削除候補。正本: 00_RESULT_BUILD_MASTER_H50E。】
A3: 00_RESULT_README — resultブック 概要・運用方針
A5: ■ resultブックの位置づけ
A6: resultブックは作業場。文献追加とPPT用データ整理を行う場所。
A7: internalブックは退避倉庫。過去検討・試行錯誤・作業証跡を保持。
A8: resultには「最終採用データ」「文献追加に必要な地図」「PPT用最小グラフデータ」だけを残す。
A9: 過去検討はinternalへ退避済み。
A11: ■ 最初に読むシート
A12: 1. 00_RESULT_README（このシート）
A13: 2. 00_SHEET_MAP（全シート地図）
A14: 3. 00_DATA_ADDITION_FLOW（文献追加手順）
A16: ■ BR列までの共通標準口
... A55: 出力ファイル名は本日付・r8へ更新。

Sheet 00_SHEET_MAP
A1: 【H-50H1 result移送用。resultブックへコピー後、internal側では削除候補。正本: 00_RESULT_BUILD_MASTER_H50E。】
A3: 00_SHEET_MAP — resultブック シート地図
A5: SheetName | B5: Role | C5: ReadPriority | D5: Editable | E5: UsedFor | F5: SourceOrArchive | G5: PublicPPTUse | H5: FutureLiteratureUse | I5: Lifecycle | J5: Notes
A6: 00_RESULT_README | B6: 概要・運用方針 | C6: 1(最優先) | D6: Yes | E6: ブック全体の理解 | F6: H-50H1新規 | G6: No | H6: No | I6: result正本 | J6: 最初に読む
A7: 00_SHEET_MAP | B7: シート地図 | C7: 2 | D7: Yes | E7: シート一覧・役割 | F7: H-50H1新規 | G7: No | H7: No | I7: result正本 | J7: このシート
A8: 00_DATA_ADDITION_FLOW | B8: 文献追加手順 | C8: 3 | D8: Yes | E8: 文献追加フロー | F8: H-50H1新規 | G8: No | H8: Yes | I8: result正本
A9: 00_ARCHIVE_MAP | B9: internal退避地図 | C9: 参照時 | D9: Yes | E9: 退避先参照 | F9: H-50H1新規 | G9: No | H9: No | I9: result参照用 | J9: 誤読防止
A10: 00_CURRENT_PUBLIC_SUMMARY | B10: 現行public要点 | C10: 参照時 | D10: No | E10: 現行採用結果 | F10: F2P_actual_ppt_summary抽出 | G10: No | H10: No | I10: result参照用 | J10: 内部ログ除外
A11: 01_PUBLIC_GRAPH_DATA | B11: PPT本編グラフ元 | C11: 参照時 | D11: Yes | E11: G1-G6本編 | F11: F2P_actual_ppt_graphs抽出 | G11: Yes | H11: No | I11: result正本 | J11: グラフはresult側で再作成
A12: 02_LDNB_GEOMETRY_DIAGNOSTIC | B12: L_DNB/DH診断 | C12: 参照時 | D12: Yes | E12: G3診断 | F12: 05_L_LDNB_AUDIT_MEMO抽出 | G12: Yes | H12: Yes | I12: result正本 | J12: L_DNB=結果量
A13: 03_GEOMETRY_LDH_SEARCH | B13: 幾何L/DH探索 | C13: 参照時 | D13: Yes | E13: G4探索条件 | F13: LDh_search抽出 | G13: Yes | H13: Yes | I13: result正本 | J13: L_geometry=探索条件
A14: literature_candidate_list | B14: Literature candidate management | C14: High when doing literature search | D14: Yes | E14: Candidate screening before adding new data | F14: H-50I整備 | G14: Yes(調査後) | H14: Primary entry point for literature candidates | I14: Result working sheet, keep | J14: H-50Iで文献調査用に整備。最低26列・判定基準・入力ルールあり。
A15: tm_ST | B15: STデータ | C15: 作業時 | D15: 追加行のみ | E15: 元データ・文献追加基準 | F15: tm_ST(internal) | G15: No | H15: Yes | I15: result正本 | J15: BR列まで標準口
A16: tm_108 | B16: 108データ | C16: 作業時 | D16: 追加行のみ | E16: 元データ・文献追加基準 | F16: tm_108(internal) | G16: No | H16: Yes | I16: result正本 | J16: BR列まで標準口
A17: tm_161 | B17: 161データ | C17: 作業時 | D17: 追加行のみ | E17: 元データ・文献追加基準 | F17: tm_161(internal) | G17: No | H17: Yes | I17: result正本 | J17: BR列まで標準口
A18: tm_164 | B18: 164データ | C18: 作業時 | D18: 追加行のみ | E18: 元データ・文献追加基準 | F18: tm_164(internal) | G18: No | H18: Yes | I18: result正本 | J18: BR列まで標準口
A19: tm_F1_ST | B19: ST F1適用後 | C19: 作業時 | D19: 追加行のみ | E19: マクロ返却基準 | F19: tm_F1_ST(internal) | G19: No | H19: Yes | I19: result正本 | J19: BR列まで標準口
A20: tm_F1_108 | B20: 108 F1適用後 | C20: 作業時 | D20: 追加行のみ | E20: マクロ返却基準 | F20: tm_F1_108(internal) | G20: No | H20: Yes | I20: result正本 | J20: BR列まで標準口
... A34: tm_r124_F1_T8_14 | B34: T&M Table8〜14 F1あり計算済みtm固定値 | C34: High during H52Q import | D34: No, values archive | E34: Table8〜14追加データのF1結果確認、追加138行抽出元 | F34: r124 F1ありマクロブック tm | G34: No | H34: Yes | I34: Current source copy / do not edit | J34: VBA計算済みtmを値貼り。追加138行は88〜225行想定。

Sheet 00_DATA_ADDITION_FLOW
A1: 【H-50H1 result移送用。resultブックへコピー後、internal側では削除候補。正本: 00_RESULT_BUILD_MASTER_H50E。】
A3: 00_DATA_ADDITION_FLOW — 文献追加フロー
A5: Step | B5: Scenario | C5: ActionInResult | D5: ActionInMacroBook | E5: Output | F5: CompletionCriterion | G5: Notes
A6: 1 | B6: 文献候補を見つける | C6: literature_candidate_listに候補を記録 | D6: - | E6: 候補一覧 | F6: 候補が一覧化された | G6: DataStatus=候補
A7: 2 | B7: 条件だけ仮登録 | C7: P/G/DH等の条件のみtm_*へ仮追加 | D7: - | E7: 条件行 | F7: 条件が揃う | G7: 実データ未取得
A8: 3 | B8: 文献データを入手 | C8: tm_literature_rawへ生データを入力 | D8: - | E8: 生データ | F8: データ取得済み | G8: DataStatus=取得
A9: ■ 文献追加後の分岐（詳細は00_RESULT_BUILD_MASTER_H50E 表6参照） | B9: tm_標準列へ追加 | C9: BR列構成でtm_*の標準口へ追加 | D9: - | E9: 標準化行 | F9: BR口に揃う | G9: SourcePaper/DataStatus記入
A10: 5 | B10: 追加データのみマクロ実行 | C10: - | D10: 追加行だけマクロ計算 | E10: マクロ結果(数式) | F10: 計算完了 | G10: 既存行は再計算しない
A11: 6 | B11: マクロ結果を値化 | C11: - | D11: 数式→値へ確定 | E11: 確定値 | F11: 値化完了=追加終了の目安 | G11: ここが追加終了
A12: 7 | B12: tm_F1_標準口へコピー | C12: 値化結果をtm_F1_*(BR列)へ | D12: - | E12: tm_F1_標準行 | F12: BR口に揃う | G12: 外部参照を残さない
A13: 8 | B13: PPT用グラフデータ更新 | C13: 必要なら01_PUBLIC_GRAPH_DATAを更新 | D13: - | E13: 更新グラフデータ | F13: PPT反映可能 | G13: 本編/Appendixを選別
A14: 9 | B14: 古い検討をinternal退避 | C14: resultから外す | D14: - | E14: internal退避 | F14: resultが最小構成 | G14: 表2・表3参照
A18: 条件 | B18: 対応
A19: 文献が見つからない | B19: 現状維持。現行P依存F2P結果を使う。
A20: 候補だけ見つかった | B20: literature_candidate_listに条件記録。DataStatus=候補。
A21: データが入手できた | B21: 表のStep3〜9のフローで追加。
A22: 補正式が変わった | B22: 新補正式で再結果・グラフ更新。旧検討はinternal退避。
A23: P依存F2Pが不要になった | B23: G1/G2グラフの取扱いを再検討。旧グラフはinternal退避候補。

Sheet 00_TM8_14_IMPORT_PLAN
A1: 00_TM8_14_IMPORT_PLAN — T&M Table 8〜14 計算済みデータ受け入れ計画
A2: 作成日: 2026-06-12 ／ 対象: r123(F1なし)・r124(F1あり) マクロブックからの値化tm受け入れ ／ 既存tm_*・tm_F1_*・tm_F1F2_*・internal_H52Q_*は変更しない
A4: ■ 1. 受け入れ管理表
A5: 項目 | B5: 内容
A6: Project | B6: H52Q / Thompson & Macbeth Table 8〜14 追加
A7: Source macrobook noF1 | B7: celataモデル_簡易計算_単管_櫻井検算r123_F1なし_Table8-14計算済み.xlsm
A8: Source macrobook F1 | B8: celataモデル_簡易計算_単管_櫻井検算r124_F1あり_Table8-14計算済み.xlsm
A9: Target result book | B9: 20260612_計算結果比較r8_result_文献追加用.xlsx
A10: Expected added rows | B10: 138
A11: Expected added row range in macro tm | B11: 88〜225
A12: Expected tables | B12: Table 8, 9, 11, 12, 13, 14
A13: Table 8 rows | B13: 16
A14: Table 9 rows | B14: 30
A15: Table 11 rows | B15: 30
A16: Table 12 rows | B16: 30
A17: Table 13 rows | B17: 2
A18: Table 14 rows | B18: 30
A19: G filter | B19: G > 1000 kg/m2s
A20: L/D filter | B20: 40 <= L/D <= 400
A21: Important note | B21: Table 11〜14 の L/D 約80 short_anchor は今回追加対象
A22: Important note | B22: Table 8 は 10〜12 MPa帯の middle L/D 候補
A23: Important note | B23: G/D/PWR-likeで厳密に切りすぎると探索データが消える
A24: Next action after VBA | B24: r123/r124 の tm シートを値貼りでresultへコピー
A25: Planned result sheet noF1 | B25: tm_r123_noF1_T8_14
A26: Planned result sheet F1 | B26: tm_r124_F1_T8_14
A27: Planned branch sheet | B27: internal_H52Q_T8_14_branch
A28: Status | B28: Waiting for VBA completion
A31: ■ 2. Legacy sheets / 旧追加シート（旧 Table 11〜14 追加検討）
A32: SheetName | B32: 位置づけ | C32: 今回の扱い
A33: tm_ST_add_TM11_14_noF1_raw | B33: 旧 Table 11〜14 追加検討（F1なし raw） | C33: 今回の Table 8〜14 正式追加では上書きしない。新規取り込み後に比較・退避判断。直ちに削除しない。
A34: tm_ST_add_TM11_14_F1_raw | B34: 旧 Table 11〜14 追加検討（F1あり raw） | C34: 今回の Table 8〜14 正式追加では上書きしない。新規取り込み後に比較・退避判断。直ちに削除しない。
A35: tm_ST_add_TM11_14_diag | B35: 旧 Table 11〜14 追加検討（診断） | C35: 今回の Table 8〜14 正式追加では上書きしない。新規取り込み後に比較・退避判断。直ちに削除しない。
A36: tm_ST_add_TM11_14_summary | B36: 旧 Table 11〜14 追加検討（サマリ） | C36: 今回の Table 8〜14 正式追加では上書きしない。新規取り込み後に比較・退避判断。直ちに削除しない。
A38: 注意: 上記4シートは以前の Table 11〜14 追加検討のシートであり、今回の Table 8〜14 追加とは別扱い。今回の正式追加では上書きせず、新規取り込み後に比較・退避判断する。直ちに削除しない。
A41: ■ 3. VBA完了後 TODO
A42: No | B42: TODO | C42: Status | D42: 出力・対象シート | E42: 備考
A43: 1 | B43: r123 F1なしマクロブックの tm を値貼りでコピー | C43: 完了 | D43: tm_r123_noF1_T8_14 | E43: 完了: tm_r123_noF1_T8_14 を値貼り(数式0・外部リンクなし)で作成
A44: 2 | B44: r124 F1ありマクロブックの tm を値貼りでコピー | C44: 完了 | D44: tm_r124_F1_T8_14 | E44: 完了: tm_r124_F1_T8_14 を値貼り(数式0・外部リンクなし)で作成
A45: 3 | B45: 2シートの行数・列数を確認 | C45: 完了 | D45: tm_r123_noF1_T8_14 / tm_r124_F1_T8_14 | E45: 完了: 両シート225行×70列(BR列まで)。マクロtmと一致
A46: 4 | B46: 追記部分138行が入っているか確認 | C46: 完了 | D46: 同上 | E46: 完了: 追加138行(88〜225行)を両シートで確認
...

Sheet 00_ARCHIVE_MAP
A1: 【H-50H1 result移送用。resultブックへコピー後、internal側では削除候補。正本: 00_RESULT_BUILD_MASTER_H50E。】
A3: 00_ARCHIVE_MAP — resultに入れない過去検討の退避先
A5: Content | B5: ArchiveLocationInInternal | C5: ReasonNotInResult | D5: CanReintroduce | E5: Notes
A6: x_Mes更新詳細 | B6: 01_xMes_UPDATE_METHOD | C6: x_Mes_newを外向き使用しない方針 | D6: No | E6: 外向き利用禁止
A7: x_Mes相関値候補 | B7: x_Mes_update_check / x_Mes_PM_check | C7: 中間検討。resultに不要 | D7: No | E7: 誤読リスク
A8: K_Tw式 | B8: 03_KTw_PROXY_LOG | C8: K_Twを主結果扱いしない | D8: Appendix判断後 | E8: Appendix可能性あり
A9: 近似サーベイ0.1047 | B9: F2P_proxy_survey / F2P_best_case_check | C9: 0.1047は近似値。主結果にしない | D9: No | E9: 0.1076が実Celata最終
A10: F2P_proxy_survey | B10: F2P_proxy_survey | C10: 中間検討ログ | D10: No
A11: ST_F2P_transfer_for_macro | B11: ST_F2P_transfer_for_macro | C11: マクロ連携中間データ | D11: No | E11: 証跡
A12: STマクロ連携ログ | B12: 04_ST_F2P_MACRO_LOG | C12: 作業ログ | D12: No
A13: 164重複キー確認 | B13: 05_L_LDNB_164_CHECK | C13: 内部確認ログ | D13: No
A14: H-48A〜H-50G管理ログ | B14: 00_INTERNAL_BOOK_INFO等 | C14: タスク管理ログ。誤読リスク | D14: No | E14: エージェント向け情報過多
A15: 旧サマリー | B15: F2P_actual_ppt_summary(internal) | C15: 内部検討ログ含む | D15: No | E15: 要点は00_CURRENT_PUBLIC_SUMMARYへ
A16: 旧PPT案 | B16: F2P_actual_ppt_graphs(internal) | C16: 内部検討含む | D16: No | E16: 要点は01_PUBLIC_GRAPH_DATAへ
A17: 旧L/Dh誤ラベル系 | B17: 05_L_LDNB_AUDIT / 05_L_LDNB_164_CHECK | C17: 旧ラベル誤用。再解釈済み | D17: No | E17: H-48G以降で整理
A18: エージェント誤認修正ログ | B18: 各管理ログシート内 | C18: 内部作業ログ | D18: No

Sheet 00_CURRENT_PUBLIC_SUMMARY
A1: 【H-50H1 result移送用。resultブックへコピー後、internal側では削除候補。正本: 00_RESULT_BUILD_MASTER_H50E。】
A3: 00_CURRENT_PUBLIC_SUMMARY — 現行public採用結果の要点（内部検討ログは除外）
A4: 出典: F2P_actual_ppt_summary (internal) から公開用要点を抽出。2026-06-08 H-50H1。
A6: ■ 主要数値（実Celata F1×F2P適用後）
A7: 項目 | B7: before | C7: after | D7: 変化 | E7: 解釈
A8: 全体RMSE | B8: 0.1282 | C8: 0.1076 | D8: -0.16 | E8: バラつき圧縮。改善。
A9: PM標準偏差 | B9: 0.1137 | C9: 0.0877 | D9: -0.23 | E9: 分布が狭くなった。
A10: tm_108 PM平均 | B10: 1.0668 | C10: 1.062 | D10: -0.005 | E10: 高めのまま(>1)。
A11: tm_161 PM平均 | B11: 0.9088 | C11: 0.906 | D11: -0.003 | E11: 低めのまま(<1)。
A12: tm_164 PM平均 | B12: 0.892 | C12: 0.8894 | D12: -0.003 | E12: 低めのまま(<1)。
A13: 改善/悪化点 | B13: — | C13: 31/27 | D13: — | E13: 改善が多数だが悪化も存在。
A15: ■ 本編用一文結論
A16: P依存F2Pは点ごとのバラつき圧縮に有効（RMSE 0.1282→0.1076）。ただし群平均差（108高め・161/164低め）は残る。群平均差の主因ではない。次は大L/DH単管データ探索へ。
A18: ■ L_DNB/DH診断（群別）
A19: Dataset | B19: L_DNB/DH mean | C19: PM mean | D19: 傾向
A20: ST | B20: 68.6 | C20: 1.115 | D20: 高め(>1)。短い側。
A21: 108 | B21: 139.7 | C21: 1.062 | D21: やや高め(>1)。幾何L/DH約189。
A22: 161 | B22: 361.4 | C22: 0.906 | D22: 低め(<1)。大L/DH側。
A23: 164 | B23: 286.8 | C23: 0.889 | D23: 低め(<1)。DNB位置が幾何より手前。
A25: ■ RMSEの注意
A26: 0.1076 = 実Celata最終RMSE。本編で使う値。
A27: 0.1047 = 近似サーベイ値。本編の主結果にしない。

Sheet 01_PUBLIC_GRAPH_DATA
A1: 【H-50H1 result移送用。resultブックへコピー後、internal側では削除候補。正本: 00_RESULT_BUILD_MASTER_H50E。】
A3: 01_PUBLIC_GRAPH_DATA — PPT用グラフ候補一覧と元データ
A4: グラフそのものはresult側で再作成。元データ表とグラフ候補一覧を記録。出典: F2P_actual_ppt_graphs (internal)。
A6: GraphID | B6: GraphTitle | C6: UseInMain | D6: UseInAppendix | E6: PublicResultSheet | F6: SourceInternal | G6: Notes
A7: G1 | B7: P依存F2Pの限界、群平均差は残る | C7: Yes | D7: No | E7: 01_PUBLIC_GRAPH_DATA | F7: F2P_actual_ppt_graphs | G7: 群平均差解消とは言わない。グラフはresult側で再作成。
A8: G2 | B8: P依存F2Pの効果、RMSEは改善する | C8: Yes | D8: No | E8: 01_PUBLIC_GRAPH_DATA | F8: F2P_actual_ppt_graphs | G8: RMSE 0.1282→0.1076。0.1076が実Celata最終。
A9: G3 | B9: L_DNB/DH診断（ST高め・108やや高め・161/164低め） | C9: Yes | D9: No | E9: 02_LDNB_GEOMETRY_DIAGNOSTIC | F9: 05_L_LDNB_AUDIT_MEMO | G9: L_DNBは結果量。診断図の軸として使う。
A10: G4 | B10: 幾何L/DH探索条件、現有STは大L/DH側を未カバー | C10: Yes | D10: No | E10: 03_GEOMETRY_LDH_SEARCH | F10: LDh_search_narrowing_for_ppt | G10: L_geometryは探索条件。補正入力候補。
A11: G5 | B11: F2P悪化点内訳 | C11: No | D11: Yes | E11: 05_APPENDIX(将来) | F11: F1F2_worsened_structure_check | G11: ST F2P悪化を失敗と書かない。
A12: G6 | B12: 全点PM before/after散布 | C12: Yes | D12: No | E12: 01_PUBLIC_GRAPH_DATA | F12: F2P_actual_ppt_graphs | G12: PM=1補助線と45度線。
A13: G7 | B13: K_Tw近似検討 | C13: No | D13: Yes(またはinternal) | E13: 05_APPENDIX(将来) | F13: 03_KTw_PROXY_LOG | G13: K_Twを主結果扱いしない。
A14: G8 | B14: 教科書L/D図（既往知見） | C14: No | D14: Yes | E14: 05_APPENDIX(将来) | F14: 既往知見 | G14: Appendix向け。
A15: G9 | B15: 文献候補比較表（文献調査後追加予定） | C15: No | D15: Yes(予定) | E15: literature_candidate_list | F15: 文献調査後 | G15: 調査後に具体化。DataStatus管理。

Sheet 02_LDNB_GEOMETRY_DIAGNOSTIC
A1: 02_LDNB_GEOMETRY_DIAGNOSTIC — L_DNB/DH診断・幾何L/DH比較（H-50H1）
A2: 出典: 05_L_LDNB_AUDIT_MEMO / 01_existing_data_position (internalブック)。値は値化済。L_DNB=結果量・診断用、L_geometry=探索条件・補正入力候補。
A4: 表1: 用語定義— L_DNB/DH と 幾何L/DH の区別
A5: Quantity | B5: Definition | C5: UseFor | D5: DoNotUseFor | E5: Notes
A6: L_DNB | B6: DNB発生位置に基づく長さ。計算・収束の結果として得られる量。 | C6: 診断(L_DNB/DH)、文献との診断比較 | D6: 補正式の入力(結果量のため循環属性) | E6: raw系 R列、F1F2系 R列実体がこれ
A7: L_DNB/DH | B7: L_DNBをDHで無次元化した診断量 | C7: 診断図の軸、群別の高め/低め判定 | D7: 補正式入力、幾何L/DHとの混同 | E7: PPT Slide 5用
A8: L_geometry | B8: 幾何長さ（試験条件として事前に分かる量） | C8: 探索条件・補正入力候補 | D8: L_DNB/DH診断との混同 | E8: raw系 BR列
A9: 幾何L/DH | B9: L_geometryをDHで無次元化。事前に分かる探索条件量 | C9: 探索条件図の軸、同程P/Gで大L/DHの単管探し | D9: L_DNB/DH診断との混同、補正式入力 | E9: PPT Slide 6用
A11: 表2: データセット別 L_DNB/DH 診断
A12: Dataset | B12: N | C12: L_DNB_over_DH_min | D12: L_DNB_over_DH_max | E12: L_DNB_over_DH_mean | F12: PM_ratio_mean | G12: Diagnosis | H12: Notes
A13: ST | B13: 86 | C13: 64.516 | D13: 80 | E13: 68.6 | F13: 1.115 | G13: 高め (PM>1) | H13: 短い側。L_DNB/DHが小さいとP依存F2Pで高めに出る傂向
A14: 108 | B14: 14 | C14: 137.969 | D14: 149.795 | E14: 139.7 | F14: 1.062 | G14: やや高め (PM>1) | H14: 中間。御安全側だが群平均差残る
A15: 161 | B15: 23 | C15: 361.355 | D15: 361.355 | E15: 361.4 | F15: 0.906 | G15: 低め (PM<1) | H15: 大L/DH側。L_DNB/DH≈幾何L/DH
A16: 164 | B16: 21 | C16: 241.623 | D16: 289.084 | E16: 286.8 | F16: 0.889 | G16: 低め (PM<1) | H16: L_DNB/DH < 幾何L/DH（DNB位置が手前）
A18: 表3: データセット別 幾何L/DH 探索条件
A19: Dataset | B19: N | C19: L_geometry_over_DH_min | D19: L_geometry_over_DH_max | E19: L_geometry_over_DH_mean | F19: SearchTarget | G19: Notes
A20: ST | B20: 86 | C20: 64.516 | D20: 80 | E20: 68.6 | F20: 現在カバー済 | G20: 小さいL/DH側のみ。大L/DH向け単管データなし
A21: 108(バンドル) | B21: 14 | C21: 189.184 | D21: 189.184 | E21: 189.2 | F21: 単管でL/DH≈189相当を探す | G21: 偶数加熱バンドル。単管で同相当が候補
A22: 161(バンドル) | B22: 23 | C22: 362.417 | D22: 362.417 | E22: 362.4 | F22: 単管でL/DH≈362相当を探す | G22: 一様加熱バンドル
A23: 164(バンドル) | B23: 21 | C23: 362.417 | D23: 362.417 | E23: 362.4 | F23: 単管でL/DH≈362相当を探す | G23: 余弦加熱バンドル
A25: 表4: L_DNB/DH と 幾何L/DH の対比要点
A26: Item | B26: Content | C26: PublicPPT | D26: Notes
A27: 最重要区別 | B27: L_DNBは結果量(診断用)、幾何Lは探索条件(補正入力候補)。混同しない。 | C27: 必ず分けて示す | D27: PPT軸ラベルに明記
A28: 161の専間刎 | B28: 161はL_DNB/DH≈幾何L/DH (≈361-362)。コインシデンスだが混同しない。 | C28: 対比図はAppendix | D28: 108・164で大きく長れる
A29: 108・164の差異 | B29: 108: L_DNB/DH(139.7) ≪ 幾何L/DH(189.2)。164: L_DNB/DH(286.8) < 幾何L/DH(362.4)。DNB位置が管末端に尾きない。 | C29: 診断図で示す | D29: L_DNB < L_geometry
A30: Excel内部事情 | B30: F1F2系R列見出しが「L」だが実体はL_DNB。Public本文に写かない。 | C30: 出さない | D30: Internalのみ

Sheet 03_GEOMETRY_LDH_SEARCH
A1: 03_GEOMETRY_LDH_SEARCH — 幾何L/DH探索条件（H-50H1）
A2: 出典: 01_existing_data_position / 05_L_LDNB_AUDIT_MEMO (internal)。周L_geometry=探索条件・補正入力候補。L_DNBと混同しない。
A4: 表1: 現有データの幾何条件・カバレッジ
A5: Dataset | B5: Type | C5: N | D5: L_geom_over_DH | E5: DH_range_m | F5: L_range_m | G5: HeatingShape | H5: Coverage | I5: Notes
A6: ST | B6: 単管/一様加熱 | C6: 86 | D6: 64.5 – 80 | E6: 0.001905 – 0.007772 | F6: 0.1524 – 0.5906 | G6: uniform | H6: 現在カバー済 | I6: 小さいL/DH側のみ。大L/DH単管なし
A7: 108 | B7: バンドル/偶数加熱 | C7: 14 | D7: ≈ 189.2 | E7: ※バンドルのためDHは相当値 | F7: ※同上 | G7: μcosine | H7: 単管で展開必要 | I7: 同程P/Gで単管L/DH≈189のデータを探す
A8: 161 | B8: バンドル/一様加熱 | C8: 23 | D8: ≈ 362.4 | E8: ※バンドル | F8: ※同上 | G8: uniform | H8: 単管で展開必要 | I8: 同程P/Gで単管L/DH≈362のデータを探す
A9: 164 | B9: バンドル/余弦加熱 | C9: 21 | D9: ≈ 362.4 | E9: ※バンドル | F9: ※同上 | G9: cosine | H9: 単管で展開必要 | I9: 同程P/Gで単管L/DH≈362のデータを探す
A11: 表2: 追加単管データ標的条件
A12: Priority | B12: TargetL_geom_over_DH | C12: HeatingShape | D12: Reason | E12: DataStatus | F12: Notes
A13: 1（最高） | B13: ≈189 単管一様加熱 | C13: uniform | D13: 108相当のカバレッジなし | E13: 未取得 | F13: Thompson & Macbeth等から探索
A14: 1（最高） | B14: ≈362 単管一様加熱 | C14: uniform | D14: 161/164相当のカバレッジなし | E14: 未取得 | F14: Thompson & Macbeth等から探索
A15: 2 | B15: ≈189 単管非一様（cos/μcosine） | C15: cosine or μcosine | D15: 加熱形状依存性の確認 | E15: 未取得 | F15: 候補があれば追加
A16: 3 | B16: 任意 大L/DH単管 | C16: any | D16: P依存F2Pの棄否判断に使用 | E16: 未取得 | F16: 低優先だがあれば有用
A18: 表3: 探索向きメッセージ（PPT Slide 6）
A19: Item | B19: Content | C19: PublicPPT
A20: 現有STの位置づけ | B20: L/DH=64.5–80の短い単管のみ。大L/DH側(108相当≈189、161/164相当≈362)は未カバー。 | C20: Yes(Slide 6)
A21: 追加探索の方向 | B21: 同程P/GでL/DH≈189または≈362の単管データを探す。 | C21: Yes(Slide 6)
A22: 言うべきこと | B22: 幾何L/DHは探索条件・補正入力候補。L_DNB/DHと混同しない。 | C22: Yes
A23: 言わないこと | B23: L_DNB/DHを補正式入力に使うと言わない。Excel内部事情（R列表記等）はPublicに出さない。 | C23: No(Internal only)
A24: 文献探索時の候補判定基準 H-50I
A25: ・最優先は、同程度P/G条件で、大きい幾何L/DHを持つ単管CHFデータ。
A26: ・現有STは幾何L/DH 64.5〜80付近。
A27: ・108相当は幾何L/DH 約189。
A28: ・161/164相当は幾何L/DH 約362。
A29: ・まずは幾何L/DH 150〜400程度を持つ単管データを優先的に探す。
A30: ・P/Gが大きく外れる場合は、L/DHだけ一致しても優先度を下げる。
A31: ・文献にL_DNBまたはCHF位置がある場合は、診断比較に使えるため評価を上げる。
A32: ・文献に幾何L/DHしかない場合も、探索条件としては有用。
A33: ・L_DNBは結果量なので、補正式入力には使わない。
A34: ・候補の登録・条件確認はliterature_candidate_listで行う。

Sheet literature_candidate_list
A1: literature_candidate_list — 文献候補管理表（H-50I整備）
A2: 目的: 同程P/G条件で現有STが未カバーの大きい幾何L/DH側を持つ単管CHFデータを探す。候補段階では本表で条件確認し、DataStatus=ReadyToAddのみ後綟tm_*へ追加。詳細は03_GEOMETRY_LDH_SEARCH参照。
A4: 表1: 文献候補（条件確認用）
A5: CandidateID | B5: SourcePaper | C5: AuthorYear | D5: DOI_or_URL | E5: DataSourceType | F5: System | G5: HeatingShape | H5: P_MPa | I5: G_kg_m2s | J5: DH_m | K5: L_geometry_m | L5: L_geometry_over_DH | M5: L_DNB_or_CHF_position_available | N5: L_DNB_m | O5: L_DNB_over_DH | P5: qCHF_available | Q5: DataDigitized | R5: DataStatus | S5: ConditionMatch_P | T5: ConditionMatch_G | U5: ConditionMatch_LDH | V5: Priority | W5: ReasonToUse | X5: ReasonToReject | Y5: NextAction | Z5: Notes
A6: LIT-001 | B6: A mechanistic critical heat flux model for wide range of subcooled and low quality flow boiling | C6: Kwon & Chang (1999) | D6: Nucl. Eng. Des. 188, 27–47 | E6: Review | F6: SingleTube | G6: Uniform | H6: 2.14–20.0（検証DB全体） | I6: 452–7499（検証DB全体） | L6: 広範囲。Table 1から孫引き候補を抽出 | M6: Unknown | P6: No | Q6: No | R6: Candidate | S6: Good | T6: Good | U6: Maybe | V6: A | W6: Weisman系bubble crowding後続展開。壁面付着気泡を粗さ・抗力源として扱い、Celata系薄液膜ドライアウトの前段階説明に使える。 | Y6: モデル背景文献として文献リストへ登録。データ追加はReferencesの原典確認後。 | Z6: tm_*へ直接追加する実験データではなく、物理説明・孫引き起点。
A7: LIT-002 | B7: Prediction of critical heat flux in flow boiling at low qualities | C7: Weisman & Pei (1983) | D7: Int. J. Heat Mass Transfer 26, 1463–1477 | E7: Review | F7: SingleTube | G7: Unknown | M7: Unknown | P7: No | Q7: No | R7: NeedPaper | S7: Unknown | T7: Unknown | U7: Maybe | V7: A | W7: near-wall bubble crowdingモデルの親筋。低クオリティDNB/CHFの壁面気泡混雑・液供給制限の根拠確認に使う。 | Y7: 原著を入手し、モデル仮定・使用データ・適用範囲を確認。 | Z7: Kwon & Changで主要先行研究として引用。
A8: LIT-003 | B8: Prediction of CHF in highly subcooled flow boiling | C8: Weisman & Ileslamlou (1988) | D8: Int. J. Heat Mass Transfer 31, 721–727 | E8: Review | F8: SingleTube | G8: Unknown | M8: Unknown | P8: No | Q8: No | R8: NeedPaper | S8: Unknown | T8: Unknown | U8: Maybe | V8: A | W8: 強サブクール条件のWeisman系モデル。PWR DNBに近いサブクール側の物理説明候補。 | Y8: 原著を入手し、P/G条件・構成式・Celata説明への使い方を確認。 | Z8: ONB/OSV以降の二相流発達とTw補正の説明に接続可能。
A9: LIT-004 | B9: Prediction of critical heat flux in flow boiling at intermediate qualities | C9: Ying & Weisman (1986) | D9: Int. J. Heat Mass Transfer 29, 1639–1648 | E9: Review | F9: SingleTube | G9: Unknown | M9: Unknown | P9: No | Q9: No | R9: NeedPaper | S9: Unknown | T9: Unknown | U9: Maybe | V9: B | W9: Weisman系の中間クオリティ領域。低クオリティ・強サブクール原著との比較用。 | Y9: 原著を入手し、今回対象のサブクール/低クオリティに対する優先度を再判定。 | Z9: 優先度はWeisman & Pei、Weisman & Ileslamlouより一段下。
A10: LIT-005 | B10: Boiling water heat transfer in uniformly heated round tubes: A compilation of world data with accurate correlations | C10: Thompson & Macbeth (1964) | D10: AEEW-R-356 | E10: Table | F10: SingleTube | G10: Uniform | H10: 原典再確認（既存Table 10は13.8 MPa抽出実績） | I10: 2400–4000は既存抽出実績 | L10: 原典で系列確認。目標150–400 | M10: Unknown | P10: Yes | Q10: NeedDigitize | R10: NeedPaper | S10: Maybe | T10: Good | U10: Maybe | V10: A | W10: 既存発表で使用実績があり、Table 10以外にも大L/DH系列がある可能性。108/161/164相当の幾何L/DH補完候補。 | Y10: 原典でTable/系列を確認し、P/G/DH/L/DHが合うデータだけReadyToAdd判定。 | Z10: Kwon & Chang Table 1にも主要DBとして引用。既存抽出条件との整合を確認する。
A11: LIT-006 | B11: Round tube burnout data for flow of boiling water at pressure between 30 and 200 bar | C11: Becker et al. (1971) | D11: KTH-NEL-14 | E11: Table | F11: SingleTube | G11: Uniform | H11: 3.04–20.0（K&C Table 1） | I11: 452–7438（K&C Table 1） | J11: 0.004–0.020 | K11: 0.3–4.97 | L11: 約15–1240（範囲からの概算） | M11: Unknown | P11: Yes | Q11: Unknown | R11: NeedPaper | S11: Good | T11: Good | U11: Good | V11: A | W11: 高圧・長尺円管データを含む可能性が高く、L/DH 150–400の本命候補。 | Y11: 原典を入手し、P≈PWR、G≈現有条件、L/DH 150–400の系列有無を確認。 | Z11: Beckerは最優先の孫引き先。
A12: LIT-007 | B12: Analysis and generalization of experimental data on heat transfer crisis associated with forced convection of cooling water in tubes | C12: Zenkevich (1974) | D12: AECL-Tr-Misc-304 | E12: Table | F12: SingleTube | G12: Uniform | H12: 5.89–19.62（K&C Table 1） | I12: 497–6694（K&C Table 1） | J12: 0.005–0.011 | K12: 0.3–6.0 | L12: 約27–1200（範囲からの概算） | M12: Unknown | P12: Yes | Q12: Unknown | R12: NeedPaper | S12: Good | T12: Good | U12: Good | V12: A | W12: 点数が多く、高圧・長尺・大L/DH側を含む可能性が高い。Beckerと並ぶ本命候補。 | Y12: 資料入手性を確認し、L/DH 150–400かつP/Gが近い系列を抽出。 | Z12: AECL翻訳資料の可能性あり。入手性が課題。
A13: LIT-008 | B13: Nucleate boiling characteristics and the critical heat flux occurrence in sub-cooled axial flow water system | C13: Weatherhead (1963) | D13: ANL-6675 | E13: Secondary | F13: SingleTube | G13: Uniform | M13: Unknown | P13: Unknown | Q13: Unknown | R13: NeedPaper | S13: Unknown | T13: Unknown | U13: Maybe | V13: B | W13: サブクール軸方向流CHFのパラメータトレンド確認に使われた文献。データ表があれば補助候補。 | Y13: 原典を確認し、データ表・P/G/DH/L/DH範囲の有無を確認。 | Z13: Kwon & Chang 4.3のparametric trends比較で使用。
A14: LIT-009 | B14: Investigation into the critical heat flux in boiling water | C14: Mayinger (1967) | D14: EUR-3347 | E14: Table | F14: SingleTube | G14: Uniform | H14: 7.0–10.24（K&C Table 1） | I14: 2255–3734（K&C Table 1） | J14: 0.007 | K14: 0.56–0.98 | L14: 約80–140 | M14: Unknown | P14: Yes | Q14: Unknown | R14: NeedPaper | S14: Maybe | T14: Good | U14: Poor | V14: C | W14: 現有STよりやや長いが、目標L/DH 150–400には届きにくい。境界領域の補助候補。 | Y14: 優先度低で原典確認。L/DHが目標に届かない場合は参考扱い。 | Z14: 108相当189、161/164相当362の補完本命ではない。
A15: LIT-010 | B15: DNB (Burnout) studies on an open lattice core | C15: Tong (1964) | D15: WCAP-3736 | E15: Secondary | F15: Bundle | G15: Unknown | H15: 5.17–13.79（K&C Table 1） | I15: 678–7499（K&C Table 1） | J15: 0.006–0.013 | K15: 0.38–3.66 | L15: 約29–610（範囲からの概算） | M15: Unknown | P15: Yes | Q15: Unknown | R15: NeedPaper | S15: Maybe | T15: Good | U15: Maybe | V15: B | W15: PWR体系接続には有用な可能性。ただしopen lattice coreであり、単管データとして使えるかは要確認。 | X15: 単管ではない可能性が高い。 | Y15: 原典を確認し、単管相当データの有無と体系を判定。 | Z15: 単管CHF補完というより、PWR燃料体系接続文献候補。
A18: 表2: 入力ルール（各列の許容値）
A19: Column | B19: AllowedValues | C19: Meaning
A20: DataSourceType | B20: Table / Graph / Review / Secondary / Unknown | C20: データの出所形式。Graphは要数値化。Secondaryは孫引用。
A21: System | B21: SingleTube / Bundle / Unknown | C21: 単管かバンドルか。探索標的は単管。
A22: HeatingShape | B22: Uniform / Cosine / MicroCosine / Unknown | C22: 加熱形状。
A23: L_DNB_or_CHF_position_available | B23: Yes / No / Unknown | C23: DNBまたはCHF位置が文献にあるか。Yesなら診断比較に使える。
A24: qCHF_available | B24: Yes / No / Unknown | C24: CHF実験値が取得できるか。
A25: DataDigitized | B25: Yes / No / NeedDigitize / Unknown | C25: 数値化済みか。Graph出典はNeedDigitize。
A26: DataStatus | B26: Candidate / NeedPaper / NeedDigitize / ReadyToAdd / Rejected | C26: 候補の進捗状態。ReadyToAddのみ後綟tm_*追加対象。
A27: ConditionMatch_P / _G / _LDH | B27: Good / Maybe / Poor / Unknown | C27: 現有データのP/Gと幾何L/DH条件との近さ・有用性。
A28: Priority | B28: A / B / C / Reject | C28: A=追加候補として強い。B=条件確認後に検討。C=参考。Reject=使わない。
A30: 表3: 列の意味（キー列の補足）
A31: Column | B31: Meaning
A32: L_geometry_m / _over_DH | B32: 幾何長さ・幾何L/DH。試験条件として事前に分かる量。探索条件・補正入力候補。
A33: L_DNB_m / _over_DH | B33: DNBまたはCHF発生位置に基づく長さ・その無次元量。結果量・診断用。補正式入力には使わない。
A34: ReasonToUse | B34: この候補を使う理由。
A35: ReasonToReject | B35: 使わない理由。
A36: NextAction | B36: 次にやること。例：文献取り寄せ、図から数値化、条件確認、保留、除外。
A38: 表4: 優先度判定ルール H-50I
A39: Priority | B39: Condition | C39: Note
A40: A | B40: 同程P/G・単管・幾余L/DHが150〜400程度。L_DNB/CHF位置もあるとなお良。 | C40: 追加候補として強い。
A41: B | B41: 幾何L/DHは有望だがP/Gまたは単管条件が未確認。 | C41: 条件確認後に検討。
A42: C | B42: 参考価値はあるがP/Gが大きく外れる、または幾何L/DHのみ。 | C42: 参考。低優先。
A43: Reject | B43: 単管でない、またはP/Gが大きく外れ、且つ幾何L/DHも一致しない。 | C43: 使わない。

Sheet tm_ST
A1: No_TableNo | B1: P | C1: Ts | D1: rhoG | E1: rhoL | F1: HG | G1: HL | H1: muG | I1: muL | J1: KL | K1: CPL | L1: sigma | M1: No | N1: G | O1: A | P1: Pw | Q1: DH | R1: L_DNB | S1: q_in | T1: Tin | U1: Tf | V1: f(beta) | W1: Re | X1: f | Y1: f_left | Z1: f_rihgt | AA1: f_balance | AB1: DB | AC1: Tw | AD1: y_plus | AE1: Tm | AF1: Tw_balance | AG1: y_star | AH1: tauw | AI1: Utau | AJ1: y_plus2 | AK1: Q | AL1: Pr | AM1: T(y_plus) | AN1: y_star_balance | AO1: delta | AP1: UB | AQ1: LB | AR1: YB | AS1: YB_plus | AT1: Karman_UB | AU1: UBL | AV1: UB_left | AW1: CD | AX1: UB_right | AY1: UB_balance | AZ1: HG-HL | BA1: LB/UB | BB1: q_P | BC1: dq_chf | BD1: dq_ratio | BE1: q_M | BF1: PM_ratio | BG1: F_form | BH1: x_Mes | BI1: A_corr | BJ1: σ_corr | BK1: Fcorr | BL1: Tsub | BM1: q_P_MW | BN1: Tsub2 | BO1: Fcorr2 | BP1: (Tsub-40)^2 | BQ1: F2 | BR1: L
A2: 9.01_10 | B2: 13789520 | C2: 608.62111 | D2: 85.147894 | E2: 624.86627 | F2: 2643264.4 | G2: 1562687 | H2: 2.2019594e-05 | I2: 7.2223253e-05 | J2: 0.49112125 | K2: 7679.7516 | L2: 0.0065036383 | M2: 1 | N2: 2440.8 | O2: 2.8502296e-06 | P2: 0.005984734 | Q2: 0.001905 | R2: 0.1524 | S2: 4124066.3 | T2: 499.9514 | U2: 570.35522 | V2: 0.03 | W2: 64379.875 | X2: 0.035268931 | Y2: 5.3248068 | Z2: 5.3248068 | AA2: -9.2647987e-09 | AB2: 1.8567696e-05 | AC2: 692.22338 | AD2: 2137.3286 | AE2: 570.35522 | AF2: 0 | AG2: 1.8650868e-05 | AH2: 42.031957 | AI2: 0.25935598 | AJ2: 41.850954 | AK2: 5.2415739 | AL2: 1.129368 | AM2: 608.62111 | AN2: 4.5620254e-09 | AO2: 8.3172384e-08 | AP2: 3.4238055 | AQ2: 4.6518328e-05 | AR2: 9.3670203e-06 | AS2: 21.018793 | AT2: 12.177085 | AU2: 3.1581997 | AV2: 0.2656058 | AW2: 0.01116311 | AX2: 0.26560579 | AY2: 9.7350428e-09 | AZ2: 1080577.4 | BA2: 1.3586732e-05 | BB2: 4133396.9 | BC2: 9330.5452 | BD2: 0.22624624 | BE2: 4038400 | BF2: 1.0235234 | BG2: 1 | BH2: -0.05 | BI2: 0.046 | BJ2: 5625 | BK2: 1.0198921 | BL2: 108.66971 | BM2: 4.1333969 | BN2: 108.66971 | BO2: 1.0198921 | BP2: 4715.529 | BQ2: Not calculated | BR2: 0.1524
A3: 10.01_10 | B3: 13789520 | C3: 608.62111 | D3: 85.147894 | E3: 624.86627 | F3: 2643264.4 | G3: 1562687 | H3: 2.2019594e-05 | I3: 7.2223253e-05 | J3: 0.49112125 | K3: 7679.7516 | L3: 0.0065036383 | M3: 2 | N3: 2454.36 | O3: 2.8502296e-06 | P3: 0.005984734 | Q3: 0.001905 | R3: 0.1524 | S3: 4160719.6 | T3: 499.3915 | U3: 570.02862 | V3: 0.03 | W3: 64737.541 | X3: 0.035176483 | Y3: 5.3317993 | Z3: 5.3317993 | AA3: -4.9712446e-08 | AB3: 1.8411355e-05 | AC3: 692.63788 | AD3: 2146.384 | AE3: 570.02862 | AF3: 9.2637868e-07 | AG3: 1.8494568e-05 | AH3: 42.388874 | AI3: 0.26045482 | AJ3: 41.676058 | AK3: 5.2710217 | AL3: 1.129368 | AM3: 608.62111 | AN3: 7.4333798e-08 | AO3: 8.3213109e-08 | AP3: 3.4322531 | AQ3: 4.6289625e-05 | AR3: 9.2888906e-06 | AS3: 20.931786 | AT3: 12.156344 | AU3: 3.1661784 | AV3: 0.26607463 | AW3: 0.011069116 | AX3: 0.26607462 | AY3: 1.0037117e-08 | AZ3: 1080577.4 | BA3: 1.3486659e-05 | BB3: 4166106.4 | BC3: 5386.7678 | BD3: 0.12946721 | BE3: 4038400 | BF3: 1.031623 | BG3: 1 | BH3: -0.055 | BI3: 0.046 | BJ3: 5625 | BK3: 1.019621 | BL3: 109.22961 | BM3: 4.1661064 | BN3: 109.22961 | BO3: 1.019621 | BP3: 4792.7389 | BQ3: Not calculated | BR3: 0.1524
A4: 11.01_10 | B4: 13789520 | C4: 608.62111 | D4: 85.147894 | E4: 624.86627 | F4: 2643264.4 | G4: 1562687 | H4: 2.2019594e-05 | I4: 7.2223253e-05 | J4: 0.49112125 | K4: 7679.7516 | L4: 0.0065036383 | M4: 3 | N4: 3037.44 | O4: 2.8502296e-06 | P4: 0.005984734 | Q4: 0.001905 | R4: 0.1524 | S4: 5012464.7 | T4: 495.51146 | U4: 564.27313 | V4: 0.03 | W4: 80117.178 | X4: 0.031869501 | Y4: 5.6016036 | Z4: 5.6016036 | AA4: -2.5984783e-08 | AB4: 1.3268567e-05 | AC4: 693.21851 | AD4: 2528.3563 | AE4: 564.27313 | AF4: 0 | AG4: 1.3343595e-05 | AH4: 58.818453 | AI4: 0.30680558 | AJ4: 35.419804 | AK4: 5.4463954 | AL4: 1.129368 | AM4: 608.62111 | AN4: 8.0265181e-09 | AO4: 7.5028138e-08 | AP4: 3.7673757 | AQ4: 3.8420622e-05 | AR4: 6.7093117e-06 | AS4: 17.809481 | AT4: 11.348655 | AU4: 3.4818307 | AV4: 0.28554509 | AW4: 0.0079772136 | AX4: 0.28554508 | AY4: 3.7904002e-09 | AZ4: 1080577.4 | BA4: 1.0198245e-05 | BB4: 4967543.5 | BC4: -44921.21 | BD4: -0.89619004 | BE4: 5395050 | BF4: 0.9207595 | BG4: 1 | BH4: -0.033 | BI4: 0.046 | BJ4: 5625 | BK4: 1.0177861 | BL4: 113.10965 | BM4: 4.9675435 | BN4: 113.10965 | BO4: 1.0177861 | BP4: 5345.021 | BQ4: Not calculated | BR4: 0.1524
A5: 12.01_10 | B5: 13789520 | C5: 608.62111 | D5: 85.147894 | E5: 624.86627 | F5: 2643264.4 | G5: 1562687 | H5: 2.2019594e-05 | I5: 7.2223253e-05 | J5: 0.49112125 | K5: 7679.7516 | L5: 0.0065036383 | M5: 4 | N5: 3118.8 | O5: 2.8502296e-06 | P5: 0.005984734 | Q5: 0.001905 | R5: 0.1524 | S5: 6642123.1 | T5: 458.88286 | U5: 547.62343 | V5: 0.03 | W5: 82263.174 | X5: 0.03149114 | Y5: 5.6351543 | Z5: 5.6351543 | AA5: -3.3351511e-08 | AB5: 1.2736534e-05 | AC5: 723.24995 | AD5: 2580.6236 | AE5: 547.62343 | AF5: 1.2324994e-06 | AG5: 1.2832823e-05 | AH5: 61.275429 | AI5: 0.313148 | AJ5: 34.768174 | AK5: 7.4019463 | AL5: 1.129368 | AM5: 608.62111 | AN5: 4.5659135e-08 | AO5: 9.6288907e-08 | AP5: 3.8154368 | AQ5: 3.7458789e-05 | AR5: 6.464556e-06 | AS5: 17.514526 | AT5: 11.265153 | AU5: 3.5276601 | AV5: 0.28777678 | AW5: 0.0076573493 | AX5: 0.28777677 | AY5: 6.0832119e-09 | AZ5: 1080577.4 | BA5: 9.8176934e-06 | BB5: 6622313.9 | BC5: -19809.265 | BD5: -0.29823695 | BE5: 6688600 | BF5: 0.99008969 | BG5: 1 | BH5: -0.075 | BI5: 0.046 | BJ5: 5625 | BK5: 1.0054073 | BL5: 149.73825 | BM5: 6.6223139 | BN5: 149.73825 | BO5: 1.0054073 | BP5: 12042.483 | BQ5: Not calculated | BR5: 0.1524
A6: 13.01_10 | B6: 13789520 | C6: 608.62111 | D6: 85.147894 | E6: 624.86627 | F6: 2643264.4 | G6: 1562687 | H6: 2.2019594e-05 | I6: 7.2223253e-05 | J6: 0.49112125 | K6: 7679.7516 | L6: 0.0065036383 | M6: 5 | N6: 3118.8 | O6: 2.8502296e-06 | P6: 0.005984734 | Q6: 0.001905 | R6: 0.1524 | S6: 5270594.1 | T6: 491.66308 | U6: 562.07965 | V6: 0.03 | W6: 82263.174 | X6: 0.03149114 | Y6: 5.6351543 | Z6: 5.6351543 | AA6: -3.3351511e-08 | AB6: 1.2736534e-05 | AC6: 696.02091 | AD6: 2580.6236 | AE6: 562.07965 | AF6: 9.6020904e-07 | AG6: 1.2813124e-05 | AH6: 61.275429 | AI6: 0.313148 | AJ6: 34.714802 | AK6: 5.6450817 | AL6: 1.129368 | AM6: 608.62111 | AN6: 2.4413453e-08 | AO6: 7.6589411e-08 | AP6: 3.8109938 | AQ6: 3.7546183e-05 | AR6: 6.4448565e-06 | AS6: 17.461154 | AT6: 11.249893 | AU6: 3.5228815 | AV6: 0.28811228 | AW6: 0.0076573493 | AX6: 0.28811228 | AY6: 5.9074059e-09 | AZ6: 1080577.4 | BA6: 9.8520715e-06 | BB6: 5249091.5 | BC6: -21502.544 | BD6: -0.40797192 | BE6: 5679000 | BF6: 0.92429856 | BG6: 1 | BH6: -0.036 | BI6: 0.046 | BJ6: 5625 | BK6: 1.0160506 | BL6: 116.95802 | BM6: 5.2490915 | BN6: 116.95802 | BO6: 1.0160506 | BP6: 5922.5376 | BQ6: Not calculated | BR6: 0.1524
A7: 14.01_10 | B7: 13789520 | C7: 608.62111 | D7: 85.147894 | E7: 624.86627 | F7: 2643264.4 | G7: 1562687 | H7: 2.2019594e-05 | I7: 7.2223253e-05 | J7: 0.49112125 | K7: 7679.7516 | L7: 0.0065036383 | M7: 6 | N7: 3118.8 | O7: 2.8502296e-06 | P7: 0.005984734 | Q7: 0.001905 | R7: 0.1524 | S7: 5246751.9 | T7: 492.22869 | U7: 562.32671 | V7: 0.03 | W7: 82263.174 | X7: 0.03149114 | Y7: 5.6351543 | Z7: 5.6351543 | AA7: -3.3351511e-08 | AB7: 1.2736534e-05 | AC7: 695.555 | AD7: 2580.6236 | AE7: 562.32672 | AF7: 9.5554992e-07 | AG7: 1.2812504e-05 | AH7: 61.275429 | AI7: 0.313148 | AJ7: 34.713125 | AK7: 5.6150323 | AL7: 1.129368 | AM7: 608.62111 | AN7: 2.3977464e-08 | AO7: 7.597026e-08 | AP7: 3.8108539 | AQ7: 3.7548939e-05 | AR7: 6.4442374e-06 | AS7: 17.459476 | AT7: 11.249413 | AU7: 3.522731 | AV7: 0.28812286 | AW7: 0.0076573493 | AX7: 0.28812285 | AY7: 5.9018651e-09 | AZ7: 1080577.4 | BA7: 9.8531562e-06 | BB7: 5206084.5 | BC7: -40667.38 | BD7: -0.7750963 | BE7: 5521250 | BF7: 0.94291773 | BG7: 1 | BH7: -0.048 | BI7: 0.046 | BJ7: 5625 | BK7: 1.0163 | BL7: 116.39242 | BM7: 5.2060845 | BN7: 116.39242 | BO7: 1.0163 | BP7: 5835.8019 | BQ7: Not calculated | BR7: 0.1524
A8: 15.01_10 | B8: 13789520 | C8: 608.62111 | D8: 85.147894 | E8: 624.86627 | F8: 2643264.4 | G8: 1562687 | H8: 2.2019594e-05 | I8: 7.2223253e-05 | J8: 0.49112125 | K8: 7679.7516 | L8: 0.0065036383 | M8: 7 | N8: 3132.36 | O8: 2.8502296e-06 | P8: 0.005984734 | Q8: 0.001905 | R8: 0.1524 | S8: 6662660.1 | T8: 458.88286 | U8: 547.51246 | V8: 0.03 | W8: 82620.84 | X8: 0.031429667 | Y8: 5.6406625 | Z8: 5.6406625 | AA8: -2.4900442e-08 | AB8: 1.2651196e-05 | AC8: 723.16767 | AD8: 2589.3127 | AE8: 547.51246 | AF8: 0 | AG8: 1.2748365e-05 | AH8: 61.68876 | AI8: 0.31420239 | AJ8: 34.655647 | AK8: 7.4005062 | AL8: 1.129368 | AM8: 608.62111 | AN8: 2.5374561e-08 | AO8: 9.7169062e-08 | AP8: 3.8228184 | AQ8: 3.7314268e-05 | AR8: 6.422767e-06 | AS8: 17.459898 | AT8: 11.249533 | AU8: 3.5346302 | AV8: 0.28818819 | AW8: 0.007606043 | AX8: 0.28818819 | AY8: 6.4917222e-09 | AZ8: 1080577.4 | BA8: 9.7609313e-06 | BB8: 6721709.3 | BC8: 59049.239 | BD8: 0.88627123 | BE8: 6751700 | BF8: 0.99555805 | BG8: 1 | BH8: -0.071 | BI8: 0.046 | BJ8: 5625 | BK8: 1.0054073 | BL8: 149.73825 | BM8: 6.7217093 | BN8: 149.73825 | BO8: 1.0054073 | BP8: 12042.483 | BQ8: Not calculated | BR8: 0.1524
A9: 16.01_10 | B9: 13789520 | C9: 608.62111 | D9: 85.147894 | E9: 624.86627 | F9: 2643264.4 | G9: 1562687 | H9: 2.2019594e-05 | I9: 7.2223253e-05 | J9: 0.49112125 | K9: 7679.7516 | L9: 0.0065036383 | M9: 8 | N9: 3145.92 | O9: 2.8502296e-06 | P9: 0.005984734 | Q9: 0.001905 | R9: 0.1524 | S9: 3751771.9 | T9: 527.87377 | U9: 577.56635 | V9: 0.03 | W9: 82978.506 | X9: 0.031368633 | Y9: 5.6461473 | Z9: 5.6461473 | AA9: -1.7290978e-08 | AB9: 1.2566773e-05 | AC9: 666.592 | AD9: 2597.9956 | AE9: 577.56635 | AF9: 0 | AG9: 1.26207e-05 | AH9: 62.103184 | AI9: 0.31525602 | AJ9: 34.423648 | AK9: 3.7493914 | AL9: 1.129368 | AM9: 608.62111 | AN9: 4.3324917e-09 | AO9: 5.3927807e-08 | AP9: 3.8200143 | AQ9: 3.736907e-05 | AR9: 6.3373141e-06 | AS9: 17.285369 | AT9: 11.199302 | AU9: 3.5306475 | AV9: 0.28936685 | AW9: 0.0075552867 | AX9: 0.28936684 | AY9: 6.4923122e-09 | AZ9: 1080577.4 | BA9: 9.7824423e-06 | BB9: 3722274.9 | BC9: -29497.034 | BD9: -0.78621607 | BE9: 4164600 | BF9: 0.89378929 | BG9: 1 | BH9: -0.027 | BI9: 0.046 | BJ9: 5625 | BK9: 1.0342425 | BL9: 80.747335 | BM9: 3.7222749 | BN9: 80.747335 | BO9: 1.0342425 | BP9: 1660.3453 | BQ9: Not calculated | BR9: 0.1524
A10: 17.01_10 | B10: 13789520 | C10: 608.62111 | D10: 85.147894 | E10: 624.86627 | F10: 2643264.4 | G10: 1562687 | H10: 2.2019594e-05 | I10: 7.2223253e-05 | J10: 0.49112125 | K10: 7679.7516 | L10: 0.0065036383 | M10: 9 | N10: 3145.92 | O10: 2.8502296e-06 | P10: 0.005984734 | Q10: 0.001905 | R10: 0.1524 | S10: 3535281.8 | T10: 532.84871 | U10: 579.67386 | V10: 0.03 | W10: 82978.506 | X10: 0.031368633 | Y10: 5.6461473 | Z10: 5.6461473 | AA10: -1.7290978e-08 | AB10: 1.2566773e-05 | AC10: 662.65222 | AD10: 2597.9956 | AE10: 579.67386 | AF10: 6.2652202e-07 | AG10: 1.2617868e-05 | AH10: 62.103184 | AI10: 0.31525602 | AJ10: 34.415921 | AK10: 3.4947048 | AL10: 1.129368 | AM10: 608.62111 | AN10: 4.0275836e-09 | AO10: 5.1094974e-08 | AP10: 3.8193592 | AQ10: 3.738189e-05 | AR10: 6.3344813e-06 | AS10: 17.277643 | AT10: 11.197067 | AU10: 3.5299427 | AV10: 0.28941648 | AW10: 0.0075552867 | AX10: 0.28941648 | AY10: 6.4652687e-09 | AZ10: 1080577.4 | BA10: 9.7874771e-06 | BB10: 3524929.2 | BC10: -10352.655 | BD10: -0.29283818 | BE10: 3943750 | BF10: 0.89380138 | BG10: 1 | BH10: -0.026 | BI10: 0.046 | BJ10: 5625 | BK10: 1.0366402 | BL10: 75.772395 | BM10: 3.5249292 | BN10: 75.772395 | BO10: 1.0366402 | BP10: 1279.6642 | BQ10: Not calculated | BR10: 0.1524
A11: 18.01_10 | B11: 13789520 | C11: 608.62111 | D11: 85.147894 | E11: 624.86627 | F11: 2643264.4 | G11: 1562687 | H11: 2.2019594e-05 | I11: 7.2223253e-05 | J11: 0.49112125 | K11: 7679.7516 | L11: 0.0065036383 | M11: 10 | N11: 3634.08 | O11: 2.8502296e-06 | P11: 0.005984734 | Q11: 0.001905 | R11: 0.1524 | S11: 3515012.9 | T11: 541.31775 | U11: 581.62055 | V11: 0.03 | W11: 95854.481 | X11: 0.029426133 | Y11: 5.8295281 | Z11: 5.8295281 | AA11: -1.1375949e-08 | AB11: 1.0039048e-05 | AC11: 654.95066 | AD11: 2906.7256 | AE11: 581.62055 | AF11: 0 | AG11: 1.0081321e-05 | AH11: 77.740099 | AI11: 0.35271912 | AJ11: 30.76497 | AK11: 3.0519132 | AL11: 1.129368 | AM11: 608.62111 | AN11: 5.4569682e-12 | AO11: 4.2273105e-08 | AP11: 4.0567578 | AQ11: 3.3134781e-05 | AR11: 5.0617971e-06 | AS11: 15.446987 | AT11: 10.63707 | AU11: 3.7518979 | AV11: 0.30485992 | AW11: 0.00603559 | AX11: 0.30485989 | AY11: 2.9307291e-08 | AZ11: 1080577.4 | BA11: 8.1677986e-06 | BB11: 3494637.2 | BC11: -20375.709 | BD11: -0.57967664 | BE11: 4417000 | BF11: 0.7911789 | BG11: 1 | BH11: 0.001 | BI11: 0.046 | BJ11: 5625 | BK11: 1.0402904 | BL11: 67.303354 | BM11: 3.4946372 | BN11: 67.303354 | BO11: 1.0402904 | BP11: 745.47312 | BQ11: Not calculated | BR11: 0.1524
A12: 19.01_10 | B12: 13789520 | C12: 608.62111 | D12: 85.147894 | E12: 624.86627 | F12: 2643264.4 | G12: 1562687 | H12: 2.2019594e-05 | I12: 7.2223253e-05 | J12: 0.49112125 | K12: 7679.7516 | L12: 0.0065036383 | M12: 11 | N12: 3851.04 | O12: 2.8502296e-06 | P12: 0.005984734 | Q12: 0.001905 | R12: 0.1524 | S12: 4025857.1 | T12: 534.00031 | U12: 577.55984 | V12: 0.03 | W12: 101577.14 | X12: 0.028694843 | Y12: 5.9033437 | Z12: 5.9033438 | AA12: -2.692234e-08 | AB12: 9.1675816e-06 | AC12: 659.74607 | AD12: 3041.7457 | AE12: 577.55984 | AF12: 0 | AG12: 9.2124976e-06 | AH12: 85.130041 | AI12: 0.36910326 | AJ12: 29.419501 | AK12: 3.404262 | AL12: 1.129368 | AM12: 608.62111 | AN12: -1.2880719e-10 | AO12: 4.4916051e-08 | AP12: 4.1562829 | AQ12: 3.1566909e-05 | AR12: 4.6287068e-06 | AS12: 14.781469 | AT12: 10.416871 | AU12: 3.8449012 | AV12: 0.31138174 | AW12: 0.0055116544 | AX12: 0.31138174 | AY12: 4.3253842e-09 | AZ12: 1080577.4 | BA12: 7.5949856e-06 | BB12: 3993168 | BC12: -32689.02 | BD12: -0.81197666 | BE12: 4858700 | BF12: 0.82185935 | BG12: 1 | BH12: -0.018 | BI12: 0.046 | BJ12: 5625 | BK12: 1.037172 | BL12: 74.620793 | BM12: 3.993168 | BN12: 74.620793 | BO12: 1.037172 | BP12: 1198.5993 | BQ12: Not calculated | BR12: 0.1524
A13: 20.01_10 | B13: 13789520 | C13: 608.62111 | D13: 85.147894 | E13: 624.86627 | F13: 2643264.4 | G13: 1562687 | H13: 2.2019594e-05 | I13: 7.2223253e-05 | J13: 0.49112125 | K13: 7679.7516 | L13: 0.0065036383 | M13: 12 | N13: 3905.28 | O13: 2.8502296e-06 | P13: 0.005984734 | Q13: 0.001905 | R13: 0.1524 | S13: 4119595.8 | T13: 532.84871 | U13: 576.8034 | V13: 0.03 | W13: 103007.8 | X13: 0.02852248 | Y13: 5.921154 | Z13: 5.921154 | AA13: -8.2254532e-09 | AB13: 8.9685669e-06 | AC13: 660.32968 | AD13: 3075.3091 | AE13: 576.8034 | AF13: 0 | AG13: 9.0140076e-06 | AH13: 87.019097 | AI13: 0.37317603 | AJ13: 29.103264 | AK13: 3.4558054 | AL13: 1.129368 | AM13: 608.62111 | AN13: 3.4825689e-09 | AO13: 4.5440633e-08 | AP13: 4.1804653 | AQ13: 3.1202761e-05 | AR13: 4.5297241e-06 | AS13: 14.624989 | AT13: 10.363658 | AU13: 3.8674688 | AV13: 0.31299651 | AW13: 0.0053920045 | AX13: 0.3129965 | AY13: 4.7917047e-09 | AZ13: 1080577.4 | BA13: 7.4639445e-06 | BB13: 4110729.9 | BC13: -8865.8875 | BD13: -0.21521256 | BE13: 4890250 | BF13: 0.84059709 | BG13: 1 | BH13: -0.026 | BI13: 0.046 | BJ13: 5625 | BK13: 1.0366402 | BL13: 75.772395 | BM13: 4.1107299 | BN13: 75.772395 | BO13: 1.0366402 | BP13: 1279.6642 | BQ13: Not calculated | BR13: 0.1524
... A87: 498.01_10 | B87: 13789520 | C87: 608.62111 | D87: 85.147894 | E87: 624.86627 | F87: 2643264.4 | G87: 1562687 | H87: 2.2019594e-05 | I87: 7.2223253e-05 | J87: 0.49112125 | K87: 7679.7516 | L87: 0.0065036383 | M87: 86 | N87: 3051 | O87: 4.7446062e-05 | P87: 0.024417715 | Q87: 0.0077724 | R87: 0.59055 | S87: 1468476.4 | T87: 572.54323 | U87: 591.59078 | V87: 0.03 | W87: 328337.36 | X87: 0.023180309 | Y87: 6.5681096 | Z87: 6.5681096 | AA87: -1.1745966e-08 | AB87: 1.8080526e-05 | AC87: 633.44645 | AD87: 8837.0014 | AE87: 591.59078 | AF87: 3.3446452e-07 | AG87: 1.8109684e-05 | AH87: 43.164484 | AI87: 0.26282685 | AJ87: 41.180409 | AK87: 1.5604141 | AL87: 1.129368 | AM87: 608.62111 | AN87: 1.9001959e-08 | AO87: 2.9157928e-08 | AP87: 3.4431537 | AQ87: 4.5996994e-05 | AR87: 9.0694211e-06 | AS87: 20.623356 | AT87: 12.082121 | AU87: 3.1755059 | AV87: 0.26764782 | AW87: 0.010870218 | AX87: 0.26764781 | AY87: 1.0569103e-08 | AZ87: 1080577.4 | BA87: 1.3358972e-05 | BB87: 1473759.4 | BC87: 5283.006 | BD87: 0.35976104 | BE87: 2618650 | BF87: 0.56279359 | BG87: 1 | BH87: 0.033 | BI87: 0.046 | BJ87: 5625 | BK87: 1.0458744 | BL87: 36.07788 | BM87: 1.4737594 | BN87: 36.07788 | BO87: 1.0458744 | BP87: 15.383025 | BQ87: Not calculated | BR87: 0.59055

Sheet tm_108
A1: No_TableNo | B1: P | C1: Ts | D1: rhoG | E1: rhoL | F1: HG | G1: HL | H1: muG | I1: muL | J1: KL | K1: CPL | L1: sigma | M1: No | N1: G | O1: A | P1: Pw | Q1: DH | R1: L_DNB | S1: q_in | T1: Tin | U1: Tf | V1: f(beta) | W1: Re | X1: f | Y1: f_left | Z1: f_rihgt | AA1: f_balance | AB1: DB | AC1: Tw | AD1: y_plus | AE1: Tm | AF1: Tw_balance | AG1: y_star | AH1: tauw | AI1: Utau | AJ1: y_plus2 | AK1: Q | AL1: Pr | AM1: T(y_plus) | AN1: y_star_balance | AO1: delta | AP1: UB | AQ1: LB | AR1: YB | AS1: YB_plus | AT1: Karman_UB | AU1: UBL | AV1: UB_left | AW1: CD | AX1: UB_right | AY1: UB_balance | AZ1: HG-HL | BA1: LB/UB | BB1: q_P | BC1: dq_chf | BD1: dq_ratio | BE1: q_M | BF1: PM_ratio | BG1: F_form | BH1: x_Mes | BI1: A_corr | BJ1: σ_corr | BK1: Fcorr | BL1: Tsub | BM1: q_P_MW | BN1: Tsub2 | BO1: Fcorr2 | BP1: (Tsub-40)^2 | BQ1: F2 | BR1: L
A2: 3_108 | B2: 14927149 | C2: 614.91567 | D2: 95.991296 | E2: 604.83147 | F2: 2612762.6 | G2: 1607339.5 | H2: 2.2671477e-05 | I2: 6.9572023e-05 | J2: 0.47825678 | K2: 8454.9053 | L2: 0.0052373024 | M2: 229 | N2: 3507.972 | O2: 0.00010848891 | P2: 0.033674103 | Q2: 0.012886925 | R2: 1.778 | S2: 1550934.6 | T2: 579.81667 | U2: 598.69947 | V2: 0.03 | W2: 1697921.2 | X2: 0.015808189 | Y2: 7.9535119 | Z2: 7.9535119 | AA2: -1.3886858e-08 | AB2: 1.5632157e-05 | AC2: 632.68348 | AD2: 37738.411 | AE2: 598.69947 | AF2: 0 | AG2: 1.566416e-05 | AH2: 40.204068 | AI2: 0.25782071 | AJ2: 35.109502 | AK2: 1.0848455 | AL2: 1.2299352 | AM2: 614.91567 | AN2: 2.7351916e-09 | AO2: 3.2003076e-08 | AP2: 3.163659 | AQ2: 3.9687171e-05 | AR2: 7.8480815e-06 | AS2: 17.590617 | AT2: 11.286828 | AU2: 2.9099781 | AV2: 0.25368096 | AW2: 0.010168984 | AX2: 0.25368094 | AY2: 1.9162515e-08 | AZ2: 1005423.1 | BA2: 1.2544706e-05 | BB2: 1551366.8 | BC2: 432.24421 | BD2: 0.027869918 | BE2: 2915712.6 | BF2: 0.53207125 | BG2: 0.65432795 | BH2: 0.041827592 | BI2: 0.046 | BJ2: 5625 | BK2: 1.045804 | BL2: 35.098999 | BM2: 1.5513668 | BN2: 35.098999 | BO2: 1.045804 | BP2: 24.019806 | BQ2: 1.0093755 | BR2: 2.438
A3: 4_108 | B3: 14582411 | C3: 613.05027 | D3: 92.580958 | E3: 610.99185 | F3: 2622345.6 | G3: 1593812.5 | H3: 2.2466336e-05 | I3: 7.0373615e-05 | J3: 0.48213978 | K3: 8194.8014 | L3: 0.0056080352 | M3: 230 | N3: 3444.24 | O3: 0.00010848891 | P3: 0.033674103 | Q3: 0.012886925 | R3: 1.778 | S3: 1803192.9 | T3: 570.37222 | U3: 593.44226 | V3: 0.03 | W3: 1648084.9 | X3: 0.016115584 | Y3: 7.8772926 | Z3: 7.8772926 | AA3: -7.4168653e-09 | AB3: 1.7206182e-05 | AC3: 634.75374 | AD3: 36985.17 | AE3: 593.44226 | AF3: 3.4753737e-07 | AG3: 1.7244639e-05 | AH3: 39.111769 | AI3: 0.25300903 | AJ3: 37.880499 | AK3: 1.3331875 | AL3: 1.1961216 | AM3: 613.05027 | AN3: 8.6697582e-09 | AO3: 3.8456963e-08 | AP3: 3.2067921 | AQ3: 4.2618773e-05 | AR3: 8.6415481e-06 | AS3: 18.982488 | AT3: 11.667584 | AU3: 2.9520042 | AV3: 0.25478794 | AW3: 0.010917872 | AX3: 0.25478794 | AY3: 1.5837695e-09 | AZ3: 1028533.1 | BA3: 1.3290158e-05 | BB3: 1818438.1 | BC3: 15245.259 | BD3: 0.84545914 | BE3: 3184415.5 | BF3: 0.57104298 | BG3: 0.65432795 | BH3: 0.030903006 | BI3: 0.046 | BJ3: 5625 | BK3: 1.0459414 | BL3: 42.678048 | BM3: 1.8184381 | BN3: 42.678048 | BO3: 1.0459414 | BP3: 7.1719393 | BQ3: 1.0111623 | BR3: 2.438
A4: 5_108 | B4: 16650838 | C4: 623.74675 | D4: 115.08175 | E4: 572.29121 | F4: 2559557.8 | G4: 1675797.4 | H4: 2.3829583e-05 | I4: 6.550994e-05 | J4: 0.45915472 | K4: 10285.253 | L4: 0.0035437209 | M4: 231 | N4: 3437.46 | O4: 0.00010848891 | P4: 0.033674103 | Q4: 0.012886925 | R4: 1.778 | S4: 2133151.3 | T4: 575.92778 | U4: 597.71525 | V4: 0.03 | W4: 1766959.1 | X4: 0.014827407 | Y4: 8.2123491 | Z4: 8.2123491 | AA4: -3.4636383e-09 | AB4: 1.1112386e-05 | AC4: 650.95276 | AD4: 38035.059 | AE4: 597.71525 | AF4: 5.0952758e-07 | AG4: 1.1160673e-05 | AH4: 38.267795 | AI4: 0.25858789 | AJ4: 25.212065 | AK4: 1.5986598 | AL4: 1.4674494 | AM4: 623.74675 | AN4: 9.1565653e-09 | AO4: 4.8286773e-08 | AP4: 2.7350726 | AQ4: 3.1064943e-05 | AR4: 5.6044797e-06 | AS4: 12.660573 | AT4: 9.6424633 | AU4: 2.4934242 | AV4: 0.2416484 | AW4: 0.0083302291 | AX4: 0.24164839 | AY4: 1.450307e-09 | AZ4: 883760.41 | BA4: 1.1357996e-05 | BB4: 2150196.3 | BC4: 17044.999 | BD4: 0.7990525 | BE4: 3144395.9 | BF4: 0.68381855 | BG4: 0.65432795 | BH4: -0.065763841 | BI4: 0.046 | BJ4: 5625 | BK4: 1.0455027 | BL4: 47.81897 | BM4: 2.1501963 | BN4: 47.81897 | BO4: 1.0455027 | BP4: 61.136284 | BQ4: 1.0083258 | BR4: 2.438
A5: 6_108 | B5: 16650838 | C5: 623.74675 | D5: 115.08175 | E5: 572.29121 | F5: 2559557.8 | G5: 1675797.4 | H5: 2.3829583e-05 | I5: 6.550994e-05 | J5: 0.45915472 | K5: 10285.253 | L5: 0.0035437209 | M5: 232 | N5: 2798.784 | O5: 0.00010848891 | P5: 0.033674103 | Q5: 0.012886925 | R5: 1.778 | S5: 2188781.5 | T5: 565.92778 | U5: 593.38496 | V5: 0.03 | W5: 1438660.2 | X5: 0.015879997 | Y5: 7.9355091 | Z5: 7.9355091 | AA5: -1.9045393e-08 | AB5: 1.5651596e-05 | AC5: 660.1586 | AD5: 32048.554 | AE5: 593.38496 | AF5: 0 | AG5: 1.5715237e-05 | AH5: 27.169529 | AI5: 0.2178876 | AJ5: 29.913231 | AK5: 2.0312746 | AL5: 1.4674494 | AM5: 623.74675 | AN5: 7.4859372e-09 | AO5: 6.3640811e-08 | AP5: 2.5089117 | AQ5: 3.6917946e-05 | AR5: 7.8894389e-06 | AS5: 15.017184 | AT5: 10.495976 | AU5: 2.286943 | AV5: 0.2219687 | AW5: 0.011732978 | AX5: 0.2219687 | AY5: 3.9990492e-09 | AZ5: 883760.41 | BA5: 1.4714725e-05 | BB5: 2187435.1 | BC5: -1346.3913 | BD5: -0.061513284 | BE5: 2955732.2 | BF5: 0.74006538 | BG5: 0.65432795 | BH5: -0.092078771 | BI5: 0.046 | BJ5: 5625 | BK5: 1.0434754 | BL5: 57.81897 | BM5: 2.1874351 | BN5: 57.81897 | BO5: 1.0434754 | BP5: 317.51567 | BQ5: 1.0087754 | BR5: 2.438
A6: 16_108 | B6: 14582411 | C6: 613.05027 | D6: 92.580958 | E6: 610.99185 | F6: 2622345.6 | G6: 1593812.5 | H6: 2.2466336e-05 | I6: 7.0373615e-05 | J6: 0.48213978 | K6: 8194.8014 | L6: 0.0056080352 | M6: 242 | N6: 2740.476 | O6: 0.00010848891 | P6: 0.033674103 | Q6: 0.012886925 | R6: 1.778 | S6: 2634801.9 | T6: 534.53889 | U6: 576.90528 | V6: 0.03 | W6: 1311330.6 | X6: 0.017469075 | Y6: 7.5659775 | Z6: 7.5659775 | AA6: -1.0260209e-08 | AB6: 2.5072374e-05 | AC6: 657.04231 | AD6: 30638.828 | AE6: 576.90528 | AF6: 0 | AG6: 2.5148983e-05 | AH6: 26.840866 | AI6: 0.20959482 | AJ6: 45.764269 | AK6: 2.6260684 | AL6: 1.1961216 | AM6: 613.05027 | AN6: 4.1083581e-08 | AO6: 7.6608651e-08 | AP6: 2.8795138 | AQ6: 5.2857209e-05 | AR6: 1.2612796e-05 | AS6: 22.951838 | AT6: 12.61699 | AU6: 2.6444558 | AV6: 0.235058 | AW6: 0.015909221 | AX6: 0.235058 | AY6: 5.9075522e-10 | AZ6: 1028533.1 | BA6: 1.8356296e-05 | BB6: 2622686.8 | BC6: -12115.05 | BD6: -0.45980877 | BE6: 3264454.7 | BF6: 0.80340733 | BG6: 0.65432795 | BH6: -0.094205149 | BI6: 0.046 | BJ6: 5625 | BK6: 1.0353386 | BL6: 78.511381 | BM6: 2.6226868 | BN6: 78.511381 | BO6: 1.0353386 | BP6: 1483.1265 | BQ6: 1.0122802 | BR6: 2.438
A7: 17_108 | B7: 14582411 | C7: 613.05027 | D7: 92.580958 | E7: 610.99185 | F7: 2622345.6 | G7: 1593812.5 | H7: 2.2466336e-05 | I7: 7.0373615e-05 | J7: 0.48213978 | K7: 8194.8014 | L7: 0.0056080352 | M7: 243 | N7: 2759.46 | O7: 0.00010848891 | P7: 0.033674103 | Q7: 0.012886925 | R7: 1.778 | S7: 2390583.9 | T7: 542.87222 | U7: 581.04725 | V7: 0.03 | W7: 1320414.5 | X7: 0.017425744 | Y7: 7.5753784 | Z7: 7.5753784 | AA7: -9.3748644e-09 | AB7: 2.4790074e-05 | AC7: 651.8849 | AD7: 30812.786 | AE7: 581.04725 | AF7: 5.1884899e-07 | AG7: 2.4859263e-05 | AH7: 27.146519 | AI7: 0.21078484 | AJ7: 45.4939 | AK7: 2.3202531 | AL7: 1.1961216 | AM7: 613.05027 | AN7: 4.9422738e-08 | AO7: 6.9188552e-08 | AP7: 2.8885981 | AQ7: 5.2525273e-05 | AR7: 1.2464226e-05 | AS7: 22.81026 | AT7: 12.586052 | AU7: 2.6529489 | AV7: 0.23564916 | AW7: 0.015730093 | AX7: 0.23564916 | AY7: 9.2025232e-10 | AZ7: 1028533.1 | BA7: 1.8183656e-05 | BB7: 2391149.5 | BC7: 565.61703 | BD7: 0.023660205 | BE7: 3144395.9 | BF7: 0.76044796 | BG7: 0.65432795 | BH7: -0.062186969 | BI7: 0.046 | BJ7: 5625 | BK7: 1.039124 | BL7: 70.178048 | BM7: 2.3911495 | BN7: 70.178048 | BO7: 1.039124 | BP7: 910.71456 | BQ7: 1.010908 | BR7: 2.438
A8: 18_108 | B8: 14582411 | C8: 613.05027 | D8: 92.580958 | E8: 610.99185 | F8: 2622345.6 | G8: 1593812.5 | H8: 2.2466336e-05 | I8: 7.0373615e-05 | J8: 0.48213978 | K8: 8194.8014 | L8: 0.0056080352 | M8: 244 | N8: 2747.256 | O8: 0.00010848891 | P8: 0.033674103 | Q8: 0.012886925 | R8: 1.778 | S8: 1964396.1 | T8: 556.20556 | U8: 587.71418 | V8: 0.03 | W8: 1314574.8 | X8: 0.017453547 | Y8: 7.5693423 | Z8: 7.5693424 | AA8: -1.0018897e-08 | AB8: 2.497097e-05 | AC8: 643.84724 | AD8: 30700.976 | AE8: 587.71418 | AF8: 0 | AG8: 2.5028702e-05 | AH8: 26.949863 | AI8: 0.21001996 | AJ8: 45.637775 | AK8: 1.8391593 | AL8: 1.1961216 | AM8: 613.05027 | AN8: 2.3982693e-08 | AO8: 5.773218e-08 | AP8: 2.8815103 | AQ8: 5.2783989e-05 | AR8: 1.2543217e-05 | AS8: 22.871522 | AT8: 12.599463 | AU8: 2.6461387 | AV8: 0.23537159 | AW8: 0.015844877 | AX8: 0.23537159 | AY8: 6.6216851e-10 | AZ8: 1028533.1 | BA8: 1.8318168e-05 | BB8: 1980567.3 | BC8: 16171.201 | BD8: 0.82321488 | BE8: 2898561.3 | BF8: 0.68329322 | BG8: 0.65432795 | BH8: -0.010917306 | BI8: 0.046 | BJ8: 5625 | BK8: 1.0437372 | BL8: 56.844714 | BM8: 1.9805673 | BN8: 56.844714 | BO8: 1.0437372 | BP8: 283.7444 | BQ8: 1.0093126 | BR8: 2.438
A9: 19_108 | B9: 14582411 | C9: 613.05027 | D9: 92.580958 | E9: 610.99185 | F9: 2622345.6 | G9: 1593812.5 | H9: 2.2466336e-05 | I9: 7.0373615e-05 | J9: 0.48213978 | K9: 8194.8014 | L9: 0.0056080352 | M9: 245 | N9: 3425.256 | O9: 0.00010848891 | P9: 0.033674103 | Q9: 0.012886925 | R9: 1.778 | S9: 2260070.8 | T9: 558.15 | U9: 587.22559 | V9: 0.03 | W9: 1639001 | X9: 0.016146426 | Y9: 7.8697656 | Z9: 7.8697656 | AA9: -8.1061771e-09 | AB9: 1.7364205e-05 | AC9: 641.70422 | AD9: 36816.494 | AE9: 587.22559 | AF9: 4.170422e-07 | AG9: 1.741211e-05 | AH9: 38.755833 | AI9: 0.25185515 | AJ9: 38.073937 | AK9: 1.7587616 | AL9: 1.1961216 | AM9: 613.05027 | AN9: 1.95339e-08 | AO9: 4.7905208e-08 | AP9: 3.1997909 | AQ9: 4.2805479e-05 | AR9: 8.7300076e-06 | AS9: 19.089344 | AT9: 11.695651 | AU9: 2.94561 | AV9: 0.25418088 | AW9: 0.011018142 | AX9: 0.25418088 | AY9: 1.4042972e-09 | AZ9: 1028533.1 | BA9: 1.3377586e-05 | BB9: 2250394.4 | BC9: -9676.3999 | BD9: -0.42814588 | BE9: 3338776.8 | BF9: 0.67401763 | BG9: 0.65432795 | BH9: -0.026417472 | BI9: 0.046 | BJ9: 5625 | BK9: 1.0442198 | BL9: 54.90027 | BM9: 2.2503944 | BN9: 54.90027 | BO9: 1.0442198 | BP9: 222.01804 | BQ9: 1.0133758 | BR9: 2.438
A10: 20_108 | B10: 14410042 | C10: 612.10418 | D10: 90.918182 | E10: 614.04048 | F10: 2627022.6 | G10: 1587051.7 | H10: 2.236639e-05 | I10: 7.0774633e-05 | J10: 0.48408645 | K10: 8073.7157 | L10: 0.0057975807 | M10: 246 | N10: 4145.292 | O10: 0.00010848891 | P10: 0.033674103 | Q10: 0.012886925 | R10: 1.778 | S10: 2018154.6 | T10: 570.65 | U10: 592.42528 | V10: 0.03 | W10: 1972302.6 | X10: 0.015224273 | Y10: 8.1046024 | Z10: 8.1046024 | AA10: -2.7798954e-09 | AB10: 1.306376e-05 | AC10: 632.34339 | AD10: 43019.647 | AE10: 592.42528 | AF10: 3.2343382e-07 | AG10: 1.3096719e-05 | AH10: 53.254933 | AI10: 0.29449737 | AJ10: 33.46288 | AK10: 1.2782021 | AL10: 1.1803972 | AM10: 612.10418 | AN10: 4.9298023e-09 | AO10: 3.2958816e-08 | AP10: 3.528375 | AQ10: 3.6948184e-05 | AR10: 6.5648391e-06 | AS10: 16.773546 | AT10: 11.049015 | AU10: 3.2539058 | AV10: 0.2744692 | AW10: 0.0081897039 | AX10: 0.27446919 | AY10: 1.1770838e-08 | AZ10: 1039970.8 | BA10: 1.0471728e-05 | BB10: 2009885.9 | BC10: -8268.6722 | BD10: -0.40971451 | BE10: 3475986.8 | BF10: 0.57822025 | BG10: 0.65432795 | BH10: 0.011901063 | BI10: 0.046 | BJ10: 5625 | BK10: 1.0459827 | BL10: 41.454175 | BM10: 2.0098859 | BN10: 41.454175 | BO10: 1.0459827 | BP10: 2.1146257 | BQ10: 1.0118388 | BR10: 2.438
A11: 21_108 | B11: 14651359 | C11: 613.42618 | D11: 93.25382 | E11: 609.76673 | F11: 2620453.8 | G11: 1596517 | H11: 2.2506791e-05 | I11: 7.0213281e-05 | J11: 0.48136205 | K11: 8244.8395 | L11: 0.0055330019 | M11: 247 | N11: 4160.208 | O11: 0.00010848891 | P11: 0.033674103 | Q11: 0.012886925 | R11: 1.778 | S11: 1761768.8 | T11: 578.15 | U11: 596.69768 | V11: 0.03 | W11: 1995224.7 | X11: 0.01507591 | Y11: 8.1443839 | Z11: 8.1443839 | AA11: -1.8636932e-08 | AB11: 1.2413154e-05 | AC11: 630.57456 | AD11: 43307.049 | AE11: 596.69768 | AF11: 0 | AG11: 1.2442079e-05 | AH11: 53.488437 | AI11: 0.29617479 | AJ11: 32.002618 | AK11: 1.0775938 | AL11: 1.2026233 | AM11: 613.42618 | AN11: 5.9517333e-09 | AO11: 2.8924789e-08 | AP11: 3.4790035 | AQ11: 3.5511468e-05 | AR11: 6.235502e-06 | AS11: 16.038508 | AT11: 10.824963 | AU11: 3.2060812 | AV11: 0.27292231 | AW11: 0.0079152405 | AX11: 0.2729223 | AY11: 1.2088576e-08 | AZ11: 1023936.8 | BA11: 1.0207368e-05 | BB11: 1769266.7 | BC11: 7497.9173 | BD11: 0.42559032 | BE11: 3121527.6 | BF11: 0.56679514 | BG11: 0.65432795 | BH11: 0.016591549 | BI11: 0.046 | BJ11: 5625 | BK11: 1.0458179 | BL11: 35.276182 | BM11: 1.7692667 | BN11: 35.276182 | BO11: 1.0458179 | BP11: 22.314458 | BQ11: 1.0092778 | BR11: 2.438
A12: 22_108 | B12: 14444516 | C12: 612.29412 | D12: 91.248556 | E12: 613.43232 | F12: 2626093.1 | G12: 1588403.9 | H12: 2.2386246e-05 | I12: 7.0694402e-05 | J12: 0.48369685 | K12: 8097.4886 | L12: 0.0057594463 | M12: 248 | N12: 4122.24 | O12: 0.00010848891 | P12: 0.033674103 | Q12: 0.012886925 | R12: 1.778 | S12: 1156398.9 | T12: 589.53889 | U12: 602.04902 | V12: 0.03 | W12: 1963560.5 | X12: 0.01523423 | Y12: 8.1019534 | Z12: 8.1019534 | AA12: -2.7876883e-09 | AB12: 1.3101818e-05 | AC12: 622.84804 | AD12: 42842.969 | AE12: 602.04902 | AF12: 0 | AG12: 1.3120979e-05 | AH12: 52.750966 | AI12: 0.29324585 | AJ12: 33.387181 | AK12: 0.66564975 | AL12: 1.1834832 | AM12: 612.29412 | AN12: 3.0298679e-09 | AO12: 1.916092e-08 | AP12: 3.5090297 | AQ12: 3.6998689e-05 | AR12: 6.5700699e-06 | AS12: 16.717968 | AT12: 11.03242 | AU12: 3.2352116 | AV12: 0.27381816 | AW12: 0.0082333135 | AX12: 0.27381815 | AY12: 1.2121562e-08 | AZ12: 1037689.2 | BA12: 1.0543852e-05 | BB12: 1156780.7 | BC12: 381.78214 | BD12: 0.033014744 | BE12: 2755634.3 | BF12: 0.41978746 | BG12: 0.65432795 | BH12: 0.069505391 | BI12: 0.046 | BJ12: 5625 | BK12: 1.0436312 | BL12: 22.755233 | BM12: 1.1567807 | BN12: 22.755233 | BO12: 1.0436312 | BP12: 297.38201 | BQ12: 0.99834772 | BR12: 2.438
A13: 26_108 | B13: 16581891 | C13: 623.40834 | D13: 114.24072 | E13: 573.66553 | F13: 2561880.9 | G13: 1673008.5 | H13: 2.3778054e-05 | I13: 6.5676255e-05 | J13: 0.45990285 | K13: 10188.162 | L13: 0.0036065031 | M13: 252 | N13: 4191.396 | O13: 0.00010848891 | P13: 0.033674103 | Q13: 0.012886925 | R13: 1.9304 | S13: 1953061.8 | T13: 577.59444 | U13: 598.43529 | V13: 0.03 | W13: 2149049.2 | X13: 0.013952668 | Y13: 8.4658656 | Z13: 8.4658656 | AA13: -1.4591388e-08 | AB13: 8.1029219e-06 | AC13: 646.39744 | AD13: 44874.538 | AE13: 598.43529 | AF13: 4.639744e-07 | AG13: 8.1377917e-06 | AH13: 53.410409 | AI13: 0.30512906 | AJ13: 21.689049 | AK13: 1.4268205 | AL13: 1.4549166 | AM13: 623.40834 | AN13: 6.8728241e-09 | AO13: 3.4869757e-08 | AP13: 2.9767178 | AQ13: 2.6843579e-05 | AR13: 4.0863307e-06 | AS13: 10.890993 | AT13: 8.8896804 | AU13: 2.7124998 | AV13: 0.26421797 | AW13: 0.006035698 | AX13: 0.26421796 | AY13: 7.4796495e-09 | AZ13: 888872.47 | BA13: 9.0178447e-06 | BB13: 1971716.1 | BC13: 18654.277 | BD13: 0.95512987 | BE13: 3001513.8 | BF13: 0.65690721 | BG13: 0.760494 | BH13: -0.058276004 | BI13: 0.046 | BJ13: 5625 | BK13: 1.0457244 | BL13: 45.813899 | BM13: 1.9717161 | BN13: 45.813899 | BO13: 1.0457244 | BP13: 33.80142 | BQ13: 1.0094312 | BR13: 2.438
... A15: 28_108 | B15: 16650838 | C15: 623.74675 | D15: 115.08175 | E15: 572.29121 | F15: 2559557.8 | G15: 1675797.4 | H15: 2.3829583e-05 | I15: 6.550994e-05 | J15: 0.45915472 | K15: 10285.253 | L15: 0.0035437209 | M15: 254 | N15: 4131.732 | O15: 0.00010848891 | P15: 0.033674103 | Q15: 0.012886925 | R15: 1.778 | S15: 1254442 | T15: 601.48333 | U15: 612.14295 | V15: 0.03 | W15: 2123836 | X15: 0.013974962 | Y15: 8.4591102 | Z15: 8.4591102 | AA15: -1.6394202e-08 | AB15: 8.1608029e-06 | AC15: 634.47232 | AD15: 44383.476 | AE15: 612.14295 | AF15: 0 | AG15: 8.1836287e-06 | AH15: 52.108415 | AI15: 0.30174869 | AJ15: 21.572535 | AK15: 0.66283739 | AL15: 1.4674494 | AM15: 623.74675 | AN15: 2.6032012e-09 | AO15: 2.2825731e-08 | AP15: 2.93486 | AQ15: 2.6979475e-05 | AR15: 4.1032272e-06 | AS15: 10.816352 | AT15: 8.8552955 | AU15: 2.6720738 | AV15: 0.26278623 | AW15: 0.0061176204 | AX15: 0.26278622 | AY15: 4.3819151e-09 | AZ15: 883760.41 | BA15: 9.1927639e-06 | BB15: 1255828.1 | BC15: 1386.0965 | BD15: 0.11049506 | BE15: 2687029.3 | BF15: 0.46736675 | BG15: 0.65432795 | BH15: 0.045215394 | BI15: 0.046 | BJ15: 5625 | BK15: 1.043498 | BL15: 22.263414 | BM15: 1.2558281 | BN15: 22.263414 | BO15: 1.043498 | BP15: 314.58648 | BQ15: 0.98980219 | BR15: 2.438

Sheet tm_161
A1: No_TableNo | B1: P | C1: Ts | D1: rhoG | E1: rhoL | F1: HG | G1: HL | H1: muG | I1: muL | J1: KL | K1: CPL | L1: sigma | M1: No | N1: G | O1: A | P1: Pw | Q1: DH | R1: L_DNB | S1: q_in | T1: Tin | U1: Tf | V1: f(beta) | W1: Re | X1: f | Y1: f_left | Z1: f_rihgt | AA1: f_balance | AB1: DB | AC1: Tw | AD1: y_plus | AE1: Tm | AF1: Tw_balance | AG1: y_star | AH1: tauw | AI1: Utau | AJ1: y_plus2 | AK1: Q | AL1: Pr | AM1: T(y_plus) | AN1: y_star_balance | AO1: delta | AP1: UB | AQ1: LB | AR1: YB | AS1: YB_plus | AT1: Karman_UB | AU1: UBL | AV1: UB_left | AW1: CD | AX1: UB_right | AY1: UB_balance | AZ1: HG-HL | BA1: LB/UB | BB1: q_P | BC1: dq_chf | BD1: dq_ratio | BE1: q_M | BF1: PM_ratio | BG1: F_form | BH1: x_Mes | BI1: A_corr | BJ1: σ_corr | BK1: Fcorr | BL1: Tsub | BM1: q_P_MW | BN1: Tsub2 | BO1: Fcorr2 | BP1: (Tsub-40)^2 | BQ1: F2 | BR1: L
A2: 1_161 | B2: 14582411 | C2: 613.05027 | D2: 92.580958 | E2: 610.99185 | F2: 2622345.6 | G2: 1593812.5 | H2: 2.2466336e-05 | I2: 7.0373615e-05 | J2: 0.48213978 | K2: 8194.8014 | L2: 0.0056080352 | M2: 268 | N2: 2709.288 | O2: 8.7843467e-05 | P2: 0.029843874 | Q2: 0.011773735 | R2: 4.2545 | S2: 309991.24 | T2: 587.81667 | U2: 607.99801 | V2: 0.03 | W2: 1148948.4 | X2: 0.017947229 | Y2: 7.4645099 | Z2: 7.4645099 | AA2: -9.248085e-09 | AB2: 2.4969488e-05 | AC2: 619.32503 | AD2: 27209.729 | AE2: 607.99801 | AF2: 0 | AG2: 2.4978622e-05 | AH2: 26.951463 | AI2: 0.2100262 | AJ2: 45.54781 | AK2: 0.37483184 | AL2: 1.1961216 | AM2: 613.05027 | AN2: 5.9641252e-09 | AO2: 9.134801e-09 | AP2: 2.8777923 | AQ2: 5.2920467e-05 | AR2: 1.2493879e-05 | AS2: 22.782234 | AT2: 12.579905 | AU2: 2.6421096 | AV2: 0.23568268 | AW2: 0.015843937 | AX2: 0.23568268 | AY2: 5.3842503e-10 | AZ2: 1028533.1 | BA2: 1.8389259e-05 | BB2: 312168.11 | BC2: 2176.8744 | BD2: 0.70223739 | BE2: 934294.73 | BF2: 0.33412167 | BG2: 1 | BH2: 0.10800429 | BI2: 0.046 | BJ2: 5625 | BK2: 1.044251 | BL2: 25.233603 | BM2: 0.31216811 | BN2: 25.233603 | BO2: 1.044251 | BP2: 218.04647 | BQ2: 0.97789546 | BR2: 4.267
