Workbook

Sheet 00_STAGING_README
A1: 00_STAGING_README
A3: 【目的】
A4: このブックは result ブック（20260612_計算結果比較r8_result_文献追加用.xlsx）を汚さずに、T&M Table 8〜14 追加データ（138行）を抽出・診断するための staging ブックです。
A6: 【result側の固定ソース（読み取り専用・本ブックでは変更しない）】
A7: ・ tm_r123_noF1_T8_14 （F1なし）
A8: ・ tm_r124_F1_T8_14 （F1あり）
A10: 【本ブックで今回行うこと】
A11: ・ 固定ソース2シートを値貼りでコピー（SRC_ プレフィックス）
A12: ・ 追加138行（88〜225行）の抽出と基本診断のみ
A13: ・ F1ありなしの詳細比較、H52Q branch解析は今回行わない
A15: 【resultへ戻すポリシー】
A16: ・ result へ戻すのは、staging で採用が決まった最小限の正本・要約シートだけ。
... A29: ※ r123(noF1)は数値書式の実体が取得できず、同一tmテンプレートのr124書式を近似適用（値・列幅・ヘッダはr123由来）。

Sheet 00_STAGING_LOG
A1: 00_STAGING_LOG
A3: 項目 | B3: 内容
A4: 作業日時 | B4: 46188
A5: 読み取り元 result ブック | B5: 20260612_計算結果比較r8_result_文献追加用.xlsx
A6: 作業先 staging ブック | B6: 20260612_計算結果比較r8_staging_TM8_14_v1.xlsx
A7: コピーしたresult側シート | B7: tm_r123_noF1_T8_14 / tm_r124_F1_T8_14
A8: staging側に作成したシート | B8: 00_STAGING_README, 00_STAGING_LOG, SRC_tm_r123_noF1_T8_14, SRC_tm_r124_F1_T8_14, STG_added138_noF1, STG_added138_F1, STG_added138_diag
A9: resultブックの変更 | B9: なし（読み取り専用として扱った）
A10: コピー方式 | B10: 値貼り（数式なし）。数値書式・列幅は維持。r123は書式実体未取得のためr124書式を近似適用。
A11: 外部リンク | B11: なし（作成していない）
A12: 抽出範囲 | B12: SRCの88〜225行（追加138行）を抽出、ヘッダ付け
A13: noF1/F1 抽出行数 | B13: noF1=138 / F1=138（一致・期待138一致）
A14: Table別件数（noF1=F1） | B14: Table8=16, Table9=30, Table11=30, Table12=30, Table13=2, Table14=30（期待一致）
A15: L/D分類別件数 | B15: outside_low=0, short_anchor=86, middle=16, long=36, outside_high=0
A16: Gフィルタ（G<=1000混入） | B16: 0行（混入なし）
... A20: 次に行うべき作業 | B20: STG_F1_compare（F1ありなし詳細比較）、STG_H52Q_branch（H52Q解析）、STG_promotion_candidates（result戻し候補）―今回は未作成

Sheet SRC_tm_r123_noF1_T8_14
A1: No_TableNo | B1: P | C1: Ts | D1: rhoG | E1: rhoL | F1: HG | G1: HL | H1: muG | I1: muL | J1: KL | K1: CPL | L1: sigma | M1: No | N1: G | O1: A | P1: Pw | Q1: DH | R1: L_DNB | S1: q_in | T1: Tin | U1: Tf | V1: f(beta) | W1: Re | X1: f | Y1: f_left | Z1: f_rihgt | AA1: f_balance | AB1: DB | AC1: Tw | AD1: y_plus | AE1: Tm | AF1: Tw_balance | AG1: y_star | AH1: tauw | AI1: Utau | AJ1: y_plus2 | AK1: Q | AL1: Pr | AM1: T(y_plus) | AN1: y_star_balance | AO1: delta | AP1: UB | AQ1: LB | AR1: YB | AS1: YB_plus | AT1: Karman_UB | AU1: UBL | AV1: UB_left | AW1: CD | AX1: UB_right | AY1: UB_balance | AZ1: HG-HL | BA1: LB/UB | BB1: q_P | BC1: dq_chf | BD1: dq_ratio | BE1: q_M | BF1: PM_ratio | BG1: F_form | BH1: x_Mes | BI1: A_corr | BJ1: σ_corr | BK1: Fcorr | BL1: Tsub | BM1: q_P_MW | BN1: Tsub2 | BO1: Fcorr2 | BP1: (Tsub-40)^2 | BQ1: F2 | BR1: L
A2: 9.01_10 | B2: 13789520 | C2: 608.62111 | D2: 85.147894 | E2: 624.86627 | F2: 2643264.4 | G2: 1562687 | H2: 2.2019594e-05 | I2: 7.2223253e-05 | J2: 0.49112125 | K2: 7679.7516 | L2: 0.0065036383 | M2: 1 | N2: 2440.8 | O2: 2.8502296e-06 | P2: 0.005984734 | Q2: 0.001905 | R2: 0.1524 | S2: 4124066.3 | T2: 499.9514 | U2: 570.35522 | V2: 0.03 | W2: 64379.875 | X2: 0.035268931 | Y2: 5.3248068 | Z2: 5.3248068 | AA2: -9.2647987e-09 | AB2: 1.8567696e-05 | AC2: 692.22338 | AD2: 2137.3286 | AE2: 570.35522 | AF2: 0 | AG2: 1.8650868e-05 | AH2: 42.031957 | AI2: 0.25935598 | AJ2: 41.850954 | AK2: 5.2415739 | AL2: 1.129368 | AM2: 608.62111 | AN2: 4.5620254e-09 | AO2: 8.3172384e-08 | AP2: 3.4238055 | AQ2: 4.6518328e-05 | AR2: 9.3670203e-06 | AS2: 21.018793 | AT2: 12.177085 | AU2: 3.1581997 | AV2: 0.2656058 | AW2: 0.01116311 | AX2: 0.26560579 | AY2: 9.7350428e-09 | AZ2: 1080577.4 | BA2: 1.3586732e-05 | BB2: 4133396.9 | BC2: 9330.5452 | BD2: 0.22624624 | BE2: 4038400 | BF2: 1.0235234 | BG2: 1 | BH2: -0.05 | BI2: 0.046 | BJ2: 5625 | BK2: 1 | BL2: 108.66971 | BM2: 4.1333969 | BN2: 108.66971 | BO2: 1 | BP2: 4715.529 | BQ2: 1 | BR2: 0.1524
A3: 10.01_10 | B3: 13789520 | C3: 608.62111 | D3: 85.147894 | E3: 624.86627 | F3: 2643264.4 | G3: 1562687 | H3: 2.2019594e-05 | I3: 7.2223253e-05 | J3: 0.49112125 | K3: 7679.7516 | L3: 0.0065036383 | M3: 2 | N3: 2454.36 | O3: 2.8502296e-06 | P3: 0.005984734 | Q3: 0.001905 | R3: 0.1524 | S3: 4160719.6 | T3: 499.3915 | U3: 570.02862 | V3: 0.03 | W3: 64737.541 | X3: 0.035176483 | Y3: 5.3317993 | Z3: 5.3317993 | AA3: -4.9712446e-08 | AB3: 1.8411355e-05 | AC3: 692.63788 | AD3: 2146.384 | AE3: 570.02862 | AF3: 9.2637868e-07 | AG3: 1.8494568e-05 | AH3: 42.388874 | AI3: 0.26045482 | AJ3: 41.676058 | AK3: 5.2710217 | AL3: 1.129368 | AM3: 608.62111 | AN3: 7.4333798e-08 | AO3: 8.3213109e-08 | AP3: 3.4322531 | AQ3: 4.6289625e-05 | AR3: 9.2888906e-06 | AS3: 20.931786 | AT3: 12.156344 | AU3: 3.1661784 | AV3: 0.26607463 | AW3: 0.011069116 | AX3: 0.26607462 | AY3: 1.0037117e-08 | AZ3: 1080577.4 | BA3: 1.3486659e-05 | BB3: 4166106.4 | BC3: 5386.7678 | BD3: 0.12946721 | BE3: 4038400 | BF3: 1.031623 | BG3: 1 | BH3: -0.055 | BI3: 0.046 | BJ3: 5625 | BK3: 1 | BL3: 109.22961 | BM3: 4.1661064 | BN3: 109.22961 | BO3: 1 | BP3: 4792.7389 | BQ3: 1 | BR3: 0.1524
A4: 11.01_10 | B4: 13789520 | C4: 608.62111 | D4: 85.147894 | E4: 624.86627 | F4: 2643264.4 | G4: 1562687 | H4: 2.2019594e-05 | I4: 7.2223253e-05 | J4: 0.49112125 | K4: 7679.7516 | L4: 0.0065036383 | M4: 3 | N4: 3037.44 | O4: 2.8502296e-06 | P4: 0.005984734 | Q4: 0.001905 | R4: 0.1524 | S4: 5012464.7 | T4: 495.51146 | U4: 564.27313 | V4: 0.03 | W4: 80117.178 | X4: 0.031869501 | Y4: 5.6016036 | Z4: 5.6016036 | AA4: -2.5984783e-08 | AB4: 1.3268567e-05 | AC4: 693.21851 | AD4: 2528.3563 | AE4: 564.27313 | AF4: 0 | AG4: 1.3343595e-05 | AH4: 58.818453 | AI4: 0.30680558 | AJ4: 35.419804 | AK4: 5.4463954 | AL4: 1.129368 | AM4: 608.62111 | AN4: 8.0265181e-09 | AO4: 7.5028138e-08 | AP4: 3.7673757 | AQ4: 3.8420622e-05 | AR4: 6.7093117e-06 | AS4: 17.809481 | AT4: 11.348655 | AU4: 3.4818307 | AV4: 0.28554509 | AW4: 0.0079772136 | AX4: 0.28554508 | AY4: 3.7904002e-09 | AZ4: 1080577.4 | BA4: 1.0198245e-05 | BB4: 4967543.5 | BC4: -44921.21 | BD4: -0.89619004 | BE4: 5395050 | BF4: 0.9207595 | BG4: 1 | BH4: -0.033 | BI4: 0.046 | BJ4: 5625 | BK4: 1 | BL4: 113.10965 | BM4: 4.9675435 | BN4: 113.10965 | BO4: 1 | BP4: 5345.021 | BQ4: 1 | BR4: 0.1524
A5: 12.01_10 | B5: 13789520 | C5: 608.62111 | D5: 85.147894 | E5: 624.86627 | F5: 2643264.4 | G5: 1562687 | H5: 2.2019594e-05 | I5: 7.2223253e-05 | J5: 0.49112125 | K5: 7679.7516 | L5: 0.0065036383 | M5: 4 | N5: 3118.8 | O5: 2.8502296e-06 | P5: 0.005984734 | Q5: 0.001905 | R5: 0.1524 | S5: 6642123.1 | T5: 458.88286 | U5: 547.62343 | V5: 0.03 | W5: 82263.174 | X5: 0.03149114 | Y5: 5.6351543 | Z5: 5.6351543 | AA5: -3.3351511e-08 | AB5: 1.2736534e-05 | AC5: 723.24995 | AD5: 2580.6236 | AE5: 547.62343 | AF5: 1.2324994e-06 | AG5: 1.2832823e-05 | AH5: 61.275429 | AI5: 0.313148 | AJ5: 34.768174 | AK5: 7.4019463 | AL5: 1.129368 | AM5: 608.62111 | AN5: 4.5659135e-08 | AO5: 9.6288907e-08 | AP5: 3.8154368 | AQ5: 3.7458789e-05 | AR5: 6.464556e-06 | AS5: 17.514526 | AT5: 11.265153 | AU5: 3.5276601 | AV5: 0.28777678 | AW5: 0.0076573493 | AX5: 0.28777677 | AY5: 6.0832119e-09 | AZ5: 1080577.4 | BA5: 9.8176934e-06 | BB5: 6622313.9 | BC5: -19809.265 | BD5: -0.29823695 | BE5: 6688600 | BF5: 0.99008969 | BG5: 1 | BH5: -0.075 | BI5: 0.046 | BJ5: 5625 | BK5: 1 | BL5: 149.73825 | BM5: 6.6223139 | BN5: 149.73825 | BO5: 1 | BP5: 12042.483 | BQ5: 1 | BR5: 0.1524
A6: 13.01_10 | B6: 13789520 | C6: 608.62111 | D6: 85.147894 | E6: 624.86627 | F6: 2643264.4 | G6: 1562687 | H6: 2.2019594e-05 | I6: 7.2223253e-05 | J6: 0.49112125 | K6: 7679.7516 | L6: 0.0065036383 | M6: 5 | N6: 3118.8 | O6: 2.8502296e-06 | P6: 0.005984734 | Q6: 0.001905 | R6: 0.1524 | S6: 5270594.1 | T6: 491.66308 | U6: 562.07965 | V6: 0.03 | W6: 82263.174 | X6: 0.03149114 | Y6: 5.6351543 | Z6: 5.6351543 | AA6: -3.3351511e-08 | AB6: 1.2736534e-05 | AC6: 696.02091 | AD6: 2580.6236 | AE6: 562.07965 | AF6: 9.6020904e-07 | AG6: 1.2813124e-05 | AH6: 61.275429 | AI6: 0.313148 | AJ6: 34.714802 | AK6: 5.6450817 | AL6: 1.129368 | AM6: 608.62111 | AN6: 2.4413453e-08 | AO6: 7.6589411e-08 | AP6: 3.8109938 | AQ6: 3.7546183e-05 | AR6: 6.4448565e-06 | AS6: 17.461154 | AT6: 11.249893 | AU6: 3.5228815 | AV6: 0.28811228 | AW6: 0.0076573493 | AX6: 0.28811228 | AY6: 5.9074059e-09 | AZ6: 1080577.4 | BA6: 9.8520715e-06 | BB6: 5249091.5 | BC6: -21502.544 | BD6: -0.40797192 | BE6: 5679000 | BF6: 0.92429856 | BG6: 1 | BH6: -0.036 | BI6: 0.046 | BJ6: 5625 | BK6: 1 | BL6: 116.95802 | BM6: 5.2490915 | BN6: 116.95802 | BO6: 1 | BP6: 5922.5376 | BQ6: 1 | BR6: 0.1524
A7: 14.01_10 | B7: 13789520 | C7: 608.62111 | D7: 85.147894 | E7: 624.86627 | F7: 2643264.4 | G7: 1562687 | H7: 2.2019594e-05 | I7: 7.2223253e-05 | J7: 0.49112125 | K7: 7679.7516 | L7: 0.0065036383 | M7: 6 | N7: 3118.8 | O7: 2.8502296e-06 | P7: 0.005984734 | Q7: 0.001905 | R7: 0.1524 | S7: 5246751.9 | T7: 492.22869 | U7: 562.32671 | V7: 0.03 | W7: 82263.174 | X7: 0.03149114 | Y7: 5.6351543 | Z7: 5.6351543 | AA7: -3.3351511e-08 | AB7: 1.2736534e-05 | AC7: 695.555 | AD7: 2580.6236 | AE7: 562.32672 | AF7: 9.5554992e-07 | AG7: 1.2812504e-05 | AH7: 61.275429 | AI7: 0.313148 | AJ7: 34.713125 | AK7: 5.6150323 | AL7: 1.129368 | AM7: 608.62111 | AN7: 2.3977464e-08 | AO7: 7.597026e-08 | AP7: 3.8108539 | AQ7: 3.7548939e-05 | AR7: 6.4442374e-06 | AS7: 17.459476 | AT7: 11.249413 | AU7: 3.522731 | AV7: 0.28812286 | AW7: 0.0076573493 | AX7: 0.28812285 | AY7: 5.9018651e-09 | AZ7: 1080577.4 | BA7: 9.8531562e-06 | BB7: 5206084.5 | BC7: -40667.38 | BD7: -0.7750963 | BE7: 5521250 | BF7: 0.94291773 | BG7: 1 | BH7: -0.048 | BI7: 0.046 | BJ7: 5625 | BK7: 1 | BL7: 116.39242 | BM7: 5.2060845 | BN7: 116.39242 | BO7: 1 | BP7: 5835.8019 | BQ7: 1 | BR7: 0.1524
A8: 15.01_10 | B8: 13789520 | C8: 608.62111 | D8: 85.147894 | E8: 624.86627 | F8: 2643264.4 | G8: 1562687 | H8: 2.2019594e-05 | I8: 7.2223253e-05 | J8: 0.49112125 | K8: 7679.7516 | L8: 0.0065036383 | M8: 7 | N8: 3132.36 | O8: 2.8502296e-06 | P8: 0.005984734 | Q8: 0.001905 | R8: 0.1524 | S8: 6662660.1 | T8: 458.88286 | U8: 547.51246 | V8: 0.03 | W8: 82620.84 | X8: 0.031429667 | Y8: 5.6406625 | Z8: 5.6406625 | AA8: -2.4900442e-08 | AB8: 1.2651196e-05 | AC8: 723.16767 | AD8: 2589.3127 | AE8: 547.51246 | AF8: 0 | AG8: 1.2748365e-05 | AH8: 61.68876 | AI8: 0.31420239 | AJ8: 34.655647 | AK8: 7.4005062 | AL8: 1.129368 | AM8: 608.62111 | AN8: 2.5374561e-08 | AO8: 9.7169062e-08 | AP8: 3.8228184 | AQ8: 3.7314268e-05 | AR8: 6.422767e-06 | AS8: 17.459898 | AT8: 11.249533 | AU8: 3.5346302 | AV8: 0.28818819 | AW8: 0.007606043 | AX8: 0.28818819 | AY8: 6.4917222e-09 | AZ8: 1080577.4 | BA8: 9.7609313e-06 | BB8: 6721709.3 | BC8: 59049.239 | BD8: 0.88627123 | BE8: 6751700 | BF8: 0.99555805 | BG8: 1 | BH8: -0.071 | BI8: 0.046 | BJ8: 5625 | BK8: 1 | BL8: 149.73825 | BM8: 6.7217093 | BN8: 149.73825 | BO8: 1 | BP8: 12042.483 | BQ8: 1 | BR8: 0.1524
A9: 16.01_10 | B9: 13789520 | C9: 608.62111 | D9: 85.147894 | E9: 624.86627 | F9: 2643264.4 | G9: 1562687 | H9: 2.2019594e-05 | I9: 7.2223253e-05 | J9: 0.49112125 | K9: 7679.7516 | L9: 0.0065036383 | M9: 8 | N9: 3145.92 | O9: 2.8502296e-06 | P9: 0.005984734 | Q9: 0.001905 | R9: 0.1524 | S9: 3751771.9 | T9: 527.87377 | U9: 577.56635 | V9: 0.03 | W9: 82978.506 | X9: 0.031368633 | Y9: 5.6461473 | Z9: 5.6461473 | AA9: -1.7290978e-08 | AB9: 1.2566773e-05 | AC9: 666.592 | AD9: 2597.9956 | AE9: 577.56635 | AF9: 0 | AG9: 1.26207e-05 | AH9: 62.103184 | AI9: 0.31525602 | AJ9: 34.423648 | AK9: 3.7493914 | AL9: 1.129368 | AM9: 608.62111 | AN9: 4.3324917e-09 | AO9: 5.3927807e-08 | AP9: 3.8200143 | AQ9: 3.736907e-05 | AR9: 6.3373141e-06 | AS9: 17.285369 | AT9: 11.199302 | AU9: 3.5306475 | AV9: 0.28936685 | AW9: 0.0075552867 | AX9: 0.28936684 | AY9: 6.4923122e-09 | AZ9: 1080577.4 | BA9: 9.7824423e-06 | BB9: 3722274.9 | BC9: -29497.034 | BD9: -0.78621607 | BE9: 4164600 | BF9: 0.89378929 | BG9: 1 | BH9: -0.027 | BI9: 0.046 | BJ9: 5625 | BK9: 1 | BL9: 80.747335 | BM9: 3.7222749 | BN9: 80.747335 | BO9: 1 | BP9: 1660.3453 | BQ9: 1 | BR9: 0.1524
A10: 17.01_10 | B10: 13789520 | C10: 608.62111 | D10: 85.147894 | E10: 624.86627 | F10: 2643264.4 | G10: 1562687 | H10: 2.2019594e-05 | I10: 7.2223253e-05 | J10: 0.49112125 | K10: 7679.7516 | L10: 0.0065036383 | M10: 9 | N10: 3145.92 | O10: 2.8502296e-06 | P10: 0.005984734 | Q10: 0.001905 | R10: 0.1524 | S10: 3535281.8 | T10: 532.84871 | U10: 579.67386 | V10: 0.03 | W10: 82978.506 | X10: 0.031368633 | Y10: 5.6461473 | Z10: 5.6461473 | AA10: -1.7290978e-08 | AB10: 1.2566773e-05 | AC10: 662.65222 | AD10: 2597.9956 | AE10: 579.67386 | AF10: 6.2652202e-07 | AG10: 1.2617868e-05 | AH10: 62.103184 | AI10: 0.31525602 | AJ10: 34.415921 | AK10: 3.4947048 | AL10: 1.129368 | AM10: 608.62111 | AN10: 4.0275836e-09 | AO10: 5.1094974e-08 | AP10: 3.8193592 | AQ10: 3.738189e-05 | AR10: 6.3344813e-06 | AS10: 17.277643 | AT10: 11.197067 | AU10: 3.5299427 | AV10: 0.28941648 | AW10: 0.0075552867 | AX10: 0.28941648 | AY10: 6.4652687e-09 | AZ10: 1080577.4 | BA10: 9.7874771e-06 | BB10: 3524929.2 | BC10: -10352.655 | BD10: -0.29283818 | BE10: 3943750 | BF10: 0.89380138 | BG10: 1 | BH10: -0.026 | BI10: 0.046 | BJ10: 5625 | BK10: 1 | BL10: 75.772395 | BM10: 3.5249292 | BN10: 75.772395 | BO10: 1 | BP10: 1279.6642 | BQ10: 1 | BR10: 0.1524
A11: 18.01_10 | B11: 13789520 | C11: 608.62111 | D11: 85.147894 | E11: 624.86627 | F11: 2643264.4 | G11: 1562687 | H11: 2.2019594e-05 | I11: 7.2223253e-05 | J11: 0.49112125 | K11: 7679.7516 | L11: 0.0065036383 | M11: 10 | N11: 3634.08 | O11: 2.8502296e-06 | P11: 0.005984734 | Q11: 0.001905 | R11: 0.1524 | S11: 3515012.9 | T11: 541.31775 | U11: 581.62055 | V11: 0.03 | W11: 95854.481 | X11: 0.029426133 | Y11: 5.8295281 | Z11: 5.8295281 | AA11: -1.1375949e-08 | AB11: 1.0039048e-05 | AC11: 654.95066 | AD11: 2906.7256 | AE11: 581.62055 | AF11: 0 | AG11: 1.0081321e-05 | AH11: 77.740099 | AI11: 0.35271912 | AJ11: 30.76497 | AK11: 3.0519132 | AL11: 1.129368 | AM11: 608.62111 | AN11: 5.4569682e-12 | AO11: 4.2273105e-08 | AP11: 4.0567578 | AQ11: 3.3134781e-05 | AR11: 5.0617971e-06 | AS11: 15.446987 | AT11: 10.63707 | AU11: 3.7518979 | AV11: 0.30485992 | AW11: 0.00603559 | AX11: 0.30485989 | AY11: 2.9307291e-08 | AZ11: 1080577.4 | BA11: 8.1677986e-06 | BB11: 3494637.2 | BC11: -20375.709 | BD11: -0.57967664 | BE11: 4417000 | BF11: 0.7911789 | BG11: 1 | BH11: 0.001 | BI11: 0.046 | BJ11: 5625 | BK11: 1 | BL11: 67.303354 | BM11: 3.4946372 | BN11: 67.303354 | BO11: 1 | BP11: 745.47312 | BQ11: 1 | BR11: 0.1524
A12: 19.01_10 | B12: 13789520 | C12: 608.62111 | D12: 85.147894 | E12: 624.86627 | F12: 2643264.4 | G12: 1562687 | H12: 2.2019594e-05 | I12: 7.2223253e-05 | J12: 0.49112125 | K12: 7679.7516 | L12: 0.0065036383 | M12: 11 | N12: 3851.04 | O12: 2.8502296e-06 | P12: 0.005984734 | Q12: 0.001905 | R12: 0.1524 | S12: 4025857.1 | T12: 534.00031 | U12: 577.55984 | V12: 0.03 | W12: 101577.14 | X12: 0.028694843 | Y12: 5.9033437 | Z12: 5.9033438 | AA12: -2.692234e-08 | AB12: 9.1675816e-06 | AC12: 659.74607 | AD12: 3041.7457 | AE12: 577.55984 | AF12: 0 | AG12: 9.2124976e-06 | AH12: 85.130041 | AI12: 0.36910326 | AJ12: 29.419501 | AK12: 3.404262 | AL12: 1.129368 | AM12: 608.62111 | AN12: -1.2880719e-10 | AO12: 4.4916051e-08 | AP12: 4.1562829 | AQ12: 3.1566909e-05 | AR12: 4.6287068e-06 | AS12: 14.781469 | AT12: 10.416871 | AU12: 3.8449012 | AV12: 0.31138174 | AW12: 0.0055116544 | AX12: 0.31138174 | AY12: 4.3253842e-09 | AZ12: 1080577.4 | BA12: 7.5949856e-06 | BB12: 3993168 | BC12: -32689.02 | BD12: -0.81197666 | BE12: 4858700 | BF12: 0.82185935 | BG12: 1 | BH12: -0.018 | BI12: 0.046 | BJ12: 5625 | BK12: 1 | BL12: 74.620793 | BM12: 3.993168 | BN12: 74.620793 | BO12: 1 | BP12: 1198.5993 | BQ12: 1 | BR12: 0.1524
A13: 20.01_10 | B13: 13789520 | C13: 608.62111 | D13: 85.147894 | E13: 624.86627 | F13: 2643264.4 | G13: 1562687 | H13: 2.2019594e-05 | I13: 7.2223253e-05 | J13: 0.49112125 | K13: 7679.7516 | L13: 0.0065036383 | M13: 12 | N13: 3905.28 | O13: 2.8502296e-06 | P13: 0.005984734 | Q13: 0.001905 | R13: 0.1524 | S13: 4119595.8 | T13: 532.84871 | U13: 576.8034 | V13: 0.03 | W13: 103007.8 | X13: 0.02852248 | Y13: 5.921154 | Z13: 5.921154 | AA13: -8.2254532e-09 | AB13: 8.9685669e-06 | AC13: 660.32968 | AD13: 3075.3091 | AE13: 576.8034 | AF13: 0 | AG13: 9.0140076e-06 | AH13: 87.019097 | AI13: 0.37317603 | AJ13: 29.103264 | AK13: 3.4558054 | AL13: 1.129368 | AM13: 608.62111 | AN13: 3.4825689e-09 | AO13: 4.5440633e-08 | AP13: 4.1804653 | AQ13: 3.1202761e-05 | AR13: 4.5297241e-06 | AS13: 14.624989 | AT13: 10.363658 | AU13: 3.8674688 | AV13: 0.31299651 | AW13: 0.0053920045 | AX13: 0.3129965 | AY13: 4.7917047e-09 | AZ13: 1080577.4 | BA13: 7.4639445e-06 | BB13: 4110729.9 | BC13: -8865.8875 | BD13: -0.21521256 | BE13: 4890250 | BF13: 0.84059709 | BG13: 1 | BH13: -0.026 | BI13: 0.046 | BJ13: 5625 | BK13: 1 | BL13: 75.772395 | BM13: 4.1107299 | BN13: 75.772395 | BO13: 1 | BP13: 1279.6642 | BQ13: 1 | BR13: 0.1524
... A225: 30.01_14 | B225: 18960583 | C225: 634.44823 | D225: 149.14958 | E225: 520.38378 | F225: 2467301.6 | G225: 1775044 | H225: 2.5972811e-05 | I225: 5.9480773e-05 | J225: 0.43661799 | K225: 16063.58 | L225: 0.0016624879 | M225: 224 | N225: 3783.8817 | O225: 2.8502296e-06 | P225: 0.005984734 | Q225: 0.001905 | R225: 0.69596 | S225: 7711816.4 | T225: 299.58376 | U225: 484.99073 | V225: 0.03 | W225: 121186.97 | X225: 0.021931703 | Y225: 6.752488 | Z225: 6.752488 | AA225: -2.1136982e-08 | AB225: 2.6448803e-06 | AC225: 785.38105 | AD225: 3172.6131 | AE225: 484.99073 | AF225: 0 | AG225: 2.8221508e-06 | AH225: 75.428196 | AI225: 0.38071938 | AJ225: 9.4000972 | AK225: 9.2542365 | AL225: 2.1883528 | AM225: 634.44823 | AN225: 1.5513524e-07 | AO225: 1.772705e-07 | AP225: 2.215499 | AQ225: 1.8357844e-05 | AR225: 1.4997106e-06 | AS225: 4.9952773 | AT225: 4.9952773 | AU225: 1.9017989 | AV225: 0.31370015 | AW225: 0.0026083901 | AX225: 0.31370014 | AY225: 1.2818768e-08 | AZ225: 692257.61 | BA225: 8.2860986e-06 | BB225: 7706866.7 | BC225: -4949.7558 | BD225: -0.064184046 | BE225: 3564686.7 | BF225: 2.1620039 | BG225: 1 | BH225: -0.387 | BI225: 0.046 | BJ225: 5625 | BK225: 1 | BL225: 334.86448 | BM225: 7.7068667 | BN225: 334.86448 | BO225: 1 | BP225: 86945.06 | BQ225: 1 | BR225: 0.69596

Sheet SRC_tm_r124_F1_T8_14
A1: No_TableNo | B1: P | C1: Ts | D1: rhoG | E1: rhoL | F1: HG | G1: HL | H1: muG | I1: muL | J1: KL | K1: CPL | L1: sigma | M1: No | N1: G | O1: A | P1: Pw | Q1: DH | R1: L_DNB | S1: q_in | T1: Tin | U1: Tf | V1: f(beta) | W1: Re | X1: f | Y1: f_left | Z1: f_rihgt | AA1: f_balance | AB1: DB | AC1: Tw | AD1: y_plus | AE1: Tm | AF1: Tw_balance | AG1: y_star | AH1: tauw | AI1: Utau | AJ1: y_plus2 | AK1: Q | AL1: Pr | AM1: T(y_plus) | AN1: y_star_balance | AO1: delta | AP1: UB | AQ1: LB | AR1: YB | AS1: YB_plus | AT1: Karman_UB | AU1: UBL | AV1: UB_left | AW1: CD | AX1: UB_right | AY1: UB_balance | AZ1: HG-HL | BA1: LB/UB | BB1: q_P | BC1: dq_chf | BD1: dq_ratio | BE1: q_M | BF1: PM_ratio | BG1: F_form | BH1: x_Mes | BI1: A_corr | BJ1: σ_corr | BK1: Fcorr | BL1: Tsub | BM1: q_P_MW | BN1: Tsub2 | BO1: Fcorr2 | BP1: (Tsub-40)^2 | BQ1: F2 | BR1: L
A2: 9.01_10 | B2: 13789520 | C2: 608.62111 | D2: 85.147894 | E2: 624.86627 | F2: 2643264.4 | G2: 1562687 | H2: 2.2019594e-05 | I2: 7.2223253e-05 | J2: 0.49112125 | K2: 7679.7516 | L2: 0.0065036383 | M2: 1 | N2: 2440.8 | O2: 2.8502296e-06 | P2: 0.005984734 | Q2: 0.001905 | R2: 0.1524 | S2: 4672272.8 | T2: 499.9514 | U2: 579.7139 | V2: 0.03 | W2: 64379.875 | X2: 0.035268931 | Y2: 5.3248068 | Z2: 5.3248068 | AA2: -9.2647987e-09 | AB2: 1.8567696e-05 | AC2: 702.32732 | AD2: 2137.3286 | AE2: 579.7139 | AF2: 0 | AG2: 1.8661842e-05 | AH2: 42.031957 | AI2: 0.25935598 | AJ2: 41.875577 | AK2: 5.8745145 | AL2: 1.129368 | AM2: 608.62111 | AN2: 5.2953055e-09 | AO2: 9.4145806e-08 | AP2: 3.4252145 | AQ2: 4.6480064e-05 | AR2: 9.3779937e-06 | AS2: 21.043416 | AT2: 12.182939 | AU2: 3.159718 | AV2: 0.26549654 | AW2: 0.01116311 | AX2: 0.26549653 | AY2: 9.7554658e-09 | AZ2: 1080577.4 | BA2: 1.3569972e-05 | BB2: 4684519.1 | BC2: 12246.303 | BD2: 0.26210591 | BE2: 4038400 | BF2: 1.1599938 | BG2: 1 | BH2: -0.05 | BI2: 0.046 | BJ2: 5625 | BK2: 1.0198921 | BL2: 108.66971 | BM2: 4.6845191 | BN2: 108.66971 | BO2: 1.0198921 | BP2: 4715.529 | BQ2: 1 | BR2: 0.1524
A3: 10.01_10 | B3: 13789520 | C3: 608.62111 | D3: 85.147894 | E3: 624.86627 | F3: 2643264.4 | G3: 1562687 | H3: 2.2019594e-05 | I3: 7.2223253e-05 | J3: 0.49112125 | K3: 7679.7516 | L3: 0.0065036383 | M3: 2 | N3: 2454.36 | O3: 2.8502296e-06 | P3: 0.005984734 | Q3: 0.001905 | R3: 0.1524 | S3: 4703655.8 | T3: 499.3915 | U3: 579.24612 | V3: 0.03 | W3: 64737.541 | X3: 0.035176483 | Y3: 5.3317993 | Z3: 5.3317993 | AA3: -4.9712446e-08 | AB3: 1.8411355e-05 | AC3: 702.61252 | AD3: 2146.384 | AE3: 579.24612 | AF3: 0 | AG3: 1.8506041e-05 | AH3: 42.388874 | AI3: 0.26045482 | AJ3: 41.70191 | AK3: 5.8962345 | AL3: 1.129368 | AM3: 608.62111 | AN3: 8.8290449e-08 | AO3: 9.4685701e-08 | AP3: 3.4337449 | AQ3: 4.6249412e-05 | AR3: 9.3003631e-06 | AS3: 20.957638 | AT3: 12.162516 | AU3: 3.1677859 | AV3: 0.26595904 | AW3: 0.011069116 | AX3: 0.26595903 | AY3: 1.0054543e-08 | AZ3: 1080577.4 | BA3: 1.3469088e-05 | BB3: 4746671.6 | BC3: 43015.826 | BD3: 0.91451901 | BE3: 4038400 | BF3: 1.1753842 | BG3: 1 | BH3: -0.055 | BI3: 0.046 | BJ3: 5625 | BK3: 1.019621 | BL3: 109.22961 | BM3: 4.7466716 | BN3: 109.22961 | BO3: 1.019621 | BP3: 4792.7389 | BQ3: 1 | BR3: 0.1524
A4: 11.01_10 | B4: 13789520 | C4: 608.62111 | D4: 85.147894 | E4: 624.86627 | F4: 2643264.4 | G4: 1562687 | H4: 2.2019594e-05 | I4: 7.2223253e-05 | J4: 0.49112125 | K4: 7679.7516 | L4: 0.0065036383 | M4: 3 | N4: 3037.44 | O4: 2.8502296e-06 | P4: 0.005984734 | Q4: 0.001905 | R4: 0.1524 | S4: 5584453.6 | T4: 495.51146 | U4: 572.11975 | V4: 0.03 | W4: 80117.178 | X4: 0.031869501 | Y4: 5.6016036 | Z4: 5.6016036 | AA4: -2.5984783e-08 | AB4: 1.3268567e-05 | AC4: 702.10302 | AD4: 2528.3563 | AE4: 572.11975 | AF4: 0 | AG4: 1.3353168e-05 | AH4: 58.818453 | AI4: 0.30680558 | AJ4: 35.445215 | AK4: 6.0176875 | AL4: 1.129368 | AM4: 608.62111 | AN4: 9.2328492e-09 | AO4: 8.4600969e-08 | AP4: 3.7694089 | AQ4: 3.8379186e-05 | AR4: 6.7188845e-06 | AS4: 17.834892 | AT4: 11.355784 | AU4: 3.4840178 | AV4: 0.28539107 | AW4: 0.0079772136 | AX4: 0.28539106 | AY4: 3.8588525e-09 | AZ4: 1080577.4 | BA4: 1.0181752e-05 | BB4: 5610425.5 | BC4: 25971.858 | BD4: 0.46507429 | BE4: 5395050 | BF4: 1.0399209 | BG4: 1 | BH4: -0.033 | BI4: 0.046 | BJ4: 5625 | BK4: 1.0177861 | BL4: 113.10965 | BM4: 5.6104255 | BN4: 113.10965 | BO4: 1.0177861 | BP4: 5345.021 | BQ4: 1 | BR4: 0.1524
A5: 12.01_10 | B5: 13789520 | C5: 608.62111 | D5: 85.147894 | E5: 624.86627 | F5: 2643264.4 | G5: 1562687 | H5: 2.2019594e-05 | I5: 7.2223253e-05 | J5: 0.49112125 | K5: 7679.7516 | L5: 0.0065036383 | M5: 4 | N5: 3118.8 | O5: 2.8502296e-06 | P5: 0.005984734 | Q5: 0.001905 | R5: 0.1524 | S5: 6821250.1 | T5: 458.88286 | U5: 550.01661 | V5: 0.03 | W5: 82263.174 | X5: 0.03149114 | Y5: 5.6351543 | Z5: 5.6351543 | AA5: -3.3351511e-08 | AB5: 1.2736534e-05 | AC5: 726.14192 | AD5: 2580.6236 | AE5: 550.01661 | AF5: 1.2682399e-06 | AG5: 1.2835299e-05 | AH5: 61.275429 | AI5: 0.313148 | AJ5: 34.774884 | AK5: 7.5884539 | AL5: 1.129368 | AM5: 608.62111 | AN5: 4.8685024e-08 | AO5: 9.8765281e-08 | AP5: 3.8159944 | AQ5: 3.7447842e-05 | AR5: 6.4670324e-06 | AS5: 17.521235 | AT5: 11.267068 | AU5: 3.5282597 | AV5: 0.28773472 | AW5: 0.0076573493 | AX5: 0.28773472 | AY5: 6.1053302e-09 | AZ5: 1080577.4 | BA5: 9.8133902e-06 | BB5: 6795606.3 | BC5: -25643.833 | BD5: -0.37594037 | BE5: 6688600 | BF5: 1.0159983 | BG5: 1 | BH5: -0.075 | BI5: 0.046 | BJ5: 5625 | BK5: 1.0054073 | BL5: 149.73825 | BM5: 6.7956063 | BN5: 149.73825 | BO5: 1.0054073 | BP5: 12042.483 | BQ5: 1 | BR5: 0.1524
A6: 13.01_10 | B6: 13789520 | C6: 608.62111 | D6: 85.147894 | E6: 624.86627 | F6: 2643264.4 | G6: 1562687 | H6: 2.2019594e-05 | I6: 7.2223253e-05 | J6: 0.49112125 | K6: 7679.7516 | L6: 0.0065036383 | M6: 5 | N6: 3118.8 | O6: 2.8502296e-06 | P6: 0.005984734 | Q6: 0.001905 | R6: 0.1524 | S6: 5796588.6 | T6: 491.66308 | U6: 569.10708 | V6: 0.03 | W6: 82263.174 | X6: 0.03149114 | Y6: 5.6351543 | Z6: 5.6351543 | AA6: -3.3351511e-08 | AB6: 1.2736534e-05 | AC6: 704.07293 | AD6: 2580.6236 | AE6: 569.10708 | AF6: 0 | AG6: 1.2820957e-05 | AH6: 61.275429 | AI6: 0.313148 | AJ6: 34.736026 | AK6: 6.1645463 | AL6: 1.129368 | AM6: 608.62111 | AN6: 3.1021273e-08 | AO6: 8.4423197e-08 | AP6: 3.8127621 | AQ6: 3.7511363e-05 | AR6: 6.4526903e-06 | AS6: 17.482378 | AT6: 11.255967 | AU6: 3.5247835 | AV6: 0.28797865 | AW6: 0.0076573493 | AX6: 0.28797865 | AY6: 5.977281e-09 | AZ6: 1080577.4 | BA6: 9.8383695e-06 | BB6: 5794042 | BC6: -2546.5667 | BD6: -0.043932162 | BE6: 5679000 | BF6: 1.0202574 | BG6: 1 | BH6: -0.036 | BI6: 0.046 | BJ6: 5625 | BK6: 1.0160506 | BL6: 116.95802 | BM6: 5.794042 | BN6: 116.95802 | BO6: 1.0160506 | BP6: 5922.5376 | BQ6: 1 | BR6: 0.1524
A7: 14.01_10 | B7: 13789520 | C7: 608.62111 | D7: 85.147894 | E7: 624.86627 | F7: 2643264.4 | G7: 1562687 | H7: 2.2019594e-05 | I7: 7.2223253e-05 | J7: 0.49112125 | K7: 7679.7516 | L7: 0.0065036383 | M7: 6 | N7: 3118.8 | O7: 2.8502296e-06 | P7: 0.005984734 | Q7: 0.001905 | R7: 0.1524 | S7: 5780887.2 | T7: 492.22869 | U7: 569.46291 | V7: 0.03 | W7: 82263.174 | X7: 0.03149114 | Y7: 5.6351543 | Z7: 5.6351543 | AA7: -3.3351511e-08 | AB7: 1.2736534e-05 | AC7: 703.7233 | AD7: 2580.6236 | AE7: 569.46291 | AF7: 0 | AG7: 1.2820846e-05 | AH7: 61.275429 | AI7: 0.313148 | AJ7: 34.735725 | AK7: 6.141975 | AL7: 1.129368 | AM7: 608.62111 | AN7: 3.0844603e-08 | AO7: 8.4312086e-08 | AP7: 3.8127371 | AQ7: 3.7511856e-05 | AR7: 6.4525792e-06 | AS7: 17.482077 | AT7: 11.255881 | AU7: 3.5247565 | AV7: 0.28798055 | AW7: 0.0076573493 | AX7: 0.28798054 | AY7: 5.9762856e-09 | AZ7: 1080577.4 | BA7: 9.8385635e-06 | BB7: 5786302.2 | BC7: 5415.015 | BD7: 0.093671002 | BE7: 5521250 | BF7: 1.0480058 | BG7: 1 | BH7: -0.048 | BI7: 0.046 | BJ7: 5625 | BK7: 1.0163 | BL7: 116.39242 | BM7: 5.7863022 | BN7: 116.39242 | BO7: 1.0163 | BP7: 5835.8019 | BQ7: 1 | BR7: 0.1524
A8: 15.01_10 | B8: 13789520 | C8: 608.62111 | D8: 85.147894 | E8: 624.86627 | F8: 2643264.4 | G8: 1562687 | H8: 2.2019594e-05 | I8: 7.2223253e-05 | J8: 0.49112125 | K8: 7679.7516 | L8: 0.0065036383 | M8: 7 | N8: 3132.36 | O8: 2.8502296e-06 | P8: 0.005984734 | Q8: 0.001905 | R8: 0.1524 | S8: 6842307 | T8: 458.88286 | U8: 549.9022 | V8: 0.03 | W8: 82620.84 | X8: 0.031429667 | Y8: 5.6406625 | Z8: 5.6406625 | AA8: -2.4900442e-08 | AB8: 1.2651196e-05 | AC8: 726.05712 | AD8: 2589.3127 | AE8: 549.9022 | AF8: 0 | AG8: 1.2750638e-05 | AH8: 61.68876 | AI8: 0.31420239 | AJ8: 34.661827 | AK8: 7.5869666 | AL8: 1.129368 | AM8: 608.62111 | AN8: 4.2675424e-08 | AO8: 9.9442362e-08 | AP8: 3.8233354 | AQ8: 3.7304178e-05 | AR8: 6.4250403e-06 | AS8: 17.466077 | AT8: 11.251303 | AU8: 3.5351862 | AV8: 0.28814922 | AW8: 0.007606043 | AX8: 0.28814922 | AY8: 6.512748e-09 | AZ8: 1080577.4 | BA8: 9.7569723e-06 | BB8: 6881757 | BC8: 39449.962 | BD8: 0.57655936 | BE8: 6751700 | BF8: 1.0192628 | BG8: 1 | BH8: -0.071 | BI8: 0.046 | BJ8: 5625 | BK8: 1.0054073 | BL8: 149.73825 | BM8: 6.881757 | BN8: 149.73825 | BO8: 1.0054073 | BP8: 12042.483 | BQ8: 1 | BR8: 0.1524
A9: 16.01_10 | B9: 13789520 | C9: 608.62111 | D9: 85.147894 | E9: 624.86627 | F9: 2643264.4 | G9: 1562687 | H9: 2.2019594e-05 | I9: 7.2223253e-05 | J9: 0.49112125 | K9: 7679.7516 | L9: 0.0065036383 | M9: 8 | N9: 3145.92 | O9: 2.8502296e-06 | P9: 0.005984734 | Q9: 0.001905 | R9: 0.1524 | S9: 4882495.9 | T9: 527.87377 | U9: 592.5429 | V9: 0.03 | W9: 82978.506 | X9: 0.031368633 | Y9: 5.6461473 | Z9: 5.6461473 | AA9: -1.7290978e-08 | AB9: 1.2566773e-05 | AC9: 682.29284 | AD9: 2597.9956 | AE9: 592.5429 | AF9: 0 | AG9: 1.2637255e-05 | AH9: 62.103184 | AI9: 0.31525602 | AJ9: 34.468802 | AK9: 4.7638668 | AL9: 1.129368 | AM9: 608.62111 | AN9: 5.4976681e-09 | AO9: 7.048264e-08 | AP9: 3.8238373 | AQ9: 3.7294385e-05 | AR9: 6.3538689e-06 | AS9: 17.330524 | AT9: 11.212347 | AU9: 3.5347598 | AV9: 0.28907754 | AW9: 0.0075552867 | AX9: 0.28907754 | AY9: 6.6502946e-09 | AZ9: 1080577.4 | BA9: 9.7531306e-06 | BB9: 4879564.9 | BC9: -2931.0368 | BD9: -0.060031526 | BE9: 4164600 | BF9: 1.1716767 | BG9: 1 | BH9: -0.027 | BI9: 0.046 | BJ9: 5625 | BK9: 1.0342425 | BL9: 80.747335 | BM9: 4.8795649 | BN9: 80.747335 | BO9: 1.0342425 | BP9: 1660.3453 | BQ9: 1 | BR9: 0.1524
A10: 17.01_10 | B10: 13789520 | C10: 608.62111 | D10: 85.147894 | E10: 624.86627 | F10: 2643264.4 | G10: 1562687 | H10: 2.2019594e-05 | I10: 7.2223253e-05 | J10: 0.49112125 | K10: 7679.7516 | L10: 0.0065036383 | M10: 9 | N10: 3145.92 | O10: 2.8502296e-06 | P10: 0.005984734 | Q10: 0.001905 | R10: 0.1524 | S10: 4746579.9 | T10: 532.84871 | U10: 595.71762 | V10: 0.03 | W10: 82978.506 | X10: 0.031368633 | Y10: 5.6461473 | Z10: 5.6461473 | AA10: -1.7290978e-08 | AB10: 1.2566773e-05 | AC10: 679.20281 | AD10: 2597.9956 | AE10: 595.71762 | AF10: 8.2104805e-07 | AG10: 1.2635624e-05 | AH10: 62.103184 | AI10: 0.31525602 | AJ10: 34.464353 | AK10: 4.5641502 | AL10: 1.129368 | AM10: 608.62111 | AN10: 5.2750693e-09 | AO10: 6.8851507e-08 | AP10: 3.8234611 | AQ10: 3.7301725e-05 | AR10: 6.3522378e-06 | AS10: 17.326075 | AT10: 11.211063 | AU10: 3.5343551 | AV10: 0.28910599 | AW10: 0.0075552867 | AX10: 0.28910599 | AY10: 6.6347027e-09 | AZ10: 1080577.4 | BA10: 9.7560102e-06 | BB10: 4765233.4 | BC10: 18653.502 | BD10: 0.39298826 | BE10: 3943750 | BF10: 1.2083001 | BG10: 1 | BH10: -0.026 | BI10: 0.046 | BJ10: 5625 | BK10: 1.0366402 | BL10: 75.772395 | BM10: 4.7652334 | BN10: 75.772395 | BO10: 1.0366402 | BP10: 1279.6642 | BQ10: 1 | BR10: 0.1524
A11: 18.01_10 | B11: 13789520 | C11: 608.62111 | D11: 85.147894 | E11: 624.86627 | F11: 2643264.4 | G11: 1562687 | H11: 2.2019594e-05 | I11: 7.2223253e-05 | J11: 0.49112125 | K11: 7679.7516 | L11: 0.0065036383 | M11: 10 | N11: 3634.08 | O11: 2.8502296e-06 | P11: 0.005984734 | Q11: 0.001905 | R11: 0.1524 | S11: 4995306.7 | T11: 541.31775 | U11: 598.59346 | V11: 0.03 | W11: 95854.481 | X11: 0.029426133 | Y11: 5.8295281 | Z11: 5.8295281 | AA11: -1.1375949e-08 | AB11: 1.0039048e-05 | AC11: 672.36144 | AD11: 2906.7256 | AE11: 598.59346 | AF11: 7.5276898e-07 | AG11: 1.0099601e-05 | AH11: 77.740099 | AI11: 0.35271912 | AJ11: 30.820754 | AK11: 4.1975785 | AL11: 1.129368 | AM11: 608.62111 | AN11: 1.9440449e-11 | AO11: 6.0552996e-08 | AP11: 4.0626716 | AQ11: 3.3038388e-05 | AR11: 5.080077e-06 | AS11: 15.502771 | AT11: 10.655094 | AU11: 3.7582554 | AV11: 0.30441616 | AW11: 0.00603559 | AX11: 0.30441613 | AY11: 2.9691387e-08 | AZ11: 1080577.4 | BA11: 8.1321828e-06 | BB11: 5027724.6 | BC11: 32417.899 | BD11: 0.64896713 | BE11: 4417000 | BF11: 1.1382668 | BG11: 1 | BH11: 0.001 | BI11: 0.046 | BJ11: 5625 | BK11: 1.0402904 | BL11: 67.303354 | BM11: 5.0277246 | BN11: 67.303354 | BO11: 1.0402904 | BP11: 745.47312 | BQ11: 1 | BR11: 0.1524
A12: 19.01_10 | B12: 13789520 | C12: 608.62111 | D12: 85.147894 | E12: 624.86627 | F12: 2643264.4 | G12: 1562687 | H12: 2.2019594e-05 | I12: 7.2223253e-05 | J12: 0.49112125 | K12: 7679.7516 | L12: 0.0065036383 | M12: 11 | N12: 3851.04 | O12: 2.8502296e-06 | P12: 0.005984734 | Q12: 0.001905 | R12: 0.1524 | S12: 5441965.2 | T12: 534.00031 | U12: 592.88204 | V12: 0.03 | W12: 101577.14 | X12: 0.028694843 | Y12: 5.9033437 | Z12: 5.9033438 | AA12: -2.692234e-08 | AB12: 9.1675816e-06 | AC12: 675.99184 | AD12: 3041.7457 | AE12: 592.88204 | AF12: 0 | AG12: 9.2286585e-06 | AH12: 85.130041 | AI12: 0.36910326 | AJ12: 29.47111 | AK12: 4.4833522 | AL12: 1.129368 | AM12: 608.62111 | AN12: 7.7393452e-09 | AO12: 6.1076909e-08 | AP12: 4.1622675 | AQ12: 3.1476199e-05 | AR12: 4.6448677e-06 | AS12: 14.833078 | AT12: 10.434298 | AU12: 3.8513335 | AV12: 0.31093403 | AW12: 0.0055116544 | AX12: 0.31093403 | AY12: 4.3665214e-09 | AZ12: 1080577.4 | BA12: 7.562272e-06 | BB12: 5453404.7 | BC12: 11439.455 | BD12: 0.21020817 | BE12: 4858700 | BF12: 1.1224 | BG12: 1 | BH12: -0.018 | BI12: 0.046 | BJ12: 5625 | BK12: 1.037172 | BL12: 74.620793 | BM12: 5.4534047 | BN12: 74.620793 | BO12: 1.037172 | BP12: 1198.5993 | BQ12: 1 | BR12: 0.1524
A13: 20.01_10 | B13: 13789520 | C13: 608.62111 | D13: 85.147894 | E13: 624.86627 | F13: 2643264.4 | G13: 1562687 | H13: 2.2019594e-05 | I13: 7.2223253e-05 | J13: 0.49112125 | K13: 7679.7516 | L13: 0.0065036383 | M13: 12 | N13: 3905.28 | O13: 2.8502296e-06 | P13: 0.005984734 | Q13: 0.001905 | R13: 0.1524 | S13: 5526348.1 | T13: 532.84871 | U13: 591.81297 | V13: 0.03 | W13: 103007.8 | X13: 0.02852248 | Y13: 5.921154 | Z13: 5.921154 | AA13: -8.2254532e-09 | AB13: 8.9685669e-06 | AC13: 676.31326 | AD13: 3075.3091 | AE13: 591.81297 | AF13: 0 | AG13: 9.0296211e-06 | AH13: 87.019097 | AI13: 0.37317603 | AJ13: 29.153675 | AK13: 4.5213585 | AL13: 1.129368 | AM13: 608.62111 | AN13: 3.3916194e-09 | AO13: 6.105419e-08 | AP13: 4.1864391 | AQ13: 3.1113775e-05 | AR13: 4.5453377e-06 | AS13: 14.6754 | AT13: 10.380863 | AU13: 3.8738893 | AV13: 0.31254988 | AW13: 0.0053920045 | AX13: 0.31254987 | AY13: 4.830728e-09 | AZ13: 1080577.4 | BA13: 7.432038e-06 | BB13: 5546902.3 | BC13: 20554.201 | BD13: 0.37193098 | BE13: 4890250 | BF13: 1.1342779 | BG13: 1 | BH13: -0.026 | BI13: 0.046 | BJ13: 5625 | BK13: 1.0366402 | BL13: 75.772395 | BM13: 5.5469023 | BN13: 75.772395 | BO13: 1.0366402 | BP13: 1279.6642 | BQ13: 1 | BR13: 0.1524
... A225: 30.01_14 | B225: 18960583 | C225: 634.44823 | D225: 149.14958 | E225: 520.38378 | F225: 2467301.6 | G225: 1775044 | H225: 2.5972811e-05 | I225: 5.9480773e-05 | J225: 0.43661799 | K225: 16063.58 | L225: 0.0016624879 | M225: 224 | N225: 3783.8817 | O225: 2.8502296e-06 | P225: 0.005984734 | Q225: 0.001905 | R225: 0.69596 | S225: 7711816.4 | T225: 299.58376 | U225: 484.99073 | V225: 0.03 | W225: 121186.97 | X225: 0.021931703 | Y225: 6.752488 | Z225: 6.752488 | AA225: -2.1136982e-08 | AB225: 2.6448803e-06 | AC225: 785.38105 | AD225: 3172.6131 | AE225: 484.99074 | AF225: 1.8538104e-06 | AG225: 2.8221506e-06 | AH225: 75.428196 | AI225: 0.38071938 | AJ225: 9.4000964 | AK225: 9.2542365 | AL225: 2.1883528 | AM225: 634.44823 | AN225: 1.551366e-07 | AO225: 1.7727027e-07 | AP225: 2.2154988 | AQ225: 1.8357848e-05 | AR225: 1.4997104e-06 | AS225: 4.9952766 | AT225: 4.9952766 | AU225: 1.9017986 | AV225: 0.31370019 | AW225: 0.0026083901 | AX225: 0.31370017 | AY225: 1.2818684e-08 | AZ225: 692257.61 | BA225: 8.2861014e-06 | BB225: 7706854.4 | BC225: -4962.0435 | BD225: -0.064343383 | BE225: 3564686.7 | BF225: 2.1620005 | BG225: 1 | BH225: -0.387 | BI225: 0.046 | BJ225: 5625 | BK225: 1 | BL225: 334.86448 | BM225: 7.7068544 | BN225: 334.86448 | BO225: 1 | BP225: 86945.06 | BQ225: 1 | BR225: 0.69596

Sheet STG_added138_noF1
A1: No_TableNo | B1: P | C1: Ts | D1: rhoG | E1: rhoL | F1: HG | G1: HL | H1: muG | I1: muL | J1: KL | K1: CPL | L1: sigma | M1: No | N1: G | O1: A | P1: Pw | Q1: DH | R1: L_DNB | S1: q_in | T1: Tin | U1: Tf | V1: f(beta) | W1: Re | X1: f | Y1: f_left | Z1: f_rihgt | AA1: f_balance | AB1: DB | AC1: Tw | AD1: y_plus | AE1: Tm | AF1: Tw_balance | AG1: y_star | AH1: tauw | AI1: Utau | AJ1: y_plus2 | AK1: Q | AL1: Pr | AM1: T(y_plus) | AN1: y_star_balance | AO1: delta | AP1: UB | AQ1: LB | AR1: YB | AS1: YB_plus | AT1: Karman_UB | AU1: UBL | AV1: UB_left | AW1: CD | AX1: UB_right | AY1: UB_balance | AZ1: HG-HL | BA1: LB/UB | BB1: q_P | BC1: dq_chf | BD1: dq_ratio | BE1: q_M | BF1: PM_ratio | BG1: F_form | BH1: x_Mes | BI1: A_corr | BJ1: σ_corr | BK1: Fcorr | BL1: Tsub | BM1: q_P_MW | BN1: Tsub2 | BO1: Fcorr2 | BP1: (Tsub-40)^2 | BQ1: F2 | BR1: L | BS1: STG_row_id | BT1: source_row_in_tm | BU1: source_variant | BV1: table_no | BW1: LD_geom | BX1: LD_band_H52Q | BY1: pass_G_gt1000 | BZ1: pass_LD_40_400 | CA1: staging_note
A2: 86.03_8 | B2: 10962664 | C2: 590.91886 | D2: 62.329535 | E2: 672.4241 | F2: 2706878.8 | G2: 1448743 | H2: 2.0627961e-05 | I2: 7.915472e-05 | J2: 0.52383293 | K2: 6433.0576 | L2: 0.010258316 | M2: 87 | N2: 1017.1724 | O2: 6.8620354e-05 | P2: 0.029365095 | Q2: 0.0093472 | R2: 1.524 | S2: 725513.61 | T2: 506.55651 | U2: 578.86628 | V2: 0.03 | W2: 120115.57 | X2: 0.041253861 | Y2: 4.9234292 | Z2: 4.9234293 | AA2: -6.1896998e-08 | AB2: 0.00015514466 | AC2: 626.31004 | AD2: 4312.7731 | AE2: 578.86628 | AF2: 2.6310022e-07 | AG2: 0.0001552636 | AH2: 7.9345172 | AI2: 0.10862721 | AJ2: 143.27642 | AK2: 2.0096721 | AL2: 0.97207878 | AM2: 590.91886 | AN2: 6.3171456e-08 | AO2: 1.1894768e-07 | AP2: 2.0088176 | AQ2: 0.00028001386 | AR2: 7.7691276e-05 | AS2: 71.693094 | AT2: 16.180986 | AU2: 1.7576953 | AV2: 0.25112224 | AW2: 0.078962181 | AX2: 0.25112224 | AY2: 4.8219696e-09 | AZ2: 1258135.8 | BA2: 0.00013939238 | BB2: 721917.75 | BC2: -3595.8639 | BD2: -0.49563011 | BE2: 1462152.8 | BF2: 0.49373618 | BG2: 1 | BH2: 0.395 | BI2: 0.046 | BJ2: 5625 | BK2: 1 | BL2: 84.362345 | BM2: 0.72191775 | BN2: 84.362345 | BO2: 1 | BP2: 1968.0176 | BQ2: 1 | BR2: 1.524 | BS2: 1 | BT2: 88 | BU2: noF1 | BV2: ="Table "&TRIM(RIGHT(SUBSTITUTE($A2,"_",REPT(" ",50)),50)) -> Table 8 | BW2: =$BR2/$Q2 -> 163.04348 | BX2: =IF($BW2<40,"outside_low",IF($BW2<=100,"short_anchor",IF($BW2<250,"middle",IF($BW2<=400,"long","outside_high")))) -> middle | BY2: =IF($N2>1000,"PASS","FAIL") -> PASS | BZ2: =IF(AND($BW2>=40,$BW2<=400),"PASS","FAIL") -> PASS
A3: 87.03_8 | B3: 10997138 | C3: 591.14539 | D3: 62.59171 | E3: 671.85013 | F3: 2706154 | G3: 1450155.2 | H3: 2.0644131e-05 | I3: 7.9067734e-05 | J3: 0.52342986 | K3: 6446.0268 | L3: 0.010209472 | M3: 88 | N3: 1017.1724 | O3: 6.8620354e-05 | P3: 0.029365095 | Q3: 0.0093472 | R3: 1.524 | S3: 1188180.2 | T3: 451.88649 | U3: 570.07059 | V3: 0.03 | W3: 120247.71 | X3: 0.041194605 | Y3: 4.926969 | Z3: 4.926969 | AA3: -5.6784206e-08 | AB3: 0.00015449607 | AC3: 652.95846 | AD3: 4314.4159 | AE3: 570.07059 | AF3: 0 | AG3: 0.00015469044 | AH3: 7.929889 | AI3: 0.1086419 | AJ3: 142.80189 | AK3: 3.5086561 | AL3: 0.97371734 | AM3: 591.14539 | AN3: 8.4076532e-08 | AO3: 1.9437112e-07 | AP3: 2.0076139 | AQ3: 0.00027796556 | AR3: 7.7442407e-05 | AS3: 71.49066 | AT3: 16.173917 | AU3: 1.7571651 | AV3: 0.25044879 | AW3: 0.078765918 | AX3: 0.25044878 | AY3: 4.5387024e-09 | AZ3: 1255998.8 | BA3: 0.00013845569 | BB3: 1184629.6 | BC3: -3550.6554 | BD3: -0.29883139 | BE3: 1810104.2 | BF3: 0.6544538 | BG3: 1 | BH3: 0.378 | BI3: 0.046 | BJ3: 5625 | BK3: 1 | BL3: 139.25889 | BM3: 1.1846296 | BN3: 139.25889 | BO3: 1 | BP3: 9852.3275 | BQ3: 1 | BR3: 1.524 | BS3: 2 | BT3: 89 | BU3: noF1 | BV3: ="Table "&TRIM(RIGHT(SUBSTITUTE($A3,"_",REPT(" ",50)),50)) -> Table 8 | BW3: =$BR3/$Q3 -> 163.04348 | BX3: =IF($BW3<40,"outside_low",IF($BW3<=100,"short_anchor",IF($BW3<250,"middle",IF($BW3<=400,"long","outside_high")))) -> middle | BY3: =IF($N3>1000,"PASS","FAIL") -> PASS | BZ3: =IF(AND($BW3>=40,$BW3<=400),"PASS","FAIL") -> PASS
A4: 88.03_8 | B4: 10997138 | C4: 591.14539 | D4: 62.59171 | E4: 671.85013 | F4: 2706154 | G4: 1450155.2 | H4: 2.0644131e-05 | I4: 7.9067734e-05 | J4: 0.52342986 | K4: 6446.0268 | L4: 0.010209472 | M4: 89 | N4: 1017.1724 | O4: 6.8620354e-05 | P4: 0.029365095 | Q4: 0.0093472 | R4: 1.524 | S4: 1188180.2 | T4: 451.88649 | U4: 570.07059 | V4: 0.03 | W4: 120247.71 | X4: 0.041194605 | Y4: 4.926969 | Z4: 4.926969 | AA4: -5.6784206e-08 | AB4: 0.00015449607 | AC4: 652.95846 | AD4: 4314.4159 | AE4: 570.07059 | AF4: 0 | AG4: 0.00015469044 | AH4: 7.929889 | AI4: 0.1086419 | AJ4: 142.80189 | AK4: 3.5086561 | AL4: 0.97371734 | AM4: 591.14539 | AN4: 8.4076532e-08 | AO4: 1.9437112e-07 | AP4: 2.0076139 | AQ4: 0.00027796556 | AR4: 7.7442407e-05 | AS4: 71.49066 | AT4: 16.173917 | AU4: 1.7571651 | AV4: 0.25044879 | AW4: 0.078765918 | AX4: 0.25044878 | AY4: 4.5387024e-09 | AZ4: 1255998.8 | BA4: 0.00013845569 | BB4: 1184629.6 | BC4: -3550.6554 | BD4: -0.29883139 | BE4: 1810104.2 | BF4: 0.6544538 | BG4: 1 | BH4: 0.378 | BI4: 0.046 | BJ4: 5625 | BK4: 1 | BL4: 139.25889 | BM4: 1.1846296 | BN4: 139.25889 | BO4: 1 | BP4: 9852.3275 | BQ4: 1 | BR4: 1.524 | BS4: 3 | BT4: 90 | BU4: noF1 | BV4: ="Table "&TRIM(RIGHT(SUBSTITUTE($A4,"_",REPT(" ",50)),50)) -> Table 8 | BW4: =$BR4/$Q4 -> 163.04348 | BX4: =IF($BW4<40,"outside_low",IF($BW4<=100,"short_anchor",IF($BW4<250,"middle",IF($BW4<=400,"long","outside_high")))) -> middle | BY4: =IF($N4>1000,"PASS","FAIL") -> PASS | BZ4: =IF(AND($BW4>=40,$BW4<=400),"PASS","FAIL") -> PASS
A5: 89.03_8 | B5: 11066085 | C5: 591.59844 | D5: 63.116059 | E5: 670.70218 | F5: 2704704.4 | G5: 1452979.6 | H5: 2.0676471e-05 | I5: 7.8893761e-05 | J5: 0.52262372 | K5: 6471.9652 | L5: 0.010111785 | M5: 90 | N5: 1017.1724 | O5: 6.8620354e-05 | P5: 0.029365095 | Q5: 0.0093472 | R5: 1.524 | S5: 726588.22 | T5: 507.48015 | U5: 579.46167 | V5: 0.03 | W5: 120512.88 | X5: 0.041075714 | Y5: 4.9340942 | Z5: 4.9340943 | AA5: -4.7161331e-08 | AB5: 0.0001531985 | AC5: 627.08447 | AD5: 4317.6857 | AE5: 579.46167 | AF5: 2.7084468e-07 | AG5: 0.00015331731 | AH5: 7.920536 | AI5: 0.10867069 | AJ5: 141.64155 | AK5: 2.0131418 | AL5: 0.9769891 | AM5: 591.59844 | AN5: 1.9676008e-08 | AO5: 1.1881009e-07 | AP5: 2.0044818 | AQ5: 0.00027410841 | AR5: 7.6718059e-05 | AS5: 70.875656 | AT5: 16.152318 | AU5: 1.7552835 | AV5: 0.24919834 | AW5: 0.078372968 | AX5: 0.24919833 | AY5: 3.8655313e-09 | AZ5: 1251724.8 | BA5: 0.00013674776 | BB5: 729409.91 | BC5: 2821.6923 | BD5: 0.3883482 | BE5: 1463730.1 | BF5: 0.49832268 | BG5: 1 | BH5: 0.398 | BI5: 0.046 | BJ5: 5625 | BK5: 1 | BL5: 84.118293 | BM5: 0.72940991 | BN5: 84.118293 | BO5: 1 | BP5: 1946.4237 | BQ5: 1 | BR5: 1.524 | BS5: 4 | BT5: 91 | BU5: noF1 | BV5: ="Table "&TRIM(RIGHT(SUBSTITUTE($A5,"_",REPT(" ",50)),50)) -> Table 8 | BW5: =$BR5/$Q5 -> 163.04348 | BX5: =IF($BW5<40,"outside_low",IF($BW5<=100,"short_anchor",IF($BW5<250,"middle",IF($BW5<=400,"long","outside_high")))) -> middle | BY5: =IF($N5>1000,"PASS","FAIL") -> PASS | BZ5: =IF(AND($BW5>=40,$BW5<=400),"PASS","FAIL") -> PASS
A6: 90.03_8 | B6: 11100559 | C6: 591.82497 | D6: 63.378234 | E6: 670.12821 | F6: 2703979.6 | G6: 1454391.8 | H6: 2.0692641e-05 | I6: 7.8806775e-05 | J6: 0.52222065 | K6: 6484.9344 | L6: 0.010062941 | M6: 91 | N6: 1017.1724 | O6: 6.8620354e-05 | P6: 0.029365095 | Q6: 0.0093472 | R6: 1.524 | S6: 251440.27 | T6: 563.20065 | U6: 588.06048 | V6: 0.03 | W6: 120645.9 | X6: 0.041016077 | Y6: 4.93768 | Z6: 4.93768 | AA6: -4.2665931e-08 | AB6: 0.0001525495 | AC6: 602.81274 | AD6: 4319.3126 | AE6: 588.06048 | AF6: 0 | AG6: 0.00015259053 | AH6: 7.9158105 | AI6: 0.10868478 | AJ6: 141.02324 | AK6: 0.62319531 | AL6: 0.97862228 | AM6: 591.82497 | AN6: 2.8433078e-08 | AO6: 4.1025804e-08 | AP6: 2.0027781 | AQ6: 0.00027223569 | AR6: 7.6315778e-05 | AS6: 70.530576 | AT6: 16.140116 | AU6: 1.754185 | AV6: 0.24859307 | AW6: 0.078176278 | AX6: 0.24859306 | AY6: 3.5208624e-09 | AZ6: 1249587.8 | BA6: 0.00013592904 | BB6: 252737.41 | BC6: 1297.1448 | BD6: 0.51588589 | BE6: 1117356 | BF6: 0.22619237 | BG6: 1 | BH6: 0.44 | BI6: 0.046 | BJ6: 5625 | BK6: 1 | BL6: 28.62432 | BM6: 0.25273741 | BN6: 28.62432 | BO6: 1 | BP6: 129.40609 | BQ6: 1 | BR6: 1.524 | BS6: 5 | BT6: 92 | BU6: noF1 | BV6: ="Table "&TRIM(RIGHT(SUBSTITUTE($A6,"_",REPT(" ",50)),50)) -> Table 8 | BW6: =$BR6/$Q6 -> 163.04348 | BX6: =IF($BW6<40,"outside_low",IF($BW6<=100,"short_anchor",IF($BW6<250,"middle",IF($BW6<=400,"long","outside_high")))) -> middle | BY6: =IF($N6>1000,"PASS","FAIL") -> PASS | BZ6: =IF(AND($BW6>=40,$BW6<=400),"PASS","FAIL") -> PASS
A7: 91.03_8 | B7: 11100559 | C7: 591.82497 | D7: 63.378234 | E7: 670.12821 | F7: 2703979.6 | G7: 1454391.8 | H7: 2.0692641e-05 | I7: 7.8806775e-05 | J7: 0.52222065 | K7: 6484.9344 | L7: 0.010062941 | M7: 92 | N7: 1017.1724 | O7: 6.8620354e-05 | P7: 0.029365095 | Q7: 0.0093472 | R7: 1.524 | S7: 251440.27 | T7: 563.20065 | U7: 588.06048 | V7: 0.03 | W7: 120645.9 | X7: 0.041016077 | Y7: 4.93768 | Z7: 4.93768 | AA7: -4.2665931e-08 | AB7: 0.0001525495 | AC7: 602.81274 | AD7: 4319.3126 | AE7: 588.06048 | AF7: 0 | AG7: 0.00015259053 | AH7: 7.9158105 | AI7: 0.10868478 | AJ7: 141.02324 | AK7: 0.62319531 | AL7: 0.97862228 | AM7: 591.82497 | AN7: 2.8433078e-08 | AO7: 4.1025804e-08 | AP7: 2.0027781 | AQ7: 0.00027223569 | AR7: 7.6315778e-05 | AS7: 70.530576 | AT7: 16.140116 | AU7: 1.754185 | AV7: 0.24859307 | AW7: 0.078176278 | AX7: 0.24859306 | AY7: 3.5208624e-09 | AZ7: 1249587.8 | BA7: 0.00013592904 | BB7: 252737.41 | BC7: 1297.1448 | BD7: 0.51588589 | BE7: 1123980.7 | BF7: 0.22485921 | BG7: 1 | BH7: 0.444 | BI7: 0.046 | BJ7: 5625 | BK7: 1 | BL7: 28.62432 | BM7: 0.25273741 | BN7: 28.62432 | BO7: 1 | BP7: 129.40609 | BQ7: 1 | BR7: 1.524 | BS7: 6 | BT7: 93 | BU7: noF1 | BV7: ="Table "&TRIM(RIGHT(SUBSTITUTE($A7,"_",REPT(" ",50)),50)) -> Table 8 | BW7: =$BR7/$Q7 -> 163.04348 | BX7: =IF($BW7<40,"outside_low",IF($BW7<=100,"short_anchor",IF($BW7<250,"middle",IF($BW7<=400,"long","outside_high")))) -> middle | BY7: =IF($N7>1000,"PASS","FAIL") -> PASS | BZ7: =IF(AND($BW7>=40,$BW7<=400),"PASS","FAIL") -> PASS
A8: 92.03_8 | B8: 10997138 | C8: 591.14539 | D8: 62.59171 | E8: 671.85013 | F8: 2706154 | G8: 1450155.2 | H8: 2.0644131e-05 | I8: 7.9067734e-05 | J8: 0.52342986 | K8: 6446.0268 | L8: 0.010209472 | M8: 93 | N8: 2034.3448 | O8: 6.8620354e-05 | P8: 0.029365095 | Q8: 0.0093472 | R8: 1.524 | S8: 1299408.3 | T8: 508.01718 | U8: 572.64096 | V8: 0.03 | W8: 240495.42 | X8: 0.0294923 | Y8: 5.8229851 | Z8: 5.8229851 | AA8: -1.2846518e-08 | AB8: 5.3949714e-05 | AC8: 626.04803 | AD8: 7301.0639 | AE8: 572.64096 | AF8: 2.6048031e-07 | AG8: 5.4012325e-05 | AH8: 22.708864 | AI8: 0.1838491 | AJ8: 84.377662 | AK8: 2.1410147 | AL8: 0.97371734 | AM8: 591.14539 | AN8: 9.5339601e-08 | AO8: 6.261121e-08 | AP8: 3.0139892 | AQ8: 0.00012332978 | AR8: 2.7037468e-05 | AS8: 42.237736 | AT8: 14.858285 | AU8: 2.7316823 | AV8: 0.28230696 | AW8: 0.027504898 | AX8: 0.28230695 | AY8: 1.2072983e-08 | AZ8: 1255998.8 | BA8: 4.0919118e-05 | BB8: 1291182 | BC8: -8226.3238 | BD8: -0.6330823 | BE8: 1988969.5 | BF8: 0.64917134 | BG8: 1 | BH8: 0.151 | BI8: 0.046 | BJ8: 5625 | BK8: 1 | BL8: 83.128209 | BM8: 1.291182 | BN8: 83.128209 | BO8: 1 | BP8: 1860.0424 | BQ8: 1 | BR8: 1.524 | BS8: 7 | BT8: 94 | BU8: noF1 | BV8: ="Table "&TRIM(RIGHT(SUBSTITUTE($A8,"_",REPT(" ",50)),50)) -> Table 8 | BW8: =$BR8/$Q8 -> 163.04348 | BX8: =IF($BW8<40,"outside_low",IF($BW8<=100,"short_anchor",IF($BW8<250,"middle",IF($BW8<=400,"long","outside_high")))) -> middle | BY8: =IF($N8>1000,"PASS","FAIL") -> PASS | BZ8: =IF(AND($BW8>=40,$BW8<=400),"PASS","FAIL") -> PASS
A9: 93.03_8 | B9: 11031612 | C9: 591.37191 | D9: 62.853884 | E9: 671.27615 | F9: 2705429.2 | G9: 1451567.4 | H9: 2.0660301e-05 | I9: 7.8980747e-05 | J9: 0.52302679 | K9: 6458.996 | L9: 0.010160629 | M9: 94 | N9: 2034.3448 | O9: 6.8620354e-05 | P9: 0.029365095 | Q9: 0.0093472 | R9: 1.524 | S9: 451398.56 | T9: 563.22085 | U9: 585.62529 | V9: 0.03 | W9: 240760.3 | X9: 0.029455365 | Y9: 5.8266348 | Z9: 5.8266348 | AA9: -1.1835185e-08 | AB9: 5.3713009e-05 | AC9: 602.19726 | AD9: 7304.5268 | AE9: 585.62529 | AF9: 0 | AG9: 5.3734839e-05 | AH9: 22.699817 | AI9: 0.18389104 | AJ9: 83.983988 | AK9: 0.66391239 | AL9: 0.97535412 | AM9: 591.37191 | AN9: 2.5174018e-08 | AO9: 2.182971e-08 | AP9: 3.0114546 | AQ9: 0.00012248628 | AR9: 2.6878334e-05 | AS9: 42.009053 | AT9: 14.844713 | AU9: 2.7298097 | AV9: 0.28164495 | AW9: 0.027431119 | AX9: 0.28164494 | AY9: 1.1852956e-08 | AZ9: 1253861.8 | BA9: 4.0673462e-05 | BB9: 451739.12 | BC9: 340.56937 | BD9: 0.075447598 | BE9: 1385496.3 | BF9: 0.32604861 | BG9: 1 | BH9: 0.224 | BI9: 0.046 | BJ9: 5625 | BK9: 1 | BL9: 28.15106 | BM9: 0.45173912 | BN9: 28.15106 | BO9: 1 | BP9: 140.39738 | BQ9: 1 | BR9: 1.524 | BS9: 8 | BT9: 95 | BU9: noF1 | BV9: ="Table "&TRIM(RIGHT(SUBSTITUTE($A9,"_",REPT(" ",50)),50)) -> Table 8 | BW9: =$BR9/$Q9 -> 163.04348 | BX9: =IF($BW9<40,"outside_low",IF($BW9<=100,"short_anchor",IF($BW9<250,"middle",IF($BW9<=400,"long","outside_high")))) -> middle | BY9: =IF($N9>1000,"PASS","FAIL") -> PASS | BZ9: =IF(AND($BW9>=40,$BW9<=400),"PASS","FAIL") -> PASS
A10: 94.03_8 | B10: 11031612 | C10: 591.37191 | D10: 62.853884 | E10: 671.27615 | F10: 2705429.2 | G10: 1451567.4 | H10: 2.0660301e-05 | I10: 7.8980747e-05 | J10: 0.52302679 | K10: 6458.996 | L10: 0.010160629 | M10: 95 | N10: 2034.3448 | O10: 6.8620354e-05 | P10: 0.029365095 | Q10: 0.0093472 | R10: 1.524 | S10: 2153254.4 | T10: 451.67798 | U10: 558.55127 | V10: 0.03 | W10: 240760.3 | X10: 0.029455365 | Y10: 5.8266348 | Z10: 5.8266348 | AA10: -1.1835185e-08 | AB10: 5.3713009e-05 | AC10: 653.24085 | AD10: 7304.5268 | AE10: 558.55127 | AF10: 0 | AG10: 5.3817923e-05 | AH10: 22.699817 | AI10: 0.18389104 | AJ10: 84.113844 | AK10: 3.7934894 | AL10: 0.97535412 | AM10: 591.37191 | AN10: 1.5115131e-07 | AO10: 1.0491396e-07 | AP10: 3.0127522 | AQ10: 0.0001223808 | AR10: 2.6961418e-05 | AS10: 42.138909 | AT10: 14.852429 | AU10: 2.7312285 | AV10: 0.28152365 | AW10: 0.027431119 | AX10: 0.28152363 | AY10: 1.1895141e-08 | AZ10: 1253861.8 | BA10: 4.0620931e-05 | BB10: 2173873.7 | BC10: 20619.292 | BD10: 0.95758734 | BE10: 2603483.7 | BF10: 0.83498648 | BG10: 1 | BH10: 0.116 | BI10: 0.046 | BJ10: 5625 | BK10: 1 | BL10: 139.69394 | BM10: 2.1738737 | BN10: 139.69394 | BO10: 1 | BP10: 9938.8807 | BQ10: 1 | BR10: 1.524 | BS10: 9 | BT10: 96 | BU10: noF1 | BV10: ="Table "&TRIM(RIGHT(SUBSTITUTE($A10,"_",REPT(" ",50)),50)) -> Table 8 | BW10: =$BR10/$Q10 -> 163.04348 | BX10: =IF($BW10<40,"outside_low",IF($BW10<=100,"short_anchor",IF($BW10<250,"middle",IF($BW10<=400,"long","outside_high")))) -> middle | BY10: =IF($N10>1000,"PASS","FAIL") -> PASS | BZ10: =IF(AND($BW10>=40,$BW10<=400),"PASS","FAIL") -> PASS
A11: 95.03_8 | B11: 11066085 | C11: 591.59844 | D11: 63.116059 | E11: 670.70218 | F11: 2704704.4 | G11: 1452979.6 | H11: 2.0676471e-05 | I11: 7.8893761e-05 | J11: 0.52262372 | K11: 6471.9652 | L11: 0.010111785 | M11: 96 | N11: 2034.3448 | O11: 6.8620354e-05 | P11: 0.029365095 | Q11: 0.0093472 | R11: 1.524 | S11: 451329.86 | T11: 563.4923 | U11: 585.84844 | V11: 0.03 | W11: 241025.75 | X11: 0.029418345 | Y11: 5.8302997 | Z11: 5.8302997 | AA11: -1.0867479e-08 | AB11: 5.3476306e-05 | AC11: 602.41987 | AD11: 7307.9838 | AE11: 585.84844 | AF11: 2.4198471e-08 | AG11: 5.3498127e-05 | AH11: 22.690689 | AI11: 0.18393271 | AJ11: 83.653596 | AK11: 0.66345758 | AL11: 0.9769891 | AM11: 591.59844 | AN11: 2.168872e-08 | AO11: 2.1820322e-08 | AP11: 3.0095434 | AQ11: 0.00012159771 | AR11: 2.6759974e-05 | AS11: 41.843858 | AT11: 14.834863 | AU11: 2.7286165 | AV11: 0.28092683 | AW11: 0.027357297 | AX11: 0.28092682 | AY11: 1.1648933e-08 | AZ11: 1251724.8 | BA11: 4.040404e-05 | BB11: 453393.12 | BC11: 2063.2593 | BD11: 0.45715107 | BE11: 1385496.3 | BF11: 0.3272424 | BG11: 1 | BH11: 0.224 | BI11: 0.046 | BJ11: 5625 | BK11: 1 | BL11: 28.106141 | BM11: 0.45339312 | BN11: 28.106141 | BO11: 1 | BP11: 141.46388 | BQ11: 1 | BR11: 1.524 | BS11: 10 | BT11: 97 | BU11: noF1 | BV11: ="Table "&TRIM(RIGHT(SUBSTITUTE($A11,"_",REPT(" ",50)),50)) -> Table 8 | BW11: =$BR11/$Q11 -> 163.04348 | BX11: =IF($BW11<40,"outside_low",IF($BW11<=100,"short_anchor",IF($BW11<250,"middle",IF($BW11<=400,"long","outside_high")))) -> middle | BY11: =IF($N11>1000,"PASS","FAIL") -> PASS | BZ11: =IF(AND($BW11>=40,$BW11<=400),"PASS","FAIL") -> PASS
A12: 96.03_8 | B12: 11066085 | C12: 591.59844 | D12: 63.116059 | E12: 670.70218 | F12: 2704704.4 | G12: 1452979.6 | H12: 2.0676471e-05 | I12: 7.8893761e-05 | J12: 0.52262372 | K12: 6471.9652 | L12: 0.010111785 | M12: 97 | N12: 2034.3448 | O12: 6.8620354e-05 | P12: 0.029365095 | Q12: 0.0093472 | R12: 1.524 | S12: 2154258.6 | T12: 452.0028 | U12: 558.71166 | V12: 0.03 | W12: 241025.75 | X12: 0.029418345 | Y12: 5.8302997 | Z12: 5.8302997 | AA12: -1.0867479e-08 | AB12: 5.3476306e-05 | AC12: 653.53298 | AD12: 7307.9838 | AE12: 558.71166 | AF12: 0 | AG12: 5.3580539e-05 | AH12: 22.690689 | AI12: 0.18393271 | AJ12: 83.782461 | AK12: 3.7962884 | AL12: 0.9769891 | AM12: 591.59844 | AN12: 1.3083854e-07 | AO12: 1.0423211e-07 | AP12: 3.0108366 | AQ12: 0.00012149327 | AR12: 2.6842385e-05 | AS12: 41.972723 | AT12: 14.84255 | AU12: 2.7300305 | AV12: 0.28080616 | AW12: 0.027357297 | AX12: 0.28080615 | AY12: 1.1694497e-08 | AZ12: 1251724.8 | BA12: 4.0351997e-05 | BB12: 2168578.2 | BC12: 14319.61 | BD12: 0.66471177 | BE12: 2603483.7 | BF12: 0.83295245 | BG12: 1 | BH12: 0.116 | BI12: 0.046 | BJ12: 5625 | BK12: 1 | BL12: 139.59565 | BM12: 2.1685782 | BN12: 139.59565 | BO12: 1 | BP12: 9919.2928 | BQ12: 1 | BR12: 1.524 | BS12: 11 | BT12: 98 | BU12: noF1 | BV12: ="Table "&TRIM(RIGHT(SUBSTITUTE($A12,"_",REPT(" ",50)),50)) -> Table 8 | BW12: =$BR12/$Q12 -> 163.04348 | BX12: =IF($BW12<40,"outside_low",IF($BW12<=100,"short_anchor",IF($BW12<250,"middle",IF($BW12<=400,"long","outside_high")))) -> middle | BY12: =IF($N12>1000,"PASS","FAIL") -> PASS | BZ12: =IF(AND($BW12>=40,$BW12<=400),"PASS","FAIL") -> PASS
A13: 97.03_8 | B13: 11100559 | C13: 591.82497 | D13: 63.378234 | E13: 670.12821 | F13: 2703979.6 | G13: 1454391.8 | H13: 2.0692641e-05 | I13: 7.8806775e-05 | J13: 0.52222065 | K13: 6484.9344 | L13: 0.010062941 | M13: 98 | N13: 2034.3448 | O13: 6.8620354e-05 | P13: 0.029365095 | Q13: 0.0093472 | R13: 1.524 | S13: 1326521.8 | T13: 507.23596 | U13: 572.81237 | V13: 0.03 | W13: 241291.8 | X13: 0.029381239 | Y13: 5.8339802 | Z13: 5.8339802 | AA13: -9.9439816e-09 | AB13: 5.3239606e-05 | AC13: 627.58431 | AD13: 7311.4349 | AE13: 572.81237 | AF13: 2.7584304e-07 | AG13: 5.3302598e-05 | AH13: 22.681479 | AI13: 0.18397412 | AJ13: 83.387212 | AK13: 2.1914344 | AL13: 0.97862228 | AM13: 591.82497 | AN13: 6.2851427e-08 | AO13: 6.2992193e-08 | AP13: 3.008271 | AQ13: 0.00012066375 | AR13: 2.6682795e-05 | AS13: 41.742879 | AT13: 14.828822 | AU13: 2.7281195 | AV13: 0.28015146 | AW13: 0.027283433 | AX13: 0.28015145 | AY13: 1.1466843e-08 | AZ13: 1249587.8 | BA13: 4.0110665e-05 | BB13: 1315078.1 | BC13: -11443.712 | BD13: -0.86268556 | BE13: 1988969.5 | BF13: 0.66118565 | BG13: 1 | BH13: 0.156 | BI13: 0.046 | BJ13: 5625 | BK13: 1 | BL13: 84.589013 | BM13: 1.3150781 | BN13: 84.589013 | BO13: 1 | BP13: 1988.18 | BQ13: 1 | BR13: 1.524 | BS13: 12 | BT13: 99 | BU13: noF1 | BV13: ="Table "&TRIM(RIGHT(SUBSTITUTE($A13,"_",REPT(" ",50)),50)) -> Table 8 | BW13: =$BR13/$Q13 -> 163.04348 | BX13: =IF($BW13<40,"outside_low",IF($BW13<=100,"short_anchor",IF($BW13<250,"middle",IF($BW13<=400,"long","outside_high")))) -> middle | BY13: =IF($N13>1000,"PASS","FAIL") -> PASS | BZ13: =IF(AND($BW13>=40,$BW13<=400),"PASS","FAIL") -> PASS
... A139: 30.01_14 | B139: 18960583 | C139: 634.44823 | D139: 149.14958 | E139: 520.38378 | F139: 2467301.6 | G139: 1775044 | H139: 2.5972811e-05 | I139: 5.9480773e-05 | J139: 0.43661799 | K139: 16063.58 | L139: 0.0016624879 | M139: 224 | N139: 3783.8817 | O139: 2.8502296e-06 | P139: 0.005984734 | Q139: 0.001905 | R139: 0.69596 | S139: 7711816.4 | T139: 299.58376 | U139: 484.99073 | V139: 0.03 | W139: 121186.97 | X139: 0.021931703 | Y139: 6.752488 | Z139: 6.752488 | AA139: -2.1136982e-08 | AB139: 2.6448803e-06 | AC139: 785.38105 | AD139: 3172.6131 | AE139: 484.99073 | AF139: 0 | AG139: 2.8221508e-06 | AH139: 75.428196 | AI139: 0.38071938 | AJ139: 9.4000972 | AK139: 9.2542365 | AL139: 2.1883528 | AM139: 634.44823 | AN139: 1.5513524e-07 | AO139: 1.772705e-07 | AP139: 2.215499 | AQ139: 1.8357844e-05 | AR139: 1.4997106e-06 | AS139: 4.9952773 | AT139: 4.9952773 | AU139: 1.9017989 | AV139: 0.31370015 | AW139: 0.0026083901 | AX139: 0.31370014 | AY139: 1.2818768e-08 | AZ139: 692257.61 | BA139: 8.2860986e-06 | BB139: 7706866.7 | BC139: -4949.7558 | BD139: -0.064184046 | BE139: 3564686.7 | BF139: 2.1620039 | BG139: 1 | BH139: -0.387 | BI139: 0.046 | BJ139: 5625 | BK139: 1 | BL139: 334.86448 | BM139: 7.7068667 | BN139: 334.86448 | BO139: 1 | BP139: 86945.06 | BQ139: 1 | BR139: 0.69596 | BS139: 138 | BT139: 225 | BU139: noF1 | BV139: ="Table "&TRIM(RIGHT(SUBSTITUTE($A139,"_",REPT(" ",50)),50)) -> Table 14 | BW139: =$BR139/$Q139 -> 365.33333 | BX139: =IF($BW139<40,"outside_low",IF($BW139<=100,"short_anchor",IF($BW139<250,"middle",IF($BW139<=400,"long","outside_high")))) -> long | BY139: =IF($N139>1000,"PASS","FAIL") -> PASS | BZ139: =IF(AND($BW139>=40,$BW139<=400),"PASS","FAIL") -> PASS

Sheet STG_added138_F1
A1: No_TableNo | B1: P | C1: Ts | D1: rhoG | E1: rhoL | F1: HG | G1: HL | H1: muG | I1: muL | J1: KL | K1: CPL | L1: sigma | M1: No | N1: G | O1: A | P1: Pw | Q1: DH | R1: L_DNB | S1: q_in | T1: Tin | U1: Tf | V1: f(beta) | W1: Re | X1: f | Y1: f_left | Z1: f_rihgt | AA1: f_balance | AB1: DB | AC1: Tw | AD1: y_plus | AE1: Tm | AF1: Tw_balance | AG1: y_star | AH1: tauw | AI1: Utau | AJ1: y_plus2 | AK1: Q | AL1: Pr | AM1: T(y_plus) | AN1: y_star_balance | AO1: delta | AP1: UB | AQ1: LB | AR1: YB | AS1: YB_plus | AT1: Karman_UB | AU1: UBL | AV1: UB_left | AW1: CD | AX1: UB_right | AY1: UB_balance | AZ1: HG-HL | BA1: LB/UB | BB1: q_P | BC1: dq_chf | BD1: dq_ratio | BE1: q_M | BF1: PM_ratio | BG1: F_form | BH1: x_Mes | BI1: A_corr | BJ1: σ_corr | BK1: Fcorr | BL1: Tsub | BM1: q_P_MW | BN1: Tsub2 | BO1: Fcorr2 | BP1: (Tsub-40)^2 | BQ1: F2 | BR1: L | BS1: STG_row_id | BT1: source_row_in_tm | BU1: source_variant | BV1: table_no | BW1: LD_geom | BX1: LD_band_H52Q | BY1: pass_G_gt1000 | BZ1: pass_LD_40_400 | CA1: staging_note
A2: 86.03_8 | B2: 10962664 | C2: 590.91886 | D2: 62.329535 | E2: 672.4241 | F2: 2706878.8 | G2: 1448743 | H2: 2.0627961e-05 | I2: 7.915472e-05 | J2: 0.52383293 | K2: 6433.0576 | L2: 0.010258316 | M2: 87 | N2: 1017.1724 | O2: 6.8620354e-05 | P2: 0.029365095 | Q2: 0.0093472 | R2: 1.524 | S2: 905400.43 | T2: 506.55651 | U2: 596.79506 | V2: 0.03 | W2: 120115.57 | X2: 0.041253861 | Y2: 4.9234292 | Z2: 4.9234293 | AA2: -6.1896998e-08 | AB2: 0.00015514466 | AC2: 634.02655 | AD2: 4312.7731 | AE2: 596.79506 | AF2: 0 | AG2: 0.00015529392 | AH2: 7.9345172 | AI2: 0.10862721 | AJ2: 143.3044 | AK2: 2.447783 | AL2: 0.97207878 | AM2: 590.91886 | AN2: 7.7970185e-08 | AO2: 1.4926391e-07 | AP2: 2.0089118 | AQ2: 0.00027998761 | AR2: 7.7721592e-05 | AS2: 71.721069 | AT2: 16.181961 | AU2: 1.7578013 | AV2: 0.25111047 | AW2: 0.078962181 | AX2: 0.25111047 | AY2: 4.8399979e-09 | AZ2: 1258135.8 | BA2: 0.00013937278 | BB2: 906040.58 | BC2: 640.15832 | BD2: 0.070704443 | BE2: 1462152.8 | BF2: 0.61966203 | BG2: 1 | BH2: 0.395 | BI2: 0.046 | BJ2: 5625 | BK2: 1.0324199 | BL2: 84.362345 | BM2: 0.90604058 | BN2: 84.362345 | BO2: 1.0324199 | BP2: 1968.0176 | BQ2: 1 | BR2: 1.524 | BS2: 1 | BT2: 88 | BU2: F1 | BV2: ="Table "&TRIM(RIGHT(SUBSTITUTE($A2,"_",REPT(" ",50)),50)) -> Table 8 | BW2: =$BR2/$Q2 -> 163.04348 | BX2: =IF($BW2<40,"outside_low",IF($BW2<=100,"short_anchor",IF($BW2<250,"middle",IF($BW2<=400,"long","outside_high")))) -> middle | BY2: =IF($N2>1000,"PASS","FAIL") -> PASS | BZ2: =IF(AND($BW2>=40,$BW2<=400),"PASS","FAIL") -> PASS
A3: 87.03_8 | B3: 10997138 | C3: 591.14539 | D3: 62.59171 | E3: 671.85013 | F3: 2706154 | G3: 1450155.2 | H3: 2.0644131e-05 | I3: 7.9067734e-05 | J3: 0.52342986 | K3: 6446.0268 | L3: 0.010209472 | M3: 88 | N3: 1017.1724 | O3: 6.8620354e-05 | P3: 0.029365095 | Q3: 0.0093472 | R3: 1.524 | S3: 1233468.4 | T3: 451.88649 | U3: 574.57525 | V3: 0.03 | W3: 120247.71 | X3: 0.041194605 | Y3: 4.926969 | Z3: 4.926969 | AA3: -5.6784206e-08 | AB3: 0.00015449607 | AC3: 655.08323 | AD3: 4314.4159 | AE3: 574.57525 | AF3: 0 | AG3: 0.00015469795 | AH3: 7.929889 | AI3: 0.1086419 | AJ3: 142.80882 | AK3: 3.6292378 | AL3: 0.97371734 | AM3: 591.14539 | AN3: 8.7300123e-08 | AO3: 2.0187655e-07 | AP3: 2.0076373 | AQ3: 0.00027795908 | AR3: 7.7449912e-05 | AS3: 71.497589 | AT3: 16.174159 | AU3: 1.7571914 | AV3: 0.25044587 | AW3: 0.078765918 | AX3: 0.25044586 | AY3: 4.5430675e-09 | AZ3: 1255998.8 | BA3: 0.00013845085 | BB3: 1230415.7 | BC3: -3052.7017 | BD3: -0.24748925 | BE3: 1810104.2 | BF3: 0.67974857 | BG3: 1 | BH3: 0.378 | BI3: 0.046 | BJ3: 5625 | BK3: 1.0079814 | BL3: 139.25889 | BM3: 1.2304157 | BN3: 139.25889 | BO3: 1.0079814 | BP3: 9852.3275 | BQ3: 1 | BR3: 1.524 | BS3: 2 | BT3: 89 | BU3: F1 | BV3: ="Table "&TRIM(RIGHT(SUBSTITUTE($A3,"_",REPT(" ",50)),50)) -> Table 8 | BW3: =$BR3/$Q3 -> 163.04348 | BX3: =IF($BW3<40,"outside_low",IF($BW3<=100,"short_anchor",IF($BW3<250,"middle",IF($BW3<=400,"long","outside_high")))) -> middle | BY3: =IF($N3>1000,"PASS","FAIL") -> PASS | BZ3: =IF(AND($BW3>=40,$BW3<=400),"PASS","FAIL") -> PASS
