Workbook
Name L_tot: '非一様加熱を一様加熱に補正161 '!$D$8
Name L_tot: 非一様加熱を一様加熱に補正164!$D$8
Name L_tot: 非一様加熱を一様加熱に補正108!$D$8
Name 半径方向の出力: '非一様加熱を一様加熱に補正161 '!$D$4
Name 半径方向の出力: 非一様加熱を一様加熱に補正164!$D$4
Name 半径方向の出力: 非一様加熱を一様加熱に補正108!$D$4

Sheet TEST SECTION NUMBER 108
A1: X | B1: Y | C1: TEST NUMBER | E1: 正規化座標XCHF | F1: Q(AVE) | G1: qCHF[10⁶ Btu/hr・ft²] | I1: SRL[-] | J1: RUN[-] | K1: PRESS[psia] | L1: TEMP[F] | M1: G(AVE)[106 lbs/hr・ft²] | N1: Q(AVE)[10⁶ Btu/hr・ft²] | O1: CHF RODS[-] | P1: HEATED LENGTH[inch] | Q1: LOCATION OF CHF[inch] | R1: NORMALIZED DISTRIBUTION(Y)
A2: 0 | B2: 0.358 | C2: 108 | E2: =Q2/P2 -> 0.72916667 | F2: =N2 -> 0.568 | G2: =$C$8*F2*R2 -> 1.0293868 | I2: 1 | J2: 8 | K2: 1515 | L2: 520 | M2: 2.5 | N2: 0.568 | O2: 14.6 | P2: 96 | Q2: 70 | R2: 1.5827953
A3: 0.052 | B3: 0.359 | C3: PITCH[in] | E3: =Q3/P3 -> 0.72916667 | F3: =N3 -> 0.624 | G3: =$C$8*F3*R3 -> 1.1308756 | I3: 2 | J3: 9 | K3: 1515 | L3: 499 | M3: 2.5 | N3: 0.624 | O3: 14.6 | P3: 96 | Q3: 70 | R3: 1.5827953
A4: 0.104 | B4: 0.4 | C4: 0.555 | E4: =Q4/P4 -> 0.72916667 | F4: =N4 -> 0.51 | G4: =$C$8*F4*R4 -> 0.92427331 | I4: 3 | J4: 10 | K4: 2165 | L4: 584 | M4: 2.587 | N4: 0.51 | O4: 14.6 | P4: 96 | Q4: 70 | R4: 1.5827953
A5: 0.156 | B5: 0.458 | C5: ROD OD[in] | E5: =Q5/P5 -> 0.72916667 | F5: =N5 -> 0.557 | G5: =$C$8*F5*R5 -> 1.0094514 | I5: 4 | J5: 11 | K5: 2115 | L5: 567 | M5: 2.54 | N5: 0.557 | O5: 14.6 | P5: 96 | Q5: 70 | R5: 1.5827953
A6: 0.208 | B6: 0.567 | C6: 0.422 | E6: =Q6/P6 -> 0.72916667 | F6: =N6 -> 0.55 | G6: =$C$8*F6*R6 -> 0.99676534 | I6: 5 | J6: 12 | K6: 2415 | L6: 577 | M6: 2.535 | N6: 0.55 | O6: 14.6 | P6: 96 | Q6: 70 | R6: 1.5827953
A7: 0.26 | B7: 0.683 | C7: 半径方向の出力分布補正 | E7: =Q7/P7 -> 0.72916667 | F7: =N7 -> 0.517 | G7: =$C$8*F7*R7 -> 0.93695942 | I7: 6 | J7: 13 | K7: 2415 | L7: 559 | M7: 2.064 | N7: 0.517 | O7: 14.6 | P7: 96 | Q7: 70 | R7: 1.5827953
A8: 0.313 | B8: 0.833 | C8: 1.145 | E8: =Q8/P8 -> 0.72916667 | F8: =N8 -> 0.512 | G8: =$C$8*F8*R8 -> 0.92789792 | I8: 7 | J8: 14 | K8: 1515 | L8: 560 | M8: 3.429 | N8: 0.512 | O8: 14.6 | P8: 96 | Q8: 70 | R8: 1.5827953
A9: 0.365 | B9: 0.992 | E9: =Q9/P9 -> 0.72916667 | F9: =N9 -> 0.545 | G9: =$C$8*F9*R9 -> 0.98770384 | I9: 8 | J9: 15 | K9: 1815 | L9: 579 | M9: 3.552 | N9: 0.545 | O9: 14.6 | P9: 96 | Q9: 70 | R9: 1.5827953
A10: 0.417 | B10: 1.133 | E10: =Q10/P10 -> 0.72916667 | F10: =N10 -> 0.563 | G10: =$C$8*F10*R10 -> 1.0203252 | I10: 9 | J10: 16 | K10: 1825 | L10: 500 | M10: 1.907 | N10: 0.563 | O10: 14.6 | P10: 96 | Q10: 70 | R10: 1.5827953
A11: 0.469 | B11: 1.258 | E11: =Q11/P11 -> 0.72916667 | F11: =N11 -> 0.579 | G11: =$C$8*F11*R11 -> 1.0493221 | I11: 10 | J11: 17 | K11: 1515 | L11: 545 | M11: 3.604 | N11: 0.579 | O11: 14.6 | P11: 96 | Q11: 70 | R11: 1.5827953
A12: 0.495 | B12: 1.305 | E12: =Q12/P12 -> 0.72916667 | F12: =N12 -> 0.664 | G12: =$C$8*F12*R12 -> 1.2033676 | I12: 11 | J12: 18 | K12: 1515 | L12: 482 | M12: 2.48 | N12: 0.664 | O12: 14.6 | P12: 96 | Q12: 70 | R12: 1.5827953
A13: 0.521 | B13: 1.35 | E13: =Q13/P13 -> 0.72916667 | F13: =N13 -> 0.61 | G13: =$C$8*F13*R13 -> 1.1055034 | I13: 12 | J13: 19 | K13: 1545 | L13: 466 | M13: 1.97 | N13: 0.61 | O13: 14.6 | P13: 96 | Q13: 70 | R13: 1.5827953
A14: 0.547 | B14: 1.41 | E14: =Q14/P14 -> 0.72916667 | F14: =N14 -> 0.508 | G14: =$C$8*F14*R14 -> 0.92064871 | I14: 13 | J14: 53 | K14: 1515 | L14: 558 | M14: 3.571 | N14: 0.508 | O14: 16.6 | P14: 96 | Q14: 70 | R14: 1.5827953
A15: 0.573 | B15: 1.467 | E15: =Q15/P15 -> 0.72916667 | F15: =N15 -> 0.605 | G15: =$C$8*F15*R15 -> 1.0964419 | I15: 14 | J15: 54 | K15: 1815 | L15: 560 | M15: 3.612 | N15: 0.605 | O15: 13.6 | P15: 96 | Q15: 70 | R15: 1.5827953
A16: 0.599 | B16: 1.522 | E16: =Q16/P16 -> 0.72916667 | F16: =N16 -> 0.597 | G16: =$C$8*F16*R16 -> 1.0819435 | I16: 15 | J16: 55 | K16: 1795 | L16: 481.5 | M16: 2.029 | N16: 0.597 | O16: 13.6 | P16: 96 | Q16: 70 | R16: 1.5827953
A17: 0.625 | B17: 1.592 | E17: =Q17/P17 -> 0.72916667 | F17: =N17 -> 0.571 | G17: =$C$8*F17*R17 -> 1.0348237 | I17: 16 | J17: 56 | K17: 2115 | L17: 502.5 | M17: 2.021 | N17: 0.571 | O17: 13.6 | P17: 96 | Q17: 70 | R17: 1.5827953
A18: 0.651 | B18: 1.64 | E18: =Q18/P18 -> 0.72916667 | F18: =N18 -> 0.55 | G18: =$C$8*F18*R18 -> 0.99676534 | I18: 17 | J18: 57 | K18: 2115 | L18: 517.5 | M18: 2.035 | N18: 0.55 | O18: 13.6 | P18: 96 | Q18: 70 | R18: 1.5827953
A19: 0.677 | B19: 1.657 | E19: =Q19/P19 -> 0.72916667 | F19: =N19 -> 0.507 | G19: =$C$8*F19*R19 -> 0.91883641 | I19: 18 | J19: 58 | K19: 2115 | L19: 541.5 | M19: 2.026 | N19: 0.507 | O19: 13.6 | P19: 96 | Q19: 70 | R19: 1.5827953
A20: 0.703 | B20: 1.64 | E20: =Q20/P20 -> 0.72916667 | F20: =N20 -> 0.584 | G20: =$C$8*F20*R20 -> 1.0583836 | I20: 19 | J20: 59 | K20: 2115 | L20: 545 | M20: 2.526 | N20: 0.584 | O20: 13.6 | P20: 96 | Q20: 70 | R20: 1.5827953
... A29: 1 | B29: 0.367 | E29: =Q29/P29 -> 0.72916667 | F29: =N29 -> 0.47 | G29: =$C$8*F29*R29 -> 0.85178129 | I29: 28 | J29: 68 | K29: 2415 | L29: 623 | M29: 3.047 | N29: 0.47 | O29: 13.6 | P29: 96 | Q29: 70 | R29: 1.5827953
E30: =Q30/P30 -> 0.72916667 | F30: =N30 -> 0.502 | G30: =$C$8*F30*R30 -> 0.90977491 | I30: 29 | J30: 69 | K30: 2415 | L30: 627 | M30: 3.557 | N30: 0.502 | O30: 13.6 | P30: 96 | Q30: 70 | R30: 1.5827953
A31: 線形補間
A32: X | B32: Y
A33: 0 | B33: 0.358
A34: 0.00010001 | B34: 0.35800192
A35: 0.00020002 | B35: 0.35800385
A36: 0.00030003 | B36: 0.35800577
A37: 0.00040004 | B37: 0.35800769
A38: 0.00050005001 | B38: 0.35800962
A39: 0.00060006001 | B39: 0.35801154
A40: 0.00070007001 | B40: 0.35801346
A41: 0.00080008001 | B41: 0.35801539
A42: 0.00090009001 | B42: 0.35801731
A43: 0.0010001 | B43: 0.35801923
A44: 0.00110011 | B44: 0.35802116
... A10032: 1 | B10032: 0.367

Sheet 単位換算108
Y4: ③Celataの計算に必要な値に変換 | AC4: クオリティの計算 | AK4: 実験値 | AL4: ロッド16本の濡れぶち | AM4: ロッド１６本の全出力 | AN4: ロッドを１本にし、ピークのロッドで考える | AO4: DNB相対位置 | AP4: 総出力をロッド１本、DNB位置までに変換 | AQ4: 検算 これにより、QAVEに半径・軸の相対ピーク値をかけるとCHFになることがわかる
A5: TEST SECTION NUMBER | B5: SRL | C5: PRESSURE (psia) | D5: LENGTH (in.) | E5: MASS VELOCITY × 10⁻⁶ (lb/hr.ft²) | F5: INLET TEMP[F] | G5: BURNOUT HEAT FLUX × 10⁻⁶ (BTU/hr.ft²) | H5: PITCH[in] | I5: ROD OD[in] | K5: 実験番号. | L5: Pin 圧力 (Pa) | M5: L_全長[m] | N5: PITCH[m] | O5: ROD OD[m] | P5: 流路断面積[m2] | Q5: 濡れ縁長さ[m] | R5: 流路断面積[in2] | S5: 濡れ縁長さ[in] | T5: 管の長さ (m) | U5: 質量流速[kg/(m²·s)] | V5: 入口温度[K] | W5: CHF [MW/m²] | Y5: 流路断面積 A[m2] | Z5: 濡れ縁長さ[m] | AA5: 入口温度[K] | AC5: G | AD5: A | AE5: Hlg | AF5: Ts | AG5: Tin | AH5: CPL_Ts | AI5: CPL_Tin | AJ5: CPL_ave | AK5: Q_AVE | AL5: A_htr | AM5: Q_all | AN5: r_ratio | AO5: z_ratio | AP5: Q_DNB | AQ5: q_DNB_nishida | AR5: GAHlg | AS5: xin_nishida | AT5: xout_nishida | AU5: DNB位置の軸方向出力 | AV5: ロッド数 | AW5: DNB位置の半径方向出力 | AX5: Tsub | AY5: Hsub | AZ5: Hsub[kJ/kg]
A6: ='TEST SECTION NUMBER 108'!$C$2 -> 108 | B6: ='TEST SECTION NUMBER 108'!I2 -> 1 | C6: ='TEST SECTION NUMBER 108'!K2 -> 1515 | D6: ='TEST SECTION NUMBER 108'!Q2 -> 70 | E6: ='TEST SECTION NUMBER 108'!M2 -> 2.5 | F6: ='TEST SECTION NUMBER 108'!L2 -> 520 | G6: ='TEST SECTION NUMBER 108'!G2 -> 1.0293868 | H6: ='TEST SECTION NUMBER 108'!$C$4 -> 0.555 | I6: ='TEST SECTION NUMBER 108'!$C$6 -> 0.422 | K6: =B6 -> 1 | L6: =C6*6894.757 -> 10445557 | M6: ='TEST SECTION NUMBER 108'!P2*0.0254 -> 2.4384 | N6: ='TEST SECTION NUMBER 108'!$C$4*0.0254 -> 0.014097 | O6: ='TEST SECTION NUMBER 108'!$C$6*0.0254 -> 0.0107188 | P6: =N6^2-PI()*(O6/2)^2 -> 0.00010848891 | Q6: =O6*PI() -> 0.033674103 | R6: ='TEST SECTION NUMBER 108'!$C$4^2-PI()*(('TEST SECTION NUMBER 108'!$C$6)^2)/4 -> 0.16815815 | S6: =PI()*'TEST SECTION NUMBER 108'!$C$6 -> 1.3257521 | T6: =D6*0.0254 -> 1.778 | U6: =E6*10^6*0.001356 -> 3390 | V6: =(F6 - 32) * 5/9 + 273.15 -> 544.26111 | W6: =G6*3.1546 -> 3.2473034 | Y6: =R6*0.0254^2 -> 0.00010848891 | Z6: =S6*0.0254 -> 0.033674103 | AA6: =V6 -> 544.26111 | AB6: 1 | AC6: =U6 -> 3390 | AD6: =Y6 -> 0.00010848891 | AE6: 1290031.6 | AF6: 587.36714 | AG6: =単位換算108!AA6 -> 544.26111 | AH6: 6257.8914 | AI6: 5041.2861 | AJ6: =(テーブル5[[#This Row],[CPL_Ts]]+テーブル5[[#This Row],[CPL_Tin]])/2 -> 5649.5887 | AK6: ='TEST SECTION NUMBER 108'!N2*3.1546 -> 1.7918128 | AL6: =PI()*O6*16*M6 -> 1.3137749 | AM6: =テーブル5[[#This Row],[Q_AVE]]*テーブル5[[#This Row],[A_htr]] -> 2.3540387 | AN6: =テーブル5[[#This Row],[DNB位置の半径方向出力]]/テーブル5[[#This Row],[ロッド数]] -> 0.0715625 | AO6: ='TEST SECTION NUMBER 108'!E2 -> 0.72916667 | AP6: =テーブル5[[#This Row],[Q_all]]*テーブル5[[#This Row],[z_ratio]]*テーブル5[[#This Row],[r_ratio]]*1000000 -> 122836.07 | AQ6: =テーブル5[[#This Row],[Q_AVE]]*テーブル5[[#This Row],[DNB位置の軸方向出力]]*テーブル5[[#This Row],[DNB位置の半径方向出力]] -> 3.2473034 | AR6: =テーブル5[[#This Row],[G]]*テーブル5[[#This Row],[A]]*テーブル5[[#This Row],[Hlg]] -> 474444.48 | AS6: =-テーブル5[[#This Row],[G]]*テーブル5[[#This Row],[A]]*テーブル5[[#This Row],[CPL_ave]]*(テーブル5[[#This Row],[Ts]]-テーブル5[[#This Row],[Tin]]) -> -89565.327 | AT6: =(テーブル5[[#This Row],[Q_DNB]]+テーブル5[[#This Row],[xin_nishida]])/テーブル5[[#This Row],[GAHlg]] -> 0.070125685 | AU6: 1.5827953 | AV6: 16 | AW6: 1.145 | AX6: =テーブル5[[#This Row],[Ts]]-テーブル5[[#This Row],[Tin]] -> 43.106029 | AY6: 237740.26 | AZ6: =テーブル5[[#This Row],[Hsub]]/1000 -> 237.74026
A7: ='TEST SECTION NUMBER 108'!$C$2 -> 108 | B7: ='TEST SECTION NUMBER 108'!I3 -> 2 | C7: ='TEST SECTION NUMBER 108'!K3 -> 1515 | D7: ='TEST SECTION NUMBER 108'!Q3 -> 70 | E7: ='TEST SECTION NUMBER 108'!M3 -> 2.5 | F7: ='TEST SECTION NUMBER 108'!L3 -> 499 | G7: ='TEST SECTION NUMBER 108'!G3 -> 1.1308756 | H7: ='TEST SECTION NUMBER 108'!$C$4 -> 0.555 | I7: ='TEST SECTION NUMBER 108'!$C$6 -> 0.422 | K7: =B7 -> 2 | L7: =C7*6894.757 -> 10445557 | M7: ='TEST SECTION NUMBER 108'!P3*0.0254 -> 2.4384 | N7: ='TEST SECTION NUMBER 108'!$C$4*0.0254 -> 0.014097 | O7: ='TEST SECTION NUMBER 108'!$C$6*0.0254 -> 0.0107188 | P7: =N7^2-PI()*(O7/2)^2 -> 0.00010848891 | Q7: =O7*PI() -> 0.033674103 | R7: ='TEST SECTION NUMBER 108'!$C$4^2-PI()*(('TEST SECTION NUMBER 108'!$C$6)^2)/4 -> 0.16815815 | S7: =PI()*'TEST SECTION NUMBER 108'!$C$6 -> 1.3257521 | T7: =D7*0.0254 -> 1.778 | U7: =E7*10^6*0.001356 -> 3390 | V7: =(F7 - 32) * 5/9 + 273.15 -> 532.59444 | W7: =G7*3.1546 -> 3.5674601 | Y7: =R7*0.0254^2 -> 0.00010848891 | Z7: =S7*0.0254 -> 0.033674103 | AA7: =V7 -> 532.59444 | AB7: 2 | AC7: =U7 -> 3390 | AD7: =Y7 -> 0.00010848891 | AE7: 1290031.6 | AF7: 587.36714 | AG7: =単位換算108!AA7 -> 532.59444 | AH7: 6257.8914 | AI7: 4888.9923 | AJ7: =(テーブル5[[#This Row],[CPL_Ts]]+テーブル5[[#This Row],[CPL_Tin]])/2 -> 5573.4419 | AK7: ='TEST SECTION NUMBER 108'!N3*3.1546 -> 1.9684704 | AL7: =PI()*O7*16*M7 -> 1.3137749 | AM7: =テーブル5[[#This Row],[Q_AVE]]*テーブル5[[#This Row],[A_htr]] -> 2.5861271 | AN7: =テーブル5[[#This Row],[DNB位置の半径方向出力]]/テーブル5[[#This Row],[ロッド数]] -> 0.0715625 | AO7: ='TEST SECTION NUMBER 108'!E3 -> 0.72916667 | AP7: =テーブル5[[#This Row],[Q_all]]*テーブル5[[#This Row],[z_ratio]]*テーブル5[[#This Row],[r_ratio]]*1000000 -> 134946.67 | AQ7: =テーブル5[[#This Row],[Q_AVE]]*テーブル5[[#This Row],[DNB位置の軸方向出力]]*テーブル5[[#This Row],[DNB位置の半径方向出力]] -> 3.5674601 | AR7: =テーブル5[[#This Row],[G]]*テーブル5[[#This Row],[A]]*テーブル5[[#This Row],[Hlg]] -> 474444.48 | AS7: =-テーブル5[[#This Row],[G]]*テーブル5[[#This Row],[A]]*テーブル5[[#This Row],[CPL_ave]]*(テーブル5[[#This Row],[Ts]]-テーブル5[[#This Row],[Tin]]) -> -112272.31 | AT7: =(テーブル5[[#This Row],[Q_DNB]]+テーブル5[[#This Row],[xin_nishida]])/テーブル5[[#This Row],[GAHlg]] -> 0.047791389 | AU7: 1.5827953 | AV7: 16 | AW7: 1.145 | AX7: =テーブル5[[#This Row],[Ts]]-テーブル5[[#This Row],[Tin]] -> 54.772696 | AY7: 295632.46 | AZ7: =テーブル5[[#This Row],[Hsub]]/1000 -> 295.63246
A8: ='TEST SECTION NUMBER 108'!$C$2 -> 108 | B8: ='TEST SECTION NUMBER 108'!I4 -> 3 | C8: ='TEST SECTION NUMBER 108'!K4 -> 2165 | D8: ='TEST SECTION NUMBER 108'!Q4 -> 70 | E8: ='TEST SECTION NUMBER 108'!M4 -> 2.587 | F8: ='TEST SECTION NUMBER 108'!L4 -> 584 | G8: ='TEST SECTION NUMBER 108'!G4 -> 0.92427331 | H8: ='TEST SECTION NUMBER 108'!$C$4 -> 0.555 | I8: ='TEST SECTION NUMBER 108'!$C$6 -> 0.422 | K8: =B8 -> 3 | L8: =C8*6894.757 -> 14927149 | M8: ='TEST SECTION NUMBER 108'!P4*0.0254 -> 2.4384 | N8: ='TEST SECTION NUMBER 108'!$C$4*0.0254 -> 0.014097 | O8: ='TEST SECTION NUMBER 108'!$C$6*0.0254 -> 0.0107188 | P8: =N8^2-PI()*(O8/2)^2 -> 0.00010848891 | Q8: =O8*PI() -> 0.033674103 | R8: ='TEST SECTION NUMBER 108'!$C$4^2-PI()*(('TEST SECTION NUMBER 108'!$C$6)^2)/4 -> 0.16815815 | S8: =PI()*'TEST SECTION NUMBER 108'!$C$6 -> 1.3257521 | T8: =D8*0.0254 -> 1.778 | U8: =E8*10^6*0.001356 -> 3507.972 | V8: =(F8 - 32) * 5/9 + 273.15 -> 579.81667 | W8: =G8*3.1546 -> 2.9157126 | Y8: =R8*0.0254^2 -> 0.00010848891 | Z8: =S8*0.0254 -> 0.033674103 | AA8: =V8 -> 579.81667 | AB8: 3 | AC8: =U8 -> 3507.972 | AD8: =Y8 -> 0.00010848891 | AE8: 1005423.1 | AF8: 614.91567 | AG8: =単位換算108!AA8 -> 579.81667 | AH8: 8454.8821 | AI8: 5662.3774 | AJ8: =(テーブル5[[#This Row],[CPL_Ts]]+テーブル5[[#This Row],[CPL_Tin]])/2 -> 7058.6297 | AK8: ='TEST SECTION NUMBER 108'!N4*3.1546 -> 1.608846 | AL8: =PI()*O8*16*M8 -> 1.3137749 | AM8: =テーブル5[[#This Row],[Q_AVE]]*テーブル5[[#This Row],[A_htr]] -> 2.1136616 | AN8: =テーブル5[[#This Row],[DNB位置の半径方向出力]]/テーブル5[[#This Row],[ロッド数]] -> 0.0715625 | AO8: ='TEST SECTION NUMBER 108'!E4 -> 0.72916667 | AP8: =テーブル5[[#This Row],[Q_all]]*テーブル5[[#This Row],[z_ratio]]*テーブル5[[#This Row],[r_ratio]]*1000000 -> 110292.95 | AQ8: =テーブル5[[#This Row],[Q_AVE]]*テーブル5[[#This Row],[DNB位置の軸方向出力]]*テーブル5[[#This Row],[DNB位置の半径方向出力]] -> 2.9157126 | AR8: =テーブル5[[#This Row],[G]]*テーブル5[[#This Row],[A]]*テーブル5[[#This Row],[Hlg]] -> 382639.99 | AS8: =-テーブル5[[#This Row],[G]]*テーブル5[[#This Row],[A]]*テーブル5[[#This Row],[CPL_ave]]*(テーブル5[[#This Row],[Ts]]-テーブル5[[#This Row],[Tin]]) -> -94288.042 | AT8: =(テーブル5[[#This Row],[Q_DNB]]+テーブル5[[#This Row],[xin_nishida]])/テーブル5[[#This Row],[GAHlg]] -> 0.041827592 | AU8: 1.5827953 | AV8: 16 | AW8: 1.145 | AX8: =テーブル5[[#This Row],[Ts]]-テーブル5[[#This Row],[Tin]] -> 35.098999 | AY8: 231852.78 | AZ8: =テーブル5[[#This Row],[Hsub]]/1000 -> 231.85278
A9: ='TEST SECTION NUMBER 108'!$C$2 -> 108 | B9: ='TEST SECTION NUMBER 108'!I5 -> 4 | C9: ='TEST SECTION NUMBER 108'!K5 -> 2115 | D9: ='TEST SECTION NUMBER 108'!Q5 -> 70 | E9: ='TEST SECTION NUMBER 108'!M5 -> 2.54 | F9: ='TEST SECTION NUMBER 108'!L5 -> 567 | G9: ='TEST SECTION NUMBER 108'!G5 -> 1.0094514 | H9: ='TEST SECTION NUMBER 108'!$C$4 -> 0.555 | I9: ='TEST SECTION NUMBER 108'!$C$6 -> 0.422 | K9: =B9 -> 4 | L9: =C9*6894.757 -> 14582411 | M9: ='TEST SECTION NUMBER 108'!P5*0.0254 -> 2.4384 | N9: ='TEST SECTION NUMBER 108'!$C$4*0.0254 -> 0.014097 | O9: ='TEST SECTION NUMBER 108'!$C$6*0.0254 -> 0.0107188 | P9: =N9^2-PI()*(O9/2)^2 -> 0.00010848891 | Q9: =O9*PI() -> 0.033674103 | R9: ='TEST SECTION NUMBER 108'!$C$4^2-PI()*(('TEST SECTION NUMBER 108'!$C$6)^2)/4 -> 0.16815815 | S9: =PI()*'TEST SECTION NUMBER 108'!$C$6 -> 1.3257521 | T9: =D9*0.0254 -> 1.778 | U9: =E9*10^6*0.001356 -> 3444.24 | V9: =(F9 - 32) * 5/9 + 273.15 -> 570.37222 | W9: =G9*3.1546 -> 3.1844155 | Y9: =R9*0.0254^2 -> 0.00010848891 | Z9: =S9*0.0254 -> 0.033674103 | AA9: =V9 -> 570.37222 | AB9: 4 | AC9: =U9 -> 3444.24 | AD9: =Y9 -> 0.00010848891 | AE9: 1028533.1 | AF9: 613.05027 | AG9: =単位換算108!AA9 -> 570.37222 | AH9: 8194.7812 | AI9: 5422.7482 | AJ9: =(テーブル5[[#This Row],[CPL_Ts]]+テーブル5[[#This Row],[CPL_Tin]])/2 -> 6808.7647 | AK9: ='TEST SECTION NUMBER 108'!N5*3.1546 -> 1.7571122 | AL9: =PI()*O9*16*M9 -> 1.3137749 | AM9: =テーブル5[[#This Row],[Q_AVE]]*テーブル5[[#This Row],[A_htr]] -> 2.30845 | AN9: =テーブル5[[#This Row],[DNB位置の半径方向出力]]/テーブル5[[#This Row],[ロッド数]] -> 0.0715625 | AO9: ='TEST SECTION NUMBER 108'!E5 -> 0.72916667 | AP9: =テーブル5[[#This Row],[Q_all]]*テーブル5[[#This Row],[z_ratio]]*テーブル5[[#This Row],[r_ratio]]*1000000 -> 120457.2 | AQ9: =テーブル5[[#This Row],[Q_AVE]]*テーブル5[[#This Row],[DNB位置の軸方向出力]]*テーブル5[[#This Row],[DNB位置の半径方向出力]] -> 3.1844155 | AR9: =テーブル5[[#This Row],[G]]*テーブル5[[#This Row],[A]]*テーブル5[[#This Row],[Hlg]] -> 384323.58 | AS9: =-テーブル5[[#This Row],[G]]*テーブル5[[#This Row],[A]]*テーブル5[[#This Row],[CPL_ave]]*(テーブル5[[#This Row],[Ts]]-テーブル5[[#This Row],[Tin]]) -> -108580.45 | AT9: =(テーブル5[[#This Row],[Q_DNB]]+テーブル5[[#This Row],[xin_nishida]])/テーブル5[[#This Row],[GAHlg]] -> 0.030903006 | AU9: 1.5827953 | AV9: 16 | AW9: 1.145 | AX9: =テーブル5[[#This Row],[Ts]]-テーブル5[[#This Row],[Tin]] -> 42.678048 | AY9: 270287.72 | AZ9: =テーブル5[[#This Row],[Hsub]]/1000 -> 270.28772
A10: ='TEST SECTION NUMBER 108'!$C$2 -> 108 | B10: ='TEST SECTION NUMBER 108'!I6 -> 5 | C10: ='TEST SECTION NUMBER 108'!K6 -> 2415 | D10: ='TEST SECTION NUMBER 108'!Q6 -> 70 | E10: ='TEST SECTION NUMBER 108'!M6 -> 2.535 | F10: ='TEST SECTION NUMBER 108'!L6 -> 577 | G10: ='TEST SECTION NUMBER 108'!G6 -> 0.99676534 | H10: ='TEST SECTION NUMBER 108'!$C$4 -> 0.555 | I10: ='TEST SECTION NUMBER 108'!$C$6 -> 0.422 | K10: =B10 -> 5 | L10: =C10*6894.757 -> 16650838 | M10: ='TEST SECTION NUMBER 108'!P6*0.0254 -> 2.4384 | N10: ='TEST SECTION NUMBER 108'!$C$4*0.0254 -> 0.014097 | O10: ='TEST SECTION NUMBER 108'!$C$6*0.0254 -> 0.0107188 | P10: =N10^2-PI()*(O10/2)^2 -> 0.00010848891 | Q10: =O10*PI() -> 0.033674103 | R10: ='TEST SECTION NUMBER 108'!$C$4^2-PI()*(('TEST SECTION NUMBER 108'!$C$6)^2)/4 -> 0.16815815 | S10: =PI()*'TEST SECTION NUMBER 108'!$C$6 -> 1.3257521 | T10: =D10*0.0254 -> 1.778 | U10: =E10*10^6*0.001356 -> 3437.46 | V10: =(F10 - 32) * 5/9 + 273.15 -> 575.92778 | W10: =G10*3.1546 -> 3.1443959 | Y10: =R10*0.0254^2 -> 0.00010848891 | Z10: =S10*0.0254 -> 0.033674103 | AA10: =V10 -> 575.92778 | AB10: 5 | AC10: =U10 -> 3437.46 | AD10: =Y10 -> 0.00010848891 | AE10: 883760.41 | AF10: 623.74675 | AG10: =単位換算108!AA10 -> 575.92778 | AH10: 10285.201 | AI10: 5485.3414 | AJ10: =(テーブル5[[#This Row],[CPL_Ts]]+テーブル5[[#This Row],[CPL_Tin]])/2 -> 7885.2713 | AK10: ='TEST SECTION NUMBER 108'!N6*3.1546 -> 1.73503 | AL10: =PI()*O10*16*M10 -> 1.3137749 | AM10: =テーブル5[[#This Row],[Q_AVE]]*テーブル5[[#This Row],[A_htr]] -> 2.2794389 | AN10: =テーブル5[[#This Row],[DNB位置の半径方向出力]]/テーブル5[[#This Row],[ロッド数]] -> 0.0715625 | AO10: ='TEST SECTION NUMBER 108'!E6 -> 0.72916667 | AP10: =テーブル5[[#This Row],[Q_all]]*テーブル5[[#This Row],[z_ratio]]*テーブル5[[#This Row],[r_ratio]]*1000000 -> 118943.38 | AQ10: =テーブル5[[#This Row],[Q_AVE]]*テーブル5[[#This Row],[DNB位置の軸方向出力]]*テーブル5[[#This Row],[DNB位置の半径方向出力]] -> 3.1443959 | AR10: =テーブル5[[#This Row],[G]]*テーブル5[[#This Row],[A]]*テーブル5[[#This Row],[Hlg]] -> 329577.5 | AS10: =-テーブル5[[#This Row],[G]]*テーブル5[[#This Row],[A]]*テーブル5[[#This Row],[CPL_ave]]*(テーブル5[[#This Row],[Ts]]-テーブル5[[#This Row],[Tin]]) -> -140617.66 | AT10: =(テーブル5[[#This Row],[Q_DNB]]+テーブル5[[#This Row],[xin_nishida]])/テーブル5[[#This Row],[GAHlg]] -> -0.065763841 | AU10: 1.5827953 | AV10: 16 | AW10: 1.145 | AX10: =テーブル5[[#This Row],[Ts]]-テーブル5[[#This Row],[Tin]] -> 47.81897 | AY10: 323748.75 | AZ10: =テーブル5[[#This Row],[Hsub]]/1000 -> 323.74875
A11: ='TEST SECTION NUMBER 108'!$C$2 -> 108 | B11: ='TEST SECTION NUMBER 108'!I7 -> 6 | C11: ='TEST SECTION NUMBER 108'!K7 -> 2415 | D11: ='TEST SECTION NUMBER 108'!Q7 -> 70 | E11: ='TEST SECTION NUMBER 108'!M7 -> 2.064 | F11: ='TEST SECTION NUMBER 108'!L7 -> 559 | G11: ='TEST SECTION NUMBER 108'!G7 -> 0.93695942 | H11: ='TEST SECTION NUMBER 108'!$C$4 -> 0.555 | I11: ='TEST SECTION NUMBER 108'!$C$6 -> 0.422 | K11: =B11 -> 6 | L11: =C11*6894.757 -> 16650838 | M11: ='TEST SECTION NUMBER 108'!P7*0.0254 -> 2.4384 | N11: ='TEST SECTION NUMBER 108'!$C$4*0.0254 -> 0.014097 | O11: ='TEST SECTION NUMBER 108'!$C$6*0.0254 -> 0.0107188 | P11: =N11^2-PI()*(O11/2)^2 -> 0.00010848891 | Q11: =O11*PI() -> 0.033674103 | R11: ='TEST SECTION NUMBER 108'!$C$4^2-PI()*(('TEST SECTION NUMBER 108'!$C$6)^2)/4 -> 0.16815815 | S11: =PI()*'TEST SECTION NUMBER 108'!$C$6 -> 1.3257521 | T11: =D11*0.0254 -> 1.778 | U11: =E11*10^6*0.001356 -> 2798.784 | V11: =(F11 - 32) * 5/9 + 273.15 -> 565.92778 | W11: =G11*3.1546 -> 2.9557322 | Y11: =R11*0.0254^2 -> 0.00010848891 | Z11: =S11*0.0254 -> 0.033674103 | AA11: =V11 -> 565.92778 | AB11: 6 | AC11: =U11 -> 2798.784 | AD11: =Y11 -> 0.00010848891 | AE11: 883760.41 | AF11: 623.74675 | AG11: =単位換算108!AA11 -> 565.92778 | AH11: 10285.201 | AI11: 5266.8111 | AJ11: =(テーブル5[[#This Row],[CPL_Ts]]+テーブル5[[#This Row],[CPL_Tin]])/2 -> 7776.0062 | AK11: ='TEST SECTION NUMBER 108'!N7*3.1546 -> 1.6309282 | AL11: =PI()*O11*16*M11 -> 1.3137749 | AM11: =テーブル5[[#This Row],[Q_AVE]]*テーブル5[[#This Row],[A_htr]] -> 2.1426726 | AN11: =テーブル5[[#This Row],[DNB位置の半径方向出力]]/テーブル5[[#This Row],[ロッド数]] -> 0.0715625 | AO11: ='TEST SECTION NUMBER 108'!E7 -> 0.72916667 | AP11: =テーブル5[[#This Row],[Q_all]]*テーブル5[[#This Row],[z_ratio]]*テーブル5[[#This Row],[r_ratio]]*1000000 -> 111806.78 | AQ11: =テーブル5[[#This Row],[Q_AVE]]*テーブル5[[#This Row],[DNB位置の軸方向出力]]*テーブル5[[#This Row],[DNB位置の半径方向出力]] -> 2.9557322 | AR11: =テーブル5[[#This Row],[G]]*テーブル5[[#This Row],[A]]*テーブル5[[#This Row],[Hlg]] -> 268342.39 | AS11: =-テーブル5[[#This Row],[G]]*テーブル5[[#This Row],[A]]*テーブル5[[#This Row],[CPL_ave]]*(テーブル5[[#This Row],[Ts]]-テーブル5[[#This Row],[Tin]]) -> -136515.41 | AT11: =(テーブル5[[#This Row],[Q_DNB]]+テーブル5[[#This Row],[xin_nishida]])/テーブル5[[#This Row],[GAHlg]] -> -0.092078771 | AU11: 1.5827953 | AV11: 16 | AW11: 1.145 | AX11: =テーブル5[[#This Row],[Ts]]-テーブル5[[#This Row],[Tin]] -> 57.81897 | AY11: 377462.38 | AZ11: =テーブル5[[#This Row],[Hsub]]/1000 -> 377.46238
A12: ='TEST SECTION NUMBER 108'!$C$2 -> 108 | B12: ='TEST SECTION NUMBER 108'!I8 -> 7 | C12: ='TEST SECTION NUMBER 108'!K8 -> 1515 | D12: ='TEST SECTION NUMBER 108'!Q8 -> 70 | E12: ='TEST SECTION NUMBER 108'!M8 -> 3.429 | F12: ='TEST SECTION NUMBER 108'!L8 -> 560 | G12: ='TEST SECTION NUMBER 108'!G8 -> 0.92789792 | H12: ='TEST SECTION NUMBER 108'!$C$4 -> 0.555 | I12: ='TEST SECTION NUMBER 108'!$C$6 -> 0.422 | K12: =B12 -> 7 | L12: =C12*6894.757 -> 10445557 | M12: ='TEST SECTION NUMBER 108'!P8*0.0254 -> 2.4384 | N12: ='TEST SECTION NUMBER 108'!$C$4*0.0254 -> 0.014097 | O12: ='TEST SECTION NUMBER 108'!$C$6*0.0254 -> 0.0107188 | P12: =N12^2-PI()*(O12/2)^2 -> 0.00010848891 | Q12: =O12*PI() -> 0.033674103 | R12: ='TEST SECTION NUMBER 108'!$C$4^2-PI()*(('TEST SECTION NUMBER 108'!$C$6)^2)/4 -> 0.16815815 | S12: =PI()*'TEST SECTION NUMBER 108'!$C$6 -> 1.3257521 | T12: =D12*0.0254 -> 1.778 | U12: =E12*10^6*0.001356 -> 4649.724 | V12: =(F12 - 32) * 5/9 + 273.15 -> 566.48333 | W12: =G12*3.1546 -> 2.9271468 | Y12: =R12*0.0254^2 -> 0.00010848891 | Z12: =S12*0.0254 -> 0.033674103 | AA12: =V12 -> 566.48333 | AB12: 7 | AC12: =U12 -> 4649.724 | AD12: =Y12 -> 0.00010848891 | AE12: 1290031.6 | AF12: 587.36714 | AG12: =単位換算108!AA12 -> 566.48333 | AH12: 6257.8914 | AI12: 5470.51 | AJ12: =(テーブル5[[#This Row],[CPL_Ts]]+テーブル5[[#This Row],[CPL_Tin]])/2 -> 5864.2007 | AK12: ='TEST SECTION NUMBER 108'!N8*3.1546 -> 1.6151552 | AL12: =PI()*O12*16*M12 -> 1.3137749 | AM12: =テーブル5[[#This Row],[Q_AVE]]*テーブル5[[#This Row],[A_htr]] -> 2.1219504 | AN12: =テーブル5[[#This Row],[DNB位置の半径方向出力]]/テーブル5[[#This Row],[ロッド数]] -> 0.0715625 | AO12: ='TEST SECTION NUMBER 108'!E8 -> 0.72916667 | AP12: =テーブル5[[#This Row],[Q_all]]*テーブル5[[#This Row],[z_ratio]]*テーブル5[[#This Row],[r_ratio]]*1000000 -> 110725.47 | AQ12: =テーブル5[[#This Row],[Q_AVE]]*テーブル5[[#This Row],[DNB位置の軸方向出力]]*テーブル5[[#This Row],[DNB位置の半径方向出力]] -> 2.9271468 | AR12: =テーブル5[[#This Row],[G]]*テーブル5[[#This Row],[A]]*テーブル5[[#This Row],[Hlg]] -> 650748.05 | AS12: =-テーブル5[[#This Row],[G]]*テーブル5[[#This Row],[A]]*テーブル5[[#This Row],[CPL_ave]]*(テーブル5[[#This Row],[Ts]]-テーブル5[[#This Row],[Tin]]) -> -61777.601 | AT12: =(テーブル5[[#This Row],[Q_DNB]]+テーブル5[[#This Row],[xin_nishida]])/テーブル5[[#This Row],[GAHlg]] -> 0.075217854 | AU12: 1.5827953 | AV12: 16 | AW12: 1.145 | AX12: =テーブル5[[#This Row],[Ts]]-テーブル5[[#This Row],[Tin]] -> 20.883807 | AY12: 121382.95 | AZ12: =テーブル5[[#This Row],[Hsub]]/1000 -> 121.38295
A13: ='TEST SECTION NUMBER 108'!$C$2 -> 108 | B13: ='TEST SECTION NUMBER 108'!I9 -> 8 | C13: ='TEST SECTION NUMBER 108'!K9 -> 1815 | D13: ='TEST SECTION NUMBER 108'!Q9 -> 70 | E13: ='TEST SECTION NUMBER 108'!M9 -> 3.552 | F13: ='TEST SECTION NUMBER 108'!L9 -> 579 | G13: ='TEST SECTION NUMBER 108'!G9 -> 0.98770384 | H13: ='TEST SECTION NUMBER 108'!$C$4 -> 0.555 | I13: ='TEST SECTION NUMBER 108'!$C$6 -> 0.422 | K13: =B13 -> 8 | L13: =C13*6894.757 -> 12513984 | M13: ='TEST SECTION NUMBER 108'!P9*0.0254 -> 2.4384 | N13: ='TEST SECTION NUMBER 108'!$C$4*0.0254 -> 0.014097 | O13: ='TEST SECTION NUMBER 108'!$C$6*0.0254 -> 0.0107188 | P13: =N13^2-PI()*(O13/2)^2 -> 0.00010848891 | Q13: =O13*PI() -> 0.033674103 | R13: ='TEST SECTION NUMBER 108'!$C$4^2-PI()*(('TEST SECTION NUMBER 108'!$C$6)^2)/4 -> 0.16815815 | S13: =PI()*'TEST SECTION NUMBER 108'!$C$6 -> 1.3257521 | T13: =D13*0.0254 -> 1.778 | U13: =E13*10^6*0.001356 -> 4816.512 | V13: =(F13 - 32) * 5/9 + 273.15 -> 577.03889 | W13: =G13*3.1546 -> 3.1158105 | Y13: =R13*0.0254^2 -> 0.00010848891 | Z13: =S13*0.0254 -> 0.033674103 | AA13: =V13 -> 577.03889 | AB13: 8 | AC13: =U13 -> 4816.512 | AD13: =Y13 -> 0.00010848891 | AE13: 1161846.5 | AF13: 601.04947 | AG13: =単位換算108!AA13 -> 577.03889 | AH13: 7027.4336 | AI13: 5687.325 | AJ13: =(テーブル5[[#This Row],[CPL_Ts]]+テーブル5[[#This Row],[CPL_Tin]])/2 -> 6357.3793 | AK13: ='TEST SECTION NUMBER 108'!N9*3.1546 -> 1.719257 | AL13: =PI()*O13*16*M13 -> 1.3137749 | AM13: =テーブル5[[#This Row],[Q_AVE]]*テーブル5[[#This Row],[A_htr]] -> 2.2587168 | AN13: =テーブル5[[#This Row],[DNB位置の半径方向出力]]/テーブル5[[#This Row],[ロッド数]] -> 0.0715625 | AO13: ='TEST SECTION NUMBER 108'!E9 -> 0.72916667 | AP13: =テーブル5[[#This Row],[Q_all]]*テーブル5[[#This Row],[z_ratio]]*テーブル5[[#This Row],[r_ratio]]*1000000 -> 117862.08 | AQ13: =テーブル5[[#This Row],[Q_AVE]]*テーブル5[[#This Row],[DNB位置の軸方向出力]]*テーブル5[[#This Row],[DNB位置の半径方向出力]] -> 3.1158105 | AR13: =テーブル5[[#This Row],[G]]*テーブル5[[#This Row],[A]]*テーブル5[[#This Row],[Hlg]] -> 607109.15 | AS13: =-テーブル5[[#This Row],[G]]*テーブル5[[#This Row],[A]]*テーブル5[[#This Row],[CPL_ave]]*(テーブル5[[#This Row],[Ts]]-テーブル5[[#This Row],[Tin]]) -> -79762.499 | AT13: =(テーブル5[[#This Row],[Q_DNB]]+テーブル5[[#This Row],[xin_nishida]])/テーブル5[[#This Row],[GAHlg]] -> 0.062755727 | AU13: 1.5827953 | AV13: 16 | AW13: 1.145 | AX13: =テーブル5[[#This Row],[Ts]]-テーブル5[[#This Row],[Tin]] -> 24.010578 | AY13: 149605.79 | AZ13: =テーブル5[[#This Row],[Hsub]]/1000 -> 149.60579
A14: ='TEST SECTION NUMBER 108'!$C$2 -> 108 | B14: ='TEST SECTION NUMBER 108'!I10 -> 9 | C14: ='TEST SECTION NUMBER 108'!K10 -> 1825 | D14: ='TEST SECTION NUMBER 108'!Q10 -> 70 | E14: ='TEST SECTION NUMBER 108'!M10 -> 1.907 | F14: ='TEST SECTION NUMBER 108'!L10 -> 500 | G14: ='TEST SECTION NUMBER 108'!G10 -> 1.0203252 | H14: ='TEST SECTION NUMBER 108'!$C$4 -> 0.555 | I14: ='TEST SECTION NUMBER 108'!$C$6 -> 0.422 | K14: =B14 -> 9 | L14: =C14*6894.757 -> 12582932 | M14: ='TEST SECTION NUMBER 108'!P10*0.0254 -> 2.4384 | N14: ='TEST SECTION NUMBER 108'!$C$4*0.0254 -> 0.014097 | O14: ='TEST SECTION NUMBER 108'!$C$6*0.0254 -> 0.0107188 | P14: =N14^2-PI()*(O14/2)^2 -> 0.00010848891 | Q14: =O14*PI() -> 0.033674103 | R14: ='TEST SECTION NUMBER 108'!$C$4^2-PI()*(('TEST SECTION NUMBER 108'!$C$6)^2)/4 -> 0.16815815 | S14: =PI()*'TEST SECTION NUMBER 108'!$C$6 -> 1.3257521 | T14: =D14*0.0254 -> 1.778 | U14: =E14*10^6*0.001356 -> 2585.892 | V14: =(F14 - 32) * 5/9 + 273.15 -> 533.15 | W14: =G14*3.1546 -> 3.218718 | Y14: =R14*0.0254^2 -> 0.00010848891 | Z14: =S14*0.0254 -> 0.033674103 | AA14: =V14 -> 533.15 | AB14: 9 | AC14: =U14 -> 2585.892 | AD14: =Y14 -> 0.00010848891 | AE14: 1157513.2 | AF14: 601.47401 | AG14: =単位換算108!AA14 -> 533.15 | AH14: 7058.4029 | AI14: 4865.5331 | AJ14: =(テーブル5[[#This Row],[CPL_Ts]]+テーブル5[[#This Row],[CPL_Tin]])/2 -> 5961.968 | AK14: ='TEST SECTION NUMBER 108'!N10*3.1546 -> 1.7760398 | AL14: =PI()*O14*16*M14 -> 1.3137749 | AM14: =テーブル5[[#This Row],[Q_AVE]]*テーブル5[[#This Row],[A_htr]] -> 2.3333166 | AN14: =テーブル5[[#This Row],[DNB位置の半径方向出力]]/テーブル5[[#This Row],[ロッド数]] -> 0.0715625 | AO14: ='TEST SECTION NUMBER 108'!E10 -> 0.72916667 | AP14: =テーブル5[[#This Row],[Q_all]]*テーブル5[[#This Row],[z_ratio]]*テーブル5[[#This Row],[r_ratio]]*1000000 -> 121754.77 | AQ14: =テーブル5[[#This Row],[Q_AVE]]*テーブル5[[#This Row],[DNB位置の軸方向出力]]*テーブル5[[#This Row],[DNB位置の半径方向出力]] -> 3.218718 | AR14: =テーブル5[[#This Row],[G]]*テーブル5[[#This Row],[A]]*テーブル5[[#This Row],[Hlg]] -> 324729.46 | AS14: =-テーブル5[[#This Row],[G]]*テーブル5[[#This Row],[A]]*テーブル5[[#This Row],[CPL_ave]]*(テーブル5[[#This Row],[Ts]]-テーブル5[[#This Row],[Tin]]) -> -114276.98 | AT14: =(テーブル5[[#This Row],[Q_DNB]]+テーブル5[[#This Row],[xin_nishida]])/テーブル5[[#This Row],[GAHlg]] -> 0.02302775 | AU14: 1.5827953 | AV14: 16 | AW14: 1.145 | AX14: =テーブル5[[#This Row],[Ts]]-テーブル5[[#This Row],[Tin]] -> 68.324013 | AY14: 380825.21 | AZ14: =テーブル5[[#This Row],[Hsub]]/1000 -> 380.82521
A15: ='TEST SECTION NUMBER 108'!$C$2 -> 108 | B15: ='TEST SECTION NUMBER 108'!I11 -> 10 | C15: ='TEST SECTION NUMBER 108'!K11 -> 1515 | D15: ='TEST SECTION NUMBER 108'!Q11 -> 70 | E15: ='TEST SECTION NUMBER 108'!M11 -> 3.604 | F15: ='TEST SECTION NUMBER 108'!L11 -> 545 | G15: ='TEST SECTION NUMBER 108'!G11 -> 1.0493221 | H15: ='TEST SECTION NUMBER 108'!$C$4 -> 0.555 | I15: ='TEST SECTION NUMBER 108'!$C$6 -> 0.422 | K15: =B15 -> 10 | L15: =C15*6894.757 -> 10445557 | M15: ='TEST SECTION NUMBER 108'!P11*0.0254 -> 2.4384 | N15: ='TEST SECTION NUMBER 108'!$C$4*0.0254 -> 0.014097 | O15: ='TEST SECTION NUMBER 108'!$C$6*0.0254 -> 0.0107188 | P15: =N15^2-PI()*(O15/2)^2 -> 0.00010848891 | Q15: =O15*PI() -> 0.033674103 | R15: ='TEST SECTION NUMBER 108'!$C$4^2-PI()*(('TEST SECTION NUMBER 108'!$C$6)^2)/4 -> 0.16815815 | S15: =PI()*'TEST SECTION NUMBER 108'!$C$6 -> 1.3257521 | T15: =D15*0.0254 -> 1.778 | U15: =E15*10^6*0.001356 -> 4887.024 | V15: =(F15 - 32) * 5/9 + 273.15 -> 558.15 | W15: =G15*3.1546 -> 3.3101914 | Y15: =R15*0.0254^2 -> 0.00010848891 | Z15: =S15*0.0254 -> 0.033674103 | AA15: =V15 -> 558.15 | AB15: 10 | AC15: =U15 -> 4887.024 | AD15: =Y15 -> 0.00010848891 | AE15: 1290031.6 | AF15: 587.36714 | AG15: =単位換算108!AA15 -> 558.15 | AH15: 6257.8914 | AI15: 5280.7462 | AJ15: =(テーブル5[[#This Row],[CPL_Ts]]+テーブル5[[#This Row],[CPL_Tin]])/2 -> 5769.3188 | AK15: ='TEST SECTION NUMBER 108'!N11*3.1546 -> 1.8265134 | AL15: =PI()*O15*16*M15 -> 1.3137749 | AM15: =テーブル5[[#This Row],[Q_AVE]]*テーブル5[[#This Row],[A_htr]] -> 2.3996275 | AN15: =テーブル5[[#This Row],[DNB位置の半径方向出力]]/テーブル5[[#This Row],[ロッド数]] -> 0.0715625 | AO15: ='TEST SECTION NUMBER 108'!E11 -> 0.72916667 | AP15: =テーブル5[[#This Row],[Q_all]]*テーブル5[[#This Row],[z_ratio]]*テーブル5[[#This Row],[r_ratio]]*1000000 -> 125214.94 | AQ15: =テーブル5[[#This Row],[Q_AVE]]*テーブル5[[#This Row],[DNB位置の軸方向出力]]*テーブル5[[#This Row],[DNB位置の半径方向出力]] -> 3.3101914 | AR15: =テーブル5[[#This Row],[G]]*テーブル5[[#This Row],[A]]*テーブル5[[#This Row],[Hlg]] -> 683959.17 | AS15: =-テーブル5[[#This Row],[G]]*テーブル5[[#This Row],[A]]*テーブル5[[#This Row],[CPL_ave]]*(テーブル5[[#This Row],[Ts]]-テーブル5[[#This Row],[Tin]]) -> -89370.066 | AT15: =(テーブル5[[#This Row],[Q_DNB]]+テーブル5[[#This Row],[xin_nishida]])/テーブル5[[#This Row],[GAHlg]] -> 0.052407913 | AU15: 1.5827953 | AV15: 16 | AW15: 1.145 | AX15: =テーブル5[[#This Row],[Ts]]-テーブル5[[#This Row],[Tin]] -> 29.217141 | AY15: 166149.45 | AZ15: =テーブル5[[#This Row],[Hsub]]/1000 -> 166.14945
A16: ='TEST SECTION NUMBER 108'!$C$2 -> 108 | B16: ='TEST SECTION NUMBER 108'!I12 -> 11 | C16: ='TEST SECTION NUMBER 108'!K12 -> 1515 | D16: ='TEST SECTION NUMBER 108'!Q12 -> 70 | E16: ='TEST SECTION NUMBER 108'!M12 -> 2.48 | F16: ='TEST SECTION NUMBER 108'!L12 -> 482 | G16: ='TEST SECTION NUMBER 108'!G12 -> 1.2033676 | H16: ='TEST SECTION NUMBER 108'!$C$4 -> 0.555 | I16: ='TEST SECTION NUMBER 108'!$C$6 -> 0.422 | K16: =B16 -> 11 | L16: =C16*6894.757 -> 10445557 | M16: ='TEST SECTION NUMBER 108'!P12*0.0254 -> 2.4384 | N16: ='TEST SECTION NUMBER 108'!$C$4*0.0254 -> 0.014097 | O16: ='TEST SECTION NUMBER 108'!$C$6*0.0254 -> 0.0107188 | P16: =N16^2-PI()*(O16/2)^2 -> 0.00010848891 | Q16: =O16*PI() -> 0.033674103 | R16: ='TEST SECTION NUMBER 108'!$C$4^2-PI()*(('TEST SECTION NUMBER 108'!$C$6)^2)/4 -> 0.16815815 | S16: =PI()*'TEST SECTION NUMBER 108'!$C$6 -> 1.3257521 | T16: =D16*0.0254 -> 1.778 | U16: =E16*10^6*0.001356 -> 3362.88 | V16: =(F16 - 32) * 5/9 + 273.15 -> 523.15 | W16: =G16*3.1546 -> 3.7961435 | Y16: =R16*0.0254^2 -> 0.00010848891 | Z16: =S16*0.0254 -> 0.033674103 | AA16: =V16 -> 523.15 | AB16: 11 | AC16: =U16 -> 3362.88 | AD16: =Y16 -> 0.00010848891 | AE16: 1290031.6 | AF16: 587.36714 | AG16: =単位換算108!AA16 -> 523.15 | AH16: 6257.8914 | AI16: 4788.1266 | AJ16: =(テーブル5[[#This Row],[CPL_Ts]]+テーブル5[[#This Row],[CPL_Tin]])/2 -> 5523.009 | AK16: ='TEST SECTION NUMBER 108'!N12*3.1546 -> 2.0946544 | AL16: =PI()*O16*16*M16 -> 1.3137749 | AM16: =テーブル5[[#This Row],[Q_AVE]]*テーブル5[[#This Row],[A_htr]] -> 2.7519045 | AN16: =テーブル5[[#This Row],[DNB位置の半径方向出力]]/テーブル5[[#This Row],[ロッド数]] -> 0.0715625 | AO16: ='TEST SECTION NUMBER 108'!E12 -> 0.72916667 | AP16: =テーブル5[[#This Row],[Q_all]]*テーブル5[[#This Row],[z_ratio]]*テーブル5[[#This Row],[r_ratio]]*1000000 -> 143597.1 | AQ16: =テーブル5[[#This Row],[Q_AVE]]*テーブル5[[#This Row],[DNB位置の軸方向出力]]*テーブル5[[#This Row],[DNB位置の半径方向出力]] -> 3.7961435 | AR16: =テーブル5[[#This Row],[G]]*テーブル5[[#This Row],[A]]*テーブル5[[#This Row],[Hlg]] -> 470648.93 | AS16: =-テーブル5[[#This Row],[G]]*テーブル5[[#This Row],[A]]*テーブル5[[#This Row],[CPL_ave]]*(テーブル5[[#This Row],[Ts]]-テーブル5[[#This Row],[Tin]]) -> -129396.77 | AT16: =(テーブル5[[#This Row],[Q_DNB]]+テーブル5[[#This Row],[xin_nishida]])/テーブル5[[#This Row],[GAHlg]] -> 0.030171799 | AU16: 1.5827953 | AV16: 16 | AW16: 1.145 | AX16: =テーブル5[[#This Row],[Ts]]-テーブル5[[#This Row],[Tin]] -> 64.217141 | AY16: 341316.54 | AZ16: =テーブル5[[#This Row],[Hsub]]/1000 -> 341.31654
A17: ='TEST SECTION NUMBER 108'!$C$2 -> 108 | B17: ='TEST SECTION NUMBER 108'!I13 -> 12 | C17: ='TEST SECTION NUMBER 108'!K13 -> 1545 | D17: ='TEST SECTION NUMBER 108'!Q13 -> 70 | E17: ='TEST SECTION NUMBER 108'!M13 -> 1.97 | F17: ='TEST SECTION NUMBER 108'!L13 -> 466 | G17: ='TEST SECTION NUMBER 108'!G13 -> 1.1055034 | H17: ='TEST SECTION NUMBER 108'!$C$4 -> 0.555 | I17: ='TEST SECTION NUMBER 108'!$C$6 -> 0.422 | K17: =B17 -> 12 | L17: =C17*6894.757 -> 10652400 | M17: ='TEST SECTION NUMBER 108'!P13*0.0254 -> 2.4384 | N17: ='TEST SECTION NUMBER 108'!$C$4*0.0254 -> 0.014097 | O17: ='TEST SECTION NUMBER 108'!$C$6*0.0254 -> 0.0107188 | P17: =N17^2-PI()*(O17/2)^2 -> 0.00010848891 | Q17: =O17*PI() -> 0.033674103 | R17: ='TEST SECTION NUMBER 108'!$C$4^2-PI()*(('TEST SECTION NUMBER 108'!$C$6)^2)/4 -> 0.16815815 | S17: =PI()*'TEST SECTION NUMBER 108'!$C$6 -> 1.3257521 | T17: =D17*0.0254 -> 1.778 | U17: =E17*10^6*0.001356 -> 2671.32 | V17: =(F17 - 32) * 5/9 + 273.15 -> 514.26111 | W17: =G17*3.1546 -> 3.487421 | Y17: =R17*0.0254^2 -> 0.00010848891 | Z17: =S17*0.0254 -> 0.033674103 | AA17: =V17 -> 514.26111 | AB17: 12 | AC17: =U17 -> 2671.32 | AD17: =Y17 -> 0.00010848891 | AE17: 1277308 | AF17: 588.82589 | AG17: =単位換算108!AA17 -> 514.26111 | AH17: 6323.3616 | AI17: 4705.0513 | AJ17: =(テーブル5[[#This Row],[CPL_Ts]]+テーブル5[[#This Row],[CPL_Tin]])/2 -> 5514.2064 | AK17: ='TEST SECTION NUMBER 108'!N13*3.1546 -> 1.924306 | AL17: =PI()*O17*16*M17 -> 1.3137749 | AM17: =テーブル5[[#This Row],[Q_AVE]]*テーブル5[[#This Row],[A_htr]] -> 2.528105 | AN17: =テーブル5[[#This Row],[DNB位置の半径方向出力]]/テーブル5[[#This Row],[ロッド数]] -> 0.0715625 | AO17: ='TEST SECTION NUMBER 108'!E13 -> 0.72916667 | AP17: =テーブル5[[#This Row],[Q_all]]*テーブル5[[#This Row],[z_ratio]]*テーブル5[[#This Row],[r_ratio]]*1000000 -> 131919.02 | AQ17: =テーブル5[[#This Row],[Q_AVE]]*テーブル5[[#This Row],[DNB位置の軸方向出力]]*テーブル5[[#This Row],[DNB位置の半径方向出力]] -> 3.487421 | AR17: =テーブル5[[#This Row],[G]]*テーブル5[[#This Row],[A]]*テーブル5[[#This Row],[Hlg]] -> 370174.86 | AS17: =-テーブル5[[#This Row],[G]]*テーブル5[[#This Row],[A]]*テーブル5[[#This Row],[CPL_ave]]*(テーブル5[[#This Row],[Ts]]-テーブル5[[#This Row],[Tin]]) -> -119159.32 | AT17: =(テーブル5[[#This Row],[Q_DNB]]+テーブル5[[#This Row],[xin_nishida]])/テーブル5[[#This Row],[GAHlg]] -> 0.034469377 | AU17: 1.5827953 | AV17: 16 | AW17: 1.145 | AX17: =テーブル5[[#This Row],[Ts]]-テーブル5[[#This Row],[Tin]] -> 74.564778 | AY17: 392225.75 | AZ17: =テーブル5[[#This Row],[Hsub]]/1000 -> 392.22575
... A34: ='TEST SECTION NUMBER 108'!$C$2 -> 108 | B34: ='TEST SECTION NUMBER 108'!I30 -> 29 | C34: ='TEST SECTION NUMBER 108'!K30 -> 2415 | D34: ='TEST SECTION NUMBER 108'!Q30 -> 70 | E34: ='TEST SECTION NUMBER 108'!M30 -> 3.557 | F34: ='TEST SECTION NUMBER 108'!L30 -> 627 | G34: ='TEST SECTION NUMBER 108'!G30 -> 0.90977491 | H34: ='TEST SECTION NUMBER 108'!$C$4 -> 0.555 | I34: ='TEST SECTION NUMBER 108'!$C$6 -> 0.422 | K34: =B34 -> 29 | L34: =C34*6894.757 -> 16650838 | M34: ='TEST SECTION NUMBER 108'!P30*0.0254 -> 2.4384 | N34: ='TEST SECTION NUMBER 108'!$C$4*0.0254 -> 0.014097 | O34: ='TEST SECTION NUMBER 108'!$C$6*0.0254 -> 0.0107188 | P34: =N34^2-PI()*(O34/2)^2 -> 0.00010848891 | Q34: =O34*PI() -> 0.033674103 | R34: ='TEST SECTION NUMBER 108'!$C$4^2-PI()*(('TEST SECTION NUMBER 108'!$C$6)^2)/4 -> 0.16815815 | S34: =PI()*'TEST SECTION NUMBER 108'!$C$6 -> 1.3257521 | T34: =D34*0.0254 -> 1.778 | U34: =E34*10^6*0.001356 -> 4823.292 | V34: =(F34 - 32) * 5/9 + 273.15 -> 603.70556 | W34: =G34*3.1546 -> 2.8699759 | Y34: =R34*0.0254^2 -> 0.00010848891 | Z34: =S34*0.0254 -> 0.033674103 | AA34: =V34 -> 603.70556 | AB34: 29 | AC34: =U34 -> 4823.292 | AD34: =Y34 -> 0.00010848891 | AE34: 883760.41 | AF34: 623.74675 | AG34: =単位換算108!AA34 -> 603.70556 | AH34: 10285.201 | AI34: 6645.7524 | AJ34: =(テーブル5[[#This Row],[CPL_Ts]]+テーブル5[[#This Row],[CPL_Tin]])/2 -> 8465.4768 | AK34: ='TEST SECTION NUMBER 108'!N30*3.1546 -> 1.5836092 | AL34: =PI()*O34*16*M34 -> 1.3137749 | AM34: =テーブル5[[#This Row],[Q_AVE]]*テーブル5[[#This Row],[A_htr]] -> 2.0805061 | AN34: =テーブル5[[#This Row],[DNB位置の半径方向出力]]/テーブル5[[#This Row],[ロッド数]] -> 0.0715625 | AO34: ='TEST SECTION NUMBER 108'!E30 -> 0.72916667 | AP34: =テーブル5[[#This Row],[Q_all]]*テーブル5[[#This Row],[z_ratio]]*テーブル5[[#This Row],[r_ratio]]*1000000 -> 108562.87 | AQ34: =テーブル5[[#This Row],[Q_AVE]]*テーブル5[[#This Row],[DNB位置の軸方向出力]]*テーブル5[[#This Row],[DNB位置の半径方向出力]] -> 2.8699759 | AR34: =テーブル5[[#This Row],[G]]*テーブル5[[#This Row],[A]]*テーブル5[[#This Row],[Hlg]] -> 462448.59 | AS34: =-テーブル5[[#This Row],[G]]*テーブル5[[#This Row],[A]]*テーブル5[[#This Row],[CPL_ave]]*(テーブル5[[#This Row],[Ts]]-テーブル5[[#This Row],[Tin]]) -> -88777.699 | AT34: =(テーブル5[[#This Row],[Q_DNB]]+テーブル5[[#This Row],[xin_nishida]])/テーブル5[[#This Row],[GAHlg]] -> 0.042783495 | AU34: 1.5827953 | AV34: 16 | AW34: 1.145 | AX34: =テーブル5[[#This Row],[Ts]]-テーブル5[[#This Row],[Tin]] -> 20.041192 | AY34: 158074.91 | AZ34: =テーブル5[[#This Row],[Hsub]]/1000 -> 158.07491
Y35: =R35*0.0254^2 -> 0 | AN35: =テーブル5[[#This Row],[DNB位置の半径方向出力]]/テーブル5[[#This Row],[ロッド数]] -> #DIV/0! | AQ35: =テーブル5[[#This Row],[Q_AVE]]*テーブル5[[#This Row],[DNB位置の軸方向出力]]*テーブル5[[#This Row],[DNB位置の半径方向出力]] -> 0 | AX35: =テーブル5[[#This Row],[Ts]]-テーブル5[[#This Row],[Tin]] -> 0 | AY35: #VALUE! | AZ35: =テーブル5[[#This Row],[Hsub]]/1000 -> #VALUE!
Y36: =R36*0.0254^2 -> 0
Y37: =R37*0.0254^2 -> 0
Y38: =R38*0.0254^2 -> 0
Y39: =R39*0.0254^2 -> 0
Y40: =R40*0.0254^2 -> 0
Y41: =R41*0.0254^2 -> 0
Y42: =R42*0.0254^2 -> 0
Y43: =R43*0.0254^2 -> 0
Y44: =R44*0.0254^2 -> 0
Y45: =R45*0.0254^2 -> 0
Q56: =0.014097^2-PI()*0.5*0.5*0.0107188^2 -> 0.00010848891

Sheet 非一様加熱を一様加熱に補正108
A1: 出力分布のX軸 | B1: 全長96inを掛ける | C1: 出力分布のY軸 | E1: A列：z[m] | F1: B列：q'' [MW/m²] | G1: C列：Δz | H1: D列：平均出力 | I1: E列：Δ出力 | K1: TEST_No | L1: q"eq
A2: 0 | B2: =A2*96*0.0254 -> 0 | C2: 0.358 | E2: =A2 -> 0 | F2: =C2 -> 0.358 | G2: =E3-テーブル13[[#This Row],[A列：z'[m']]] -> 0.052 | H2: =(F2+F3)/2 -> 0.3585 | I2: =テーブル13[[#This Row],[C列：Δz]]*テーブル13[[#This Row],[D列：平均出力]] -> 0.018642 | K2: 70in | L2: =SUM(I2:I21) -> 0.755174
A3: 0.052 | B3: =A3*96*0.0254 -> 0.1267968 | C3: 0.359 | D3: 半径方向の出力 | E3: =A3 -> 0.052 | F3: =C3 -> 0.359 | G3: =E4-テーブル13[[#This Row],[A列：z'[m']]] -> 0.052 | H3: =(F3+F4)/2 -> 0.3795 | I3: =テーブル13[[#This Row],[C列：Δz]]*テーブル13[[#This Row],[D列：平均出力]] -> 0.019734
A4: 0.104 | B4: =A4*96*0.0254 -> 0.2535936 | C4: 0.4 | D4: 1.145 | E4: =A4 -> 0.104 | F4: =C4 -> 0.4 | G4: =E5-テーブル13[[#This Row],[A列：z'[m']]] -> 0.052 | H4: =(F4+F5)/2 -> 0.429 | I4: =テーブル13[[#This Row],[C列：Δz]]*テーブル13[[#This Row],[D列：平均出力]] -> 0.022308 | K4: 76in | L4: =SUM(I2:I23) -> 0.862749
A5: 0.156 | B5: =A5*96*0.0254 -> 0.3803904 | C5: 0.458 | E5: =A5 -> 0.156 | F5: =C5 -> 0.458 | G5: =E6-テーブル13[[#This Row],[A列：z'[m']]] -> 0.052 | H5: =(F5+F6)/2 -> 0.5125 | I5: =テーブル13[[#This Row],[C列：Δz]]*テーブル13[[#This Row],[D列：平均出力]] -> 0.02665
A6: 0.208 | B6: =A6*96*0.0254 -> 0.5071872 | C6: 0.567 | E6: =A6 -> 0.208 | F6: =C6 -> 0.567 | G6: =E7-テーブル13[[#This Row],[A列：z'[m']]] -> 0.052 | H6: =(F6+F7)/2 -> 0.625 | I6: =テーブル13[[#This Row],[C列：Δz]]*テーブル13[[#This Row],[D列：平均出力]] -> 0.0325 | K6: 実験値のCHFはDNB位置の値
A7: 0.26 | B7: =A7*96*0.0254 -> 0.633984 | C7: 0.683 | D7: 管長[m] | E7: =A7 -> 0.26 | F7: =C7 -> 0.683 | G7: =E8-テーブル13[[#This Row],[A列：z'[m']]] -> 0.053 | H7: =(F7+F8)/2 -> 0.758 | I7: =テーブル13[[#This Row],[C列：Δz]]*テーブル13[[#This Row],[D列：平均出力]] -> 0.040174
A8: 0.313 | B8: =A8*96*0.0254 -> 0.7632192 | C8: 0.833 | D8: =B21 -> 1.7775936 | E8: =A8 -> 0.313 | F8: =C8 -> 0.833 | G8: =E9-テーブル13[[#This Row],[A列：z'[m']]] -> 0.052 | H8: =(F8+F9)/2 -> 0.9125 | I8: =テーブル13[[#This Row],[C列：Δz]]*テーブル13[[#This Row],[D列：平均出力]] -> 0.04745
A9: 0.365 | B9: =A9*96*0.0254 -> 0.890016 | C9: 0.992 | D9: 1.9043904 | E9: =A9 -> 0.365 | F9: =C9 -> 0.992 | G9: =E10-テーブル13[[#This Row],[A列：z'[m']]] -> 0.052 | H9: =(F9+F10)/2 -> 1.0625 | I9: =テーブル13[[#This Row],[C列：Δz]]*テーブル13[[#This Row],[D列：平均出力]] -> 0.05525
A10: 0.417 | B10: =A10*96*0.0254 -> 1.0168128 | C10: 1.133 | D10: 70inと76inの２種類 | E10: =A10 -> 0.417 | F10: =C10 -> 1.133 | G10: =E11-テーブル13[[#This Row],[A列：z'[m']]] -> 0.052 | H10: =(F10+F11)/2 -> 1.1955 | I10: =テーブル13[[#This Row],[C列：Δz]]*テーブル13[[#This Row],[D列：平均出力]] -> 0.062166 | K10: No108はいらない数値を消して見やすくした。20251104
A11: 0.469 | B11: =A11*96*0.0254 -> 1.1436096 | C11: 1.258 | E11: =A11 -> 0.469 | F11: =C11 -> 1.258 | G11: =E12-テーブル13[[#This Row],[A列：z'[m']]] -> 0.026 | H11: =(F11+F12)/2 -> 1.2815 | I11: =テーブル13[[#This Row],[C列：Δz]]*テーブル13[[#This Row],[D列：平均出力]] -> 0.033319
A12: 0.495 | B12: =A12*96*0.0254 -> 1.207008 | C12: 1.305 | E12: =A12 -> 0.495 | F12: =C12 -> 1.305 | G12: =E13-テーブル13[[#This Row],[A列：z'[m']]] -> 0.026 | H12: =(F12+F13)/2 -> 1.3275 | I12: =テーブル13[[#This Row],[C列：Δz]]*テーブル13[[#This Row],[D列：平均出力]] -> 0.034515
A13: 0.521 | B13: =A13*96*0.0254 -> 1.2704064 | C13: 1.35 | E13: =A13 -> 0.521 | F13: =C13 -> 1.35 | G13: =E14-テーブル13[[#This Row],[A列：z'[m']]] -> 0.026 | H13: =(F13+F14)/2 -> 1.38 | I13: =テーブル13[[#This Row],[C列：Δz]]*テーブル13[[#This Row],[D列：平均出力]] -> 0.03588
A14: 0.547 | B14: =A14*96*0.0254 -> 1.3338048 | C14: 1.41 | E14: =A14 -> 0.547 | F14: =C14 -> 1.41 | G14: =E15-テーブル13[[#This Row],[A列：z'[m']]] -> 0.026 | H14: =(F14+F15)/2 -> 1.4385 | I14: =テーブル13[[#This Row],[C列：Δz]]*テーブル13[[#This Row],[D列：平均出力]] -> 0.037401
A15: 0.573 | B15: =A15*96*0.0254 -> 1.3972032 | C15: 1.467 | E15: =A15 -> 0.573 | F15: =C15 -> 1.467 | G15: =E16-テーブル13[[#This Row],[A列：z'[m']]] -> 0.026 | H15: =(F15+F16)/2 -> 1.4945 | I15: =テーブル13[[#This Row],[C列：Δz]]*テーブル13[[#This Row],[D列：平均出力]] -> 0.038857
A16: 0.599 | B16: =A16*96*0.0254 -> 1.4606016 | C16: 1.522 | E16: =A16 -> 0.599 | F16: =C16 -> 1.522 | G16: =E17-テーブル13[[#This Row],[A列：z'[m']]] -> 0.026 | H16: =(F16+F17)/2 -> 1.557 | I16: =テーブル13[[#This Row],[C列：Δz]]*テーブル13[[#This Row],[D列：平均出力]] -> 0.040482
A17: 0.625 | B17: =A17*96*0.0254 -> 1.524 | C17: 1.592 | E17: =A17 -> 0.625 | F17: =C17 -> 1.592 | G17: =E18-テーブル13[[#This Row],[A列：z'[m']]] -> 0.026 | H17: =(F17+F18)/2 -> 1.616 | I17: =テーブル13[[#This Row],[C列：Δz]]*テーブル13[[#This Row],[D列：平均出力]] -> 0.042016
A18: 0.651 | B18: =A18*96*0.0254 -> 1.5873984 | C18: 1.64 | E18: =A18 -> 0.651 | F18: =C18 -> 1.64 | G18: =E19-テーブル13[[#This Row],[A列：z'[m']]] -> 0.026 | H18: =(F18+F19)/2 -> 1.6485 | I18: =テーブル13[[#This Row],[C列：Δz]]*テーブル13[[#This Row],[D列：平均出力]] -> 0.042861
A19: 0.677 | B19: =A19*96*0.0254 -> 1.6507968 | C19: 1.657 | E19: =A19 -> 0.677 | F19: =C19 -> 1.657 | G19: =E20-テーブル13[[#This Row],[A列：z'[m']]] -> 0.026 | H19: =(F19+F20)/2 -> 1.6485 | I19: =テーブル13[[#This Row],[C列：Δz]]*テーブル13[[#This Row],[D列：平均出力]] -> 0.042861
A20: 0.703 | B20: =A20*96*0.0254 -> 1.7141952 | C20: 1.64 | E20: =A20 -> 0.703 | F20: =C20 -> 1.64 | G20: =E21-テーブル13[[#This Row],[A列：z'[m']]] -> 0.026 | H20: =(F20+F21)/2 -> 1.6115 | I20: =テーブル13[[#This Row],[C列：Δz]]*テーブル13[[#This Row],[D列：平均出力]] -> 0.041899
A21: 0.729 | B21: =A21*96*0.0254 -> 1.7775936 | C21: 1.583 | E21: =A21 -> 0.729 | F21: =C21 -> 1.583 | G21: =E22-テーブル13[[#This Row],[A列：z'[m']]] -> 0.026 | H21: =(F21+F22)/2 -> 1.5465 | I21: =テーブル13[[#This Row],[C列：Δz]]*テーブル13[[#This Row],[D列：平均出力]] -> 0.040209
A22: 0.755 | B22: =A22*96*0.0254 -> 1.840992 | C22: 1.51 | E22: =A22 -> 0.755 | F22: =C22 -> 1.51 | G22: =E23-テーブル13[[#This Row],[A列：z'[m']]] -> 0.026 | H22: =(F22+F23)/2 -> 1.4715 | I22: =テーブル13[[#This Row],[C列：Δz]]*テーブル13[[#This Row],[D列：平均出力]] -> 0.038259
... A28: 0.963 | B28: =A28*96*0.0254 -> 2.3481792 | C28: 0.52 | E28: =A28 -> 0.963 | F28: =C28 -> 0.52 | G28: =E29-テーブル13[[#This Row],[A列：z'[m']]] -> 0.037 | H28: =(F28+F29)/2 -> 0.4435 | I28: =テーブル13[[#This Row],[C列：Δz]]*テーブル13[[#This Row],[D列：平均出力]] -> 0.0164095
A29: 1 | B29: =A29*96*0.0254 -> 2.4384 | C29: 0.367 | E29: =A29 -> 1 | F29: =C29 -> 0.367 | G29: 0 | H29: =(F29+F30)/2 -> 0.1835 | I29: =テーブル13[[#This Row],[C列：Δz]]*テーブル13[[#This Row],[D列：平均出力]] -> 0

Sheet TEST SECTION NUMBER 161
A1: X | B1: Y | C1: TEST NUMBER | E1: 正規化座標XCHF | F1: Q(AVE) | G1: qCHF[10⁶ Btu/hr・ft²] | I1: SRL[-] | J1: RUN[-] | K1: PRESS[psia] | L1: TEMP[F] | M1: G(AVE)[106 lbs/hr・ft²] | N1: Q(AVE)[10⁶ Btu/hr・ft²] | O1: CHF RODS[-] | P1: HEATED LENGTH[inch] | Q1: LOCATION OF CHF[inch] | R1: NORMALIZED DISTRIBUTION(Y)
A2: 0 | B2: 1 | C2: 161 | E2: =Q2/P2 -> 0.99702381 | F2: =N2 -> 0.269 | G2: =$C$8*F2*R2 -> 0.296169 | I2: 1 | J2: 1796 | K2: 2115 | L2: 598.4 | M2: 1.998 | N2: 0.269 | O2: 19.1 | P2: 168 | Q2: 167.5 | R2: 1
A3: 0.052 | B3: 1 | C3: PITCH[in] | E3: =Q3/P3 -> 0.99702381 | F3: =N3 -> 0.283 | G3: =$C$8*F3*R3 -> 0.311583 | I3: 2 | J3: 1797 | K3: 2400 | L3: 600.3 | M3: 2.019 | N3: 0.283 | O3: 19.1 | P3: 168 | Q3: 167.5 | R3: 1
A4: 0.104 | B4: 1 | C4: 0.496 | E4: =Q4/P4 -> 0.99702381 | F4: =N4 -> 0.367 | G4: =$C$8*F4*R4 -> 0.404067 | I4: 3 | J4: 1798 | K4: 2400 | L4: 541.9 | M4: 2.014 | N4: 0.367 | O4: 19.1 | P4: 168 | Q4: 167.5 | R4: 1
A5: 0.156 | B5: 1 | C5: ROD OD[in] | E5: =Q5/P5 -> 0.99702381 | F5: =N5 -> 0.34 | G5: =$C$8*F5*R5 -> 0.37434 | I5: 4 | J5: 1799 | K5: 2100 | L5: 543.9 | M5: 1.983 | N5: 0.34 | O5: 19.1 | P5: 168 | Q5: 167.5 | R5: 1
A6: 0.208 | B6: 1 | C6: 0.374 | E6: =Q6/P6 -> 0.99702381 | F6: =N6 -> 0.432 | G6: =$C$8*F6*R6 -> 0.475632 | I6: 6 | J6: 1801 | K6: 2415 | L6: 493.5 | M6: 1.982 | N6: 0.432 | O6: 19.1 | P6: 168 | Q6: 167.5 | R6: 1
A7: 0.26 | B7: 1 | C7: 半径方向の出力分布補正 | E7: =Q7/P7 -> 0.99702381 | F7: =N7 -> 0.506 | G7: =$C$8*F7*R7 -> 0.557106 | I7: 7 | J7: 1802 | K7: 2415 | L7: 448.4 | M7: 2.043 | N7: 0.506 | O7: 19.1 | P7: 168 | Q7: 167.5 | R7: 1
A8: 0.313 | B8: 1 | C8: 1.101 | E8: =Q8/P8 -> 0.99702381 | F8: =N8 -> 0.4 | G8: =$C$8*F8*R8 -> 0.4404 | I8: 8 | J8: 1803 | K8: 2100 | L8: 491.2 | M8: 2.008 | N8: 0.4 | O8: 19.1 | P8: 168 | Q8: 167.5 | R8: 1
A9: 0.365 | B9: 1 | E9: =Q9/P9 -> 0.99702381 | F9: =N9 -> 0.3 | G9: =$C$8*F9*R9 -> 0.3303 | I9: 9 | J9: 1804 | K9: 2100 | L9: 602.8 | M9: 2.474 | N9: 0.3 | O9: 19.1 | P9: 168 | Q9: 167.5 | R9: 1
A10: 0.417 | B10: 1 | E10: =Q10/P10 -> 0.99702381 | F10: =N10 -> 0.329 | G10: =$C$8*F10*R10 -> 0.362229 | I10: 10 | J10: 1805 | K10: 2400 | L10: 601.8 | M10: 2.511 | N10: 0.329 | O10: 19.1 | P10: 168 | Q10: 167.5 | R10: 1
A11: 0.469 | B11: 1 | E11: =Q11/P11 -> 0.99702381 | F11: =N11 -> 0.353 | G11: =$C$8*F11*R11 -> 0.388653 | I11: 11 | J11: 1806 | K11: 2100 | L11: 597.9 | M11: 2.998 | N11: 0.353 | O11: 19.1 | P11: 168 | Q11: 167.5 | R11: 1
A12: 0.495 | B12: 1 | E12: =Q12/P12 -> 0.99702381 | F12: =N12 -> 0.379 | G12: =$C$8*F12*R12 -> 0.417279 | I12: 12 | J12: 1807 | K12: 2400 | L12: 604.2 | M12: 2.998 | N12: 0.379 | O12: 19.1 | P12: 168 | Q12: 167.5 | R12: 1
A13: 0.521 | B13: 1 | E13: =Q13/P13 -> 0.99702381 | F13: =N13 -> 0.291 | G13: =$C$8*F13*R13 -> 0.320391 | I13: 13 | J13: 1808 | K13: 2100 | L13: 539.5 | M13: 1.482 | N13: 0.291 | O13: 19.1 | P13: 168 | Q13: 167.5 | R13: 1
A14: 0.547 | B14: 1 | E14: =Q14/P14 -> 0.99702381 | F14: =N14 -> 0.29 | G14: =$C$8*F14*R14 -> 0.31929 | I14: 14 | J14: 1809 | K14: 2400 | L14: 548.9 | M14: 1.478 | N14: 0.29 | O14: 19.1 | P14: 168 | Q14: 167.5 | R14: 1
A15: 0.573 | B15: 1 | E15: =Q15/P15 -> 0.99702381 | F15: =N15 -> 0.416 | G15: =$C$8*F15*R15 -> 0.458016 | I15: 15 | J15: 1810 | K15: 2400 | L15: 552.4 | M15: 2.504 | N15: 0.416 | O15: 19.1 | P15: 168 | Q15: 167.5 | R15: 1
A16: 0.599 | B16: 1 | E16: =Q16/P16 -> 0.99702381 | F16: =N16 -> 0.378 | G16: =$C$8*F16*R16 -> 0.416178 | I16: 16 | J16: 1811 | K16: 2100 | L16: 555.3 | M16: 2.484 | N16: 0.378 | O16: 19.1 | P16: 168 | Q16: 167.5 | R16: 1
A17: 0.625 | B17: 1 | E17: =Q17/P17 -> 0.99702381 | F17: =N17 -> 0.342 | G17: =$C$8*F17*R17 -> 0.376542 | I17: 17 | J17: 1812 | K17: 2100 | L17: 485.4 | M17: 1.507 | N17: 0.342 | O17: 19.1 | P17: 168 | Q17: 167.5 | R17: 1
A18: 0.651 | B18: 1 | E18: =Q18/P18 -> 0.99702381 | F18: =N18 -> 0.333 | G18: =$C$8*F18*R18 -> 0.366633 | I18: 18 | J18: 1813 | K18: 2400 | L18: 499.9 | M18: 1.449 | N18: 0.333 | O18: 19.1 | P18: 168 | Q18: 167.5 | R18: 1
A19: 0.677 | B19: 1 | E19: =Q19/P19 -> 0.99702381 | F19: =N19 -> 0.392 | G19: =$C$8*F19*R19 -> 0.431592 | I19: 19 | J19: 1814 | K19: 2100 | L19: 429.9 | M19: 1.499 | N19: 0.392 | O19: 19.1 | P19: 168 | Q19: 167.5 | R19: 1
A20: 0.703 | B20: 1 | E20: =Q20/P20 -> 0.99702381 | F20: =N20 -> 0.417 | G20: =$C$8*F20*R20 -> 0.459117 | I20: 20 | J20: 1815 | K20: 2400 | L20: 425.2 | M20: 1.514 | N20: 0.417 | O20: 19.1 | P20: 168 | Q20: 167.5 | R20: 1
... A29: 1 | B29: 1 | E29: =Q29/P29 -> 0.99702381 | F29: =N29 -> 0.397 | G29: =$C$8*F29*R29 -> 0.437097 | I29: 30 | J29: 1825 | K29: 2100 | L29: 572.8 | M29: 2.922 | N29: 0.397 | O29: 19.1 | P29: 168 | Q29: 167.5 | R29: 1
E30: =Q30/P30 -> 0.99702381 | F30: =N30 -> 0.466 | G30: =$C$8*F30*R30 -> 0.513066 | I30: 31 | J30: 1826 | K30: 2100 | L30: 570.6 | M30: 3.497 | N30: 0.466 | O30: 19.1 | P30: 168 | Q30: 167.5 | R30: 1
E31: =Q31/P31 -> 0.99702381 | F31: =N31 -> 0.466 | G31: =$C$8*F31*R31 -> 0.513066 | I31: 32 | J31: 1827 | K31: 2100 | L31: 543.3 | M31: 2.941 | N31: 0.466 | O31: 19.1 | P31: 168 | Q31: 167.5 | R31: 1
E32: =Q32/P32 -> 0.99702381 | F32: =N32 -> 0.463 | G32: =$C$8*F32*R32 -> 0.509763 | I32: 33 | J32: 1828 | K32: 2100 | L32: 503.3 | M32: 2.494 | N32: 0.463 | O32: 19.1 | P32: 168 | Q32: 167.5 | R32: 1
E33: =Q33/P33 -> 0.99702381 | F33: =N33 -> 0.265 | G33: =$C$8*F33*R33 -> 0.291765 | I33: 34 | J33: 1829 | K33: 2105 | L33: 476.9 | M33: 0.992 | N33: 0.265 | O33: 19.1 | P33: 168 | Q33: 167.5 | R33: 1
E34: =Q34/P34 -> 0.99702381 | F34: =N34 -> 0.269 | G34: =$C$8*F34*R34 -> 0.296169 | I34: 35 | J34: 1830 | K34: 2415 | L34: 484.8 | M34: 0.996 | N34: 0.269 | O34: 19.1 | P34: 168 | Q34: 167.5 | R34: 1
E35: =Q35/P35 -> 0.99702381 | F35: =N35 -> 0.456 | G35: =$C$8*F35*R35 -> 0.502056 | I35: 36 | J35: 1831 | K35: 2100 | L35: 459.8 | M35: 2.01 | N35: 0.456 | O35: 19.1 | P35: 168 | Q35: 167.5 | R35: 1
E36: =Q36/P36 -> 0.99702381 | F36: =N36 -> 0.517 | G36: =$C$8*F36*R36 -> 0.569217 | I36: 37 | J36: 1832 | K36: 2100 | L36: 468.9 | M36: 2.467 | N36: 0.517 | O36: 19.1 | P36: 168 | Q36: 167.5 | R36: 1
E37: =Q37/P37 -> 0.99702381 | F37: =N37 -> 0.286 | G37: =$C$8*F37*R37 -> 0.314886 | I37: 38 | J37: 1833 | K37: 2085 | L37: 437.3 | M37: 0.957 | N37: 0.286 | O37: 19.1 | P37: 168 | Q37: 167.5 | R37: 1
E38: =Q38/P38 -> 0.99702381 | F38: =N38 -> 0.3 | G38: =$C$8*F38*R38 -> 0.3303 | I38: 39 | J38: 1834 | K38: 2415 | L38: 433.9 | M38: 0.97 | N38: 0.3 | O38: 19.1 | P38: 168 | Q38: 167.5 | R38: 1
E39: =Q39/P39 -> 0.99702381 | F39: =N39 -> 0.487 | G39: =$C$8*F39*R39 -> 0.536187 | I39: 40 | J39: 1835 | K39: 2100 | L39: 436.8 | M39: 2.038 | N39: 0.487 | O39: 19.1 | P39: 168 | Q39: 167.5 | R39: 1
E40: =Q40/P40 -> 0.99702381 | F40: =N40 -> 0.331 | G40: =$C$8*F40*R40 -> 0.364431 | I40: 41 | J40: 1836 | K40: 2100 | L40: 384.4 | M40: 1.012 | N40: 0.331 | O40: 19.1 | P40: 168 | Q40: 167.5 | R40: 1
E41: =Q41/P41 -> 0.99702381 | F41: =N41 -> 0.34 | G41: =$C$8*F41*R41 -> 0.37434 | I41: 42 | J41: 1837 | K41: 2415 | L41: 382.2 | M41: 1.022 | N41: 0.34 | O41: 19.1 | P41: 168 | Q41: 167.5 | R41: 1
... E51: =Q51/P51 -> 0.99702381 | F51: =N51 -> 0.341 | G51: =$C$8*F51*R51 -> 0.375441 | I51: 70 | J51: 1865 | K51: 2095 | L51: 543.8 | M51: 1.991 | N51: 0.341 | O51: 19.1 | P51: 168 | Q51: 167.5 | R51: 1
A65: 線形補間
A66: X | B66: Y
A67: 0 | B67: 0.358
A68: 0.00010001 | B68: 0.35800192
A69: 0.00020002 | B69: 0.35800385
A70: 0.00030003 | B70: 0.35800577
...

Sheet 単位換算161
Y4: ③Celataの計算に必要な値に変換 | AC4: クオリティの計算 | AK4: 実験値 | AL4: ロッド16本の濡れぶち | AM4: ロッド１６本の全出力 | AN4: ロッドを１本にし、ピークのロッドで考える | AO4: DNB相対位置 | AP4: 総出力をロッド１本、DNB位置までに変換 | AQ4: 検算 これにより、QAVEに半径・軸の相対ピーク値をかけるとCHFになることがわかる
A5: TEST SECTION NUMBER | B5: SRL | C5: PRESSURE (psia) | D5: LENGTH (in.) | E5: MASS VELOCITY × 10⁻⁶ (lb/hr.ft²) | F5: INLET TEMP[F] | G5: BURNOUT HEAT FLUX × 10⁻⁶ (BTU/hr.ft²) | H5: PITCH[in] | I5: ROD OD[in] | K5: 実験番号. | L5: Pin圧力 (Pa) | M5: L_全長[m] | N5: PITCH[m] | O5: ROD OD[m] | P5: 流路断面積[m2] | Q5: 濡れ縁長さ[m] | R5: 流路断面積[in2] | S5: 濡れ縁長さ[in] | T5: 管の長さ (m) | U5: 質量流速[kg/(m²·s)] | V5: 入口温度[K] | W5: CHF [MW/m²] | Y5: 流路断面積 A[m2] | Z5: 濡れ縁長さ[m] | AA5: 入口温度[K] | AC5: G | AD5: A | AE5: Hlg | AF5: Ts | AG5: Tin | AH5: CPL_Ts | AI5: CPL_Tin | AJ5: CPL_ave | AK5: Q_AVE | AL5: A_htr | AM5: Q_all | AN5: r_ratio | AO5: z_ratio | AP5: Q_DNB | AQ5: q_DNB_nishida | AR5: GAHlg | AS5: xin_nishida | AT5: xout_nishida | AU5: DNB位置の軸方向出力 | AV5: ロッド数 | AW5: DNB位置の半径方向出力 | AX5: Tsub | AY5: Hsub | AZ5: Hsub[kJ/kg]
A6: ='TEST SECTION NUMBER 161'!$C$2 -> 161 | B6: ='TEST SECTION NUMBER 161'!I2 -> 1 | C6: ='TEST SECTION NUMBER 161'!K2 -> 2115 | D6: ='TEST SECTION NUMBER 161'!Q2 -> 167.5 | E6: ='TEST SECTION NUMBER 161'!M2 -> 1.998 | F6: ='TEST SECTION NUMBER 161'!L2 -> 598.4 | G6: ='TEST SECTION NUMBER 161'!G2 -> 0.296169 | H6: ='TEST SECTION NUMBER 161'!$C$4 -> 0.496 | I6: ='TEST SECTION NUMBER 161'!$C$6 -> 0.374 | K6: =B6&"_"&テーブル414[[#This Row],[TEST SECTION NUMBER]] -> 1_161 | L6: =C6*6894.757 -> 14582411 | M6: ='TEST SECTION NUMBER 161'!P2*0.0254 -> 4.2672 | N6: ='TEST SECTION NUMBER 161'!$C$4*0.0254 -> 0.0125984 | O6: ='TEST SECTION NUMBER 161'!$C$6*0.0254 -> 0.0094996 | P6: =N6^2-PI()*(O6/2)^2 -> 8.7843467e-05 | Q6: =O6*PI() -> 0.029843874 | R6: ='TEST SECTION NUMBER 161'!$C$4^2-PI()*(('TEST SECTION NUMBER 161'!$C$6)^2)/4 -> 0.13615765 | S6: =PI()*'TEST SECTION NUMBER 161'!$C$6 -> 1.1749557 | T6: =D6*0.0254 -> 4.2545 | U6: =E6*10^6*0.001356 -> 2709.288 | V6: =(F6 - 32) * 5/9 + 273.15 -> 587.81667 | W6: =G6*3.1546 -> 0.93429473 | Y6: =R6*0.0254^2 -> 8.7843467e-05 | Z6: =S6*0.0254 -> 0.029843874 | AA6: =V6 -> 587.81667 | AB6: 1 | AC6: =U6 -> 2709.288 | AD6: =Y6 -> 8.7843467e-05 | AE6: 1028533.1 | AF6: 613.05027 | AG6: =単位換算161!AA6 -> 587.81667 | AH6: 8194.7812 | AI6: 5965.6064 | AJ6: =(テーブル515[[#This Row],[CPL_Ts]]+テーブル515[[#This Row],[CPL_Tin]])/2 -> 7080.1938 | AK6: ='TEST SECTION NUMBER 161'!N2*3.1546 -> 0.8485874 | AL6: =PI()*O6*16*M6 -> 2.0375964 | AM6: =テーブル515[[#This Row],[Q_AVE]]*テーブル515[[#This Row],[A_htr]] -> 1.7290787 | AN6: =テーブル515[[#This Row],[DNB位置の軸方向出力]]/テーブル515[[#This Row],[ロッド数]] -> 0.04 | AO6: ='TEST SECTION NUMBER 161'!E2 -> 0.99702381 | AP6: =テーブル515[[#This Row],[Q_all]]*テーブル515[[#This Row],[z_ratio]]*テーブル515[[#This Row],[r_ratio]]*1000000 -> 68957.304 | AQ6: =テーブル515[[#This Row],[Q_AVE]]*テーブル515[[#This Row],[DNB位置の軸方向出力]]*テーブル515[[#This Row],[DNB位置の半径方向出力]] -> 0.93429473 | AR6: =テーブル515[[#This Row],[G]]*テーブル515[[#This Row],[A]]*テーブル515[[#This Row],[Hlg]] -> 244783.93 | AS6: =-テーブル515[[#This Row],[G]]*テーブル515[[#This Row],[A]]*テーブル515[[#This Row],[CPL_ave]]*(テーブル515[[#This Row],[Ts]]-テーブル515[[#This Row],[Tin]]) -> -42519.589 | AT6: =(テーブル515[[#This Row],[Q_DNB]]+テーブル515[[#This Row],[xin_nishida]])/テーブル515[[#This Row],[GAHlg]] -> 0.10800429 | AU6: 1 | AV6: 25 | AW6: 1.101 | AX6: =テーブル515[[#This Row],[Ts]]-テーブル515[[#This Row],[Tin]] -> 25.233603 | AY6: 171402.51 | AZ6: =テーブル515[[#This Row],[Hsub]]/1000 -> 171.40251
A7: ='TEST SECTION NUMBER 161'!$C$2 -> 161 | B7: ='TEST SECTION NUMBER 161'!I3 -> 2 | C7: ='TEST SECTION NUMBER 161'!K3 -> 2400 | D7: ='TEST SECTION NUMBER 161'!Q3 -> 167.5 | E7: ='TEST SECTION NUMBER 161'!M3 -> 2.019 | F7: ='TEST SECTION NUMBER 161'!L3 -> 600.3 | G7: ='TEST SECTION NUMBER 161'!G3 -> 0.311583 | H7: ='TEST SECTION NUMBER 161'!$C$4 -> 0.496 | I7: ='TEST SECTION NUMBER 161'!$C$6 -> 0.374 | K7: =B7&"_"&テーブル414[[#This Row],[TEST SECTION NUMBER]] -> 2_161 | L7: =C7*6894.757 -> 16547417 | M7: ='TEST SECTION NUMBER 161'!P3*0.0254 -> 4.2672 | N7: ='TEST SECTION NUMBER 161'!$C$4*0.0254 -> 0.0125984 | O7: ='TEST SECTION NUMBER 161'!$C$6*0.0254 -> 0.0094996 | P7: =N7^2-PI()*(O7/2)^2 -> 8.7843467e-05 | Q7: =O7*PI() -> 0.029843874 | R7: ='TEST SECTION NUMBER 161'!$C$4^2-PI()*(('TEST SECTION NUMBER 161'!$C$6)^2)/4 -> 0.13615765 | S7: =PI()*'TEST SECTION NUMBER 161'!$C$6 -> 1.1749557 | T7: =D7*0.0254 -> 4.2545 | U7: =E7*10^6*0.001356 -> 2737.764 | V7: =(F7 - 32) * 5/9 + 273.15 -> 588.87222 | W7: =G7*3.1546 -> 0.98291973 | Y7: =R7*0.0254^2 -> 8.7843467e-05 | Z7: =S7*0.0254 -> 0.029843874 | AA7: =V7 -> 588.87222 | AB7: 2 | AC7: =U7 -> 2737.764 | AD7: =Y7 -> 8.7843467e-05 | AE7: 891419.3 | AF7: 623.2387 | AG7: =単位換算161!AA7 -> 588.87222 | AH7: 10140.552 | AI7: 5886.1688 | AJ7: =(テーブル515[[#This Row],[CPL_Ts]]+テーブル515[[#This Row],[CPL_Tin]])/2 -> 8013.3602 | AK7: ='TEST SECTION NUMBER 161'!N3*3.1546 -> 0.8927518 | AL7: =PI()*O7*16*M7 -> 2.0375964 | AM7: =テーブル515[[#This Row],[Q_AVE]]*テーブル515[[#This Row],[A_htr]] -> 1.8190679 | AN7: =テーブル515[[#This Row],[DNB位置の軸方向出力]]/テーブル515[[#This Row],[ロッド数]] -> 0.04 | AO7: ='TEST SECTION NUMBER 161'!E3 -> 0.99702381 | AP7: =テーブル515[[#This Row],[Q_all]]*テーブル515[[#This Row],[z_ratio]]*テーブル515[[#This Row],[r_ratio]]*1000000 -> 72546.16 | AQ7: =テーブル515[[#This Row],[Q_AVE]]*テーブル515[[#This Row],[DNB位置の軸方向出力]]*テーブル515[[#This Row],[DNB位置の半径方向出力]] -> 0.98291973 | AR7: =テーブル515[[#This Row],[G]]*テーブル515[[#This Row],[A]]*テーブル515[[#This Row],[Hlg]] -> 214381.6 | AS7: =-テーブル515[[#This Row],[G]]*テーブル515[[#This Row],[A]]*テーブル515[[#This Row],[CPL_ave]]*(テーブル515[[#This Row],[Ts]]-テーブル515[[#This Row],[Tin]]) -> -66230.066 | AT7: =(テーブル515[[#This Row],[Q_DNB]]+テーブル515[[#This Row],[xin_nishida]])/テーブル515[[#This Row],[GAHlg]] -> 0.029461923 | AU7: 1 | AV7: 25 | AW7: 1.101 | AX7: =テーブル515[[#This Row],[Ts]]-テーブル515[[#This Row],[Tin]] -> 34.366479 | AY7: 246025.87 | AZ7: =テーブル515[[#This Row],[Hsub]]/1000 -> 246.02587
